Workbook

Sheet CAPA
C18: RELATÓRIO PARCIAL
C20: CONTROLE TECNOLÓGICO
C21: ='DADOS - FREGUESIA DO Ó'!B4 -> Período: 01/03/2026 à 31/03/2026
C35: POLO FREGUESIA DO Ó
C36: CONTRATADA AUDITADA: Consórcio Nova Norte X
C37: CONTRATO: 11522428
C41: SÃO PAULO
C42: 2026

Sheet DADOS - FREGUESIA DO Ó
B2: FREGUESIA DO Ó
B3: ACOMPANHAMENTO EM CAMPO
B4: Período: 01/03/2026 à 31/03/2026
B6: ÍNDICE TECNOLÓGICO (%)
B7: IT (%)
D9: ÍNDICE DE CONFORMIDADE (%)
B10: Tipo de Serviço | C10: IC (%) | E10: Quantidade de LVs
B11: Água | C11: 1 | E11: 100
B12: Esgoto | C12: 0.5 | E12: 50
B13: Reposição | C13: 0.1 | E13: 1
B15: FREGUESIA DO Ó | E15: FALTAM | F15: =('GRÁFICOS - ÁGUA'!B8+'GRÁFICOS - ESGOTO'!B8+'GRÁFICOS - CAVALETE'!B8+'GRÁFICOS - REPOSIÇÃO'!B8) -> 0
B16: QUALIDADE | C16: 0
B17: PRAZO | C17: 0
B18: SEGURANÇA | C18: 0
B19: ORGANIZAÇÃO | C19: 0
B22: OLHAR DIGITAL
B24: ÍNDICE DE QUALIDADE SABESP - IQS (%)
B25: Tipo de Serviço | C25: Fotos Avaliadas | D25: Fotos NC | E25: Fotos Conforme | F25: Não Conforme (%) | G25: Conforme (%)
B26: Água | C26: =D26+E26 -> 505 | D26: =COUNTIF(ÁGUA!AF:AF,"Nc") -> 140 | E26: =COUNTIF(ÁGUA!AF:AF,"c") -> 365 | F26: =IFERROR(D26/C26,"-") -> 0.27722772 | G26: =IFERROR(100%-F26,"-") -> 0.72277228
B27: Esgoto | C27: =D27+E27 -> 236 | D27: =COUNTIF(ESGOTO!AF:AF,"NC") -> 93 | E27: =COUNTIF(ESGOTO!AF:AF,"C") -> 143 | F27: =IFERROR(D27/C27,"-") -> 0.3940678 | G27: =IFERROR(100%-F27,"-") -> 0.6059322
B28: Cavalete | C28: =D28+E28 -> 536 | D28: =COUNTIF(CAVALETE!Z:Z,"nc") -> 106 | E28: =COUNTIF(CAVALETE!Z:Z,"C") -> 430 | F28: =IFERROR(D28/C28,"-") -> 0.19776119 | G28: =IFERROR(100%-F28,"-") -> 0.80223881
B29: Reposição | C29: =D29+E29 -> 23 | D29: =COUNTIF(REPOSIÇÃO!AF:AF,"nC") -> 16 | E29: =COUNTIF(REPOSIÇÃO!AF:AF,"c") -> 7 | F29: =IFERROR(D29/C29,"-") -> 0.69565217 | G29: =IFERROR(100%-F29,"-") -> 0.30434783
B30: Total | C30: =SUM(C26:C29) -> 1300 | D30: =SUM(D26:D29) -> 355 | E30: =SUM(E26:E29) -> 945 | F30: =IFERROR(AVERAGE(F26,F27,F28,F29),"-") -> 0.39117722 | G30: =IFERROR(AVERAGE(G26,G27,G28,G29),"-") -> 0.60882278
F31: IQS Não Conforme (%): | G31: IQS (%):
B33: TEMPO DE EXECUÇÃO
B34: Tipo de Serviço | C34: Avaliados | D34: Não Conforme | E34: Conforme | F34: Não Conforme (%) | G34: Conforme (%)
B35: Água | C35: =D35+E35 -> 499 | D35: =COUNTIF(ÁGUA!AE:AE,"Nc") -> 60 | E35: =COUNTIF(ÁGUA!AE:AE,"c") -> 439 | F35: =IFERROR(D35/C35,"-") -> 0.12024048 | G35: =IFERROR(E35/C35,"-") -> 0.87975952
B36: Esgoto | C36: =D36+E36 -> 236 | D36: =COUNTIF(ESGOTO!AE:AE,"NC") -> 54 | E36: =COUNTIF(ESGOTO!AE:AE,"C") -> 182 | F36: =IFERROR(D36/C36,"-") -> 0.22881356 | G36: =IFERROR(E36/C36,"-") -> 0.77118644
B37: Cavalete | C37: =D37+E37 -> 536 | D37: =COUNTIF(CAVALETE!Y:Y,"NC") -> 46 | E37: =COUNTIF(CAVALETE!Y:Y,"C") -> 490 | F37: =IFERROR(D37/C37,"-") -> 0.085820896 | G37: =IFERROR(E37/C37,"-") -> 0.9141791
B38: Reposição | C38: =D38+E38 -> 23 | D38: =COUNTIF(REPOSIÇÃO!AE:AE,"nC") -> 2 | E38: =COUNTIF(REPOSIÇÃO!AE:AE,"c") -> 21 | F38: =IFERROR(D38/C38,"-") -> 0.086956522 | G38: =IFERROR(E38/C38,"-") -> 0.91304348
B40: BAIXA DE MATERIAIS
B41: Tipo de Serviço | C41: Avaliados | D41: Não Conforme | E41: Conforme | F41: Não Conforme (%) | G41: Conforme (%)
B42: Água | C42: =D42+E42 -> 434 | D42: =COUNTIF(ÁGUA!AH:AH,"Nc") -> 0 | E42: =COUNTIF(ÁGUA!AH:AH,"c") -> 434 | F42: =IFERROR(D42/C42,"-") -> 0 | G42: =IFERROR(E42/C42,"-") -> 1
B43: Esgoto | C43: =D43+E43 -> 205 | D43: =COUNTIF(ESGOTO!AH:AH,"NC") -> 1 | E43: =COUNTIF(ESGOTO!AH:AH,"C") -> 204 | F43: =IFERROR(D43/C43,"-") -> 0.0048780488 | G43: =IFERROR(E43/C43,"-") -> 0.99512195
B44: Cavalete | C44: =D44+E44 -> 575 | D44: =COUNTIF(CAVALETE!AB:AB,"NC") -> 0 | E44: =COUNTIF(CAVALETE!AB:AB,"C") -> 575 | F44: =IFERROR(D44/C44,"-") -> 0 | G44: =IFERROR(E44/C44,"-") -> 1
B46: ÁGUA
B48: TEMPO DE EXECUÇÃO
B49: Tipo de Serviço | C49: Avaliados | D49: Não Conforme | E49: Conforme | F49: Não Conforme (%) | G49: Conforme (%)
B50: Água | C50: =D50+E50 -> 499 | D50: =COUNTIF(ÁGUA!AE:AE,"NC") -> 60 | E50: =COUNTIF(ÁGUA!AE:AE,"C") -> 439 | F50: =IFERROR(D50/C50,"-") -> 0.12024048 | G50: =IFERROR(E50/C50,"-") -> 0.87975952
B52: ÍNDICE DE QUALIDADE SABESP - IQS (%)
...

Sheet GRÁFICOS - FREGUESIA DO Ó
A2: POLO FREGUESIA DO Ó
A4: ACOMPANHAMENTO EM CAMPO
A5: ='DADOS - FREGUESIA DO Ó'!B4 -> Período: 01/03/2026 à 31/03/2026
A7: ÍNDICE TECNOLÓGICO
B20: O Índice Tecnológico pode ser obtido através da fórmula:
B22: IT = {[97 + 3 (Kc/100)] x Ks/100}
B24: Onde:
B25: IT = Índice Tecnológico
B26: Kc = Fator do Canteiro
B27: Ks = Média de Notas das LVs
B29: Estando acima de 80% o IT é considerado satisfatório.
A31: Nota: O Índice Tecnológico não foi calculado, pois a avaliação de Canteiro ainda não foi realizada.
A34: ACOMPANHAMENTO DE LISTAS DE VERIFICAÇÃO - LVS
B36: Índice de Conformidade (%) | E36: Quantidade de LVs
B51: TIPO DE SERVIÇO | C51: QUANTIDADE DE LVS ACIMA DE 80%
B52: Água | C52: 0
B53: Esgoto | C53: 0
B54: Reposição | C54: 0
A57: CONFORMIDADE POR CRITÉRIO DE AVALIAÇÃO
A84: OLHAR DIGITAL
A85: ='DADOS - FREGUESIA DO Ó'!B4 -> Período: 01/03/2026 à 31/03/2026
B86: ÍNDICE DE QUALIDADE SABESP - IQS (%) - MARÇO
B101: ÍNDICE DE QUALIDADE SABESP - IQS (%)
B102: Tipo de Serviço | C102: Fotos Avaliadas | D102: Fotos NC | E102: Fotos Conforme | F102: Não Conforme (%) | G102: Conforme (%)
B103: Água | C103: =D103+E103 -> 505 | D103: =COUNTIF(ÁGUA!AF:AF,"Nc") -> 140 | E103: =COUNTIF(ÁGUA!AF:AF,"c") -> 365 | F103: =IFERROR(D103/C103,"-") -> 0.27722772 | G103: =IFERROR(100%-F103,"-") -> 0.72277228
B104: Esgoto | C104: =D104+E104 -> 236 | D104: =COUNTIF(ESGOTO!AF:AF,"NC") -> 93 | E104: =COUNTIF(ESGOTO!AF:AF,"C") -> 143 | F104: =IFERROR(D104/C104,"-") -> 0.3940678 | G104: =IFERROR(100%-F104,"-") -> 0.6059322
B105: Cavalete | C105: =D105+E105 -> 536 | D105: =COUNTIF(CAVALETE!Z:Z,"nc") -> 106 | E105: =COUNTIF(CAVALETE!Z:Z,"C") -> 430 | F105: =IFERROR(D105/C105,"-") -> 0.19776119 | G105: =IFERROR(100%-F105,"-") -> 0.80223881
B106: Reposição | C106: =D106+E106 -> 23 | D106: =COUNTIF(REPOSIÇÃO!AF:AF,"nC") -> 16 | E106: =COUNTIF(REPOSIÇÃO!AF:AF,"c") -> 7 | F106: =IFERROR(D106/C106,"-") -> 0.69565217 | G106: =IFERROR(100%-F106,"-") -> 0.30434783
F107: IQS (%): | G107: =IFERROR(AVERAGE(G103,G104,G105,G106), "-") -> 0.60882278

Sheet GRÁFICOS - ÁGUA
A1: AMOSTRA
B3: EXECUTADOS | D3: AVALIADOS
B4: =COUNTIF(ÁGUA!A:A,"ONMF - DIV MANUT SERV OPE FREGUESIA") -> 562 | D4: ='DADOS - FREGUESIA DO Ó'!C26 -> 505
B5: VERIFICADOS | C5: (%) | D5: SEM EVIDÊNCIAS | E5: (%) | G5: =344/6 -> 57.333333
B6: ='DADOS - FREGUESIA DO Ó'!C26+'GRÁFICOS - ÁGUA'!D8 -> 562 | C6: =IFERROR(B6/B4,"-") -> 1 | D6: =COUNTIFS(ÁGUA!O:O,"SF",ÁGUA!Q:Q,"SF",ÁGUA!S:S,"SF",ÁGUA!U:U,"SF",ÁGUA!W:W,"SF",ÁGUA!Y:Y,"SF",ÁGUA!AC:AC,"SF",ÁGUA!AA:AA,"SF") -> 34 | E6: =IFERROR(D6/B4,"-") -> 0.060498221
B7: NÃO VERIFICADOS | C7: (%) | D7: NÃO SINCRONIZADOS | E7: (%)
B8: =B4-B6 -> 0 | C8: =IFERROR(B8/B4,"-") -> 0 | D8: =COUNTIFS(ÁGUA!O:O,"na",ÁGUA!Q:Q,"na",ÁGUA!S:S,"na",ÁGUA!U:U,"na",ÁGUA!W:W,"na",ÁGUA!Y:Y,"na",ÁGUA!AC:AC,"na",ÁGUA!AA:AA,"na") -> 57 | E8: =IFERROR(D8/B4,"-") -> 0.10142349
A11: RESULTADO
A40: AVALIAÇÃO DE MATERIAIS
A69: CONFORMIDADE POR ETAPAS DE SERVIÇO
A103: EQUIPES - CONFORMIDADES

Sheet ÁGUA
A1: Unidade Executante | B1: Número OS | C1: Descrição TSS | D1: Família | E1: Município | F1: Endereço | G1: Número | H1: Complemento | I1: Bairro | J1: Resultado | K1: Nota Execução/Não Execução | L1: Data Início Execução | M1: Data Fim Execução | N1: EQUIPE | O1: FACHADA | P1: Observação Fachada | Q1: SINALIZAÇÃO | R1: Observação Sinalização | S1: ENCERADO | T1: Observação encerado | U1: GEOMETRIA | V1: Observação Geometria | W1: BERÇO DE AREIA | X1: Observação Berço de Areia | Y1: ESTANQUEIDADE | Z1: Observaçao Estanqueidade | AA1: .COMPACTAÇÃO | AB1: Observação Compactação | AC1: FINALIZAÇÃO | AD1: Observação Finalização | AE1: Tempo de execução | AF1: Sequência de Fotos | AG1: Observações | AH1: Baixa de materias | AI1: POLO | AJ1: MUNICÍPIO | AK1: CARACTERÍSTICA DO SERVIÇO
A2: ONMF - DIV MANUT SERV OPE FREGUESIA | B2: 2617563355 | C2: INTERLIGAR REDE DE ÁGUA | D2: REDE DE ÁGUA | E2: SÃO PAULO | F2: RUA CAROLINA SOARES | G2: 465 | I2: V DIVA | J2: INTERLIGAÇÃO DE REDE DE AGUA | K2: Rede 225 | L2: 46058.25 | M2: 46058.251 | N2: ROMERO FRANCISCO DOS SANTOS | O2: C | Q2: C | S2: C | U2: C | W2: SF | Y2: NA | AA2: C | AC2: C | AE2: C | AF2: =IF(AND(O2="",Q2="",S2="",U2="",W2="",Y2="",AA2="",AC2=""),"",IF(OR(AND(O2<>"NA",O2<>"C",O2<>"NC",O2<>"SF",O2<>""),AND(Q2<>"NA",Q2<>"C",Q2<>"NC",Q2<>"SF",Q2<>""),AND(S2<>"NA",S2<>"C",S2<>"NC",S2<>"SF",S2<>""),AND(U2<>"NA",U2<>"C",U2<>"NC",U2<>"SF",U2<>""),AND(W2<>"NA",W2<>"C",W2<>"NC",W2<>"SF",W2<>""),AND(Y2<>"NA",Y2<>"C",Y2<>"NC",Y2<>"SF",Y2<>""),AND(AA2<>"NA",AA2<>"C",AA2<>"NC",AA2<>"SF",AA2<>""),AND(AC2<>"NA",AC2<>"C",AC2<>"NC",AC2<>"SF",AC2<>"")),"FALSO",IF(AND(O2="NA",Q2="NA",S2="NA",U2="NA",W2="NA",Y2="NA",AA2="NA",AC2="NA"),"NA",IF(OR(O2="NC",Q2="NC",S2="NC",U2="NC",W2="NC",Y2="NC",AA2="NC",AC2="NC",O2="SF",Q2="SF",S2="SF",U2="SF",W2="SF",Y2="SF",AA2="SF",AC2="SF"),"NC",IF(OR(O2="C",Q2="C",S2="C",U2="C",W2="C",Y2="C",AA2="C",AC2="C"),"C",""))))) -> NC | AG2: =IF(AND(AE2="C",AF2="C"),"UTILIZOU O PDA CORRETAMENTE",IF(AND(AE2="C",AF2="NC"),"UTILIZOU O PDA CORRETAMENTE. NÃO HÁ FOTOS DE TODAS AS ETAPAS",IF(AND(AE2="NC",AF2="NC"),"NÃO UTILIZOU O PDA",IF(AND(AE2="NA",AF2="NA"),"NÃO AVALIADO POR FALHA DE SINCRONISMO")))) -> UTILIZOU O PDA CORRETAMENTE. NÃO HÁ FOTOS DE TODAS AS ETAPAS | AH2: C | AI2: FREGUESIA DO Ó | AJ2: =E2 -> SÃO PAULO | AK2: ÁGUA
A3: ONMF - DIV MANUT SERV OPE FREGUESIA | B3: 2617564324 | C3: INSTALAR VÁLVULA DE REDE DE ÁGUA | D3: REDE DE ÁGUA | E3: SÃO PAULO | F3: RUA ROCHA LIMA | G3: 411 | I3: SITIO DO MORRO | J3: INSTALADA VALVULA DE REDE DE AGUA | K3: sem requadramento da vala rua paralelepípedo | L3: 46027.355 | M3: 46027.358 | N3: RAIMUNDO DA EXALTACAO | O3: C | Q3: C | S3: C | U3: C | W3: C | Y3: NA | AA3: C | AC3: C | AE3: C | AF3: =IF(AND(O3="",Q3="",S3="",U3="",W3="",Y3="",AA3="",AC3=""),"",IF(OR(AND(O3<>"NA",O3<>"C",O3<>"NC",O3<>"SF",O3<>""),AND(Q3<>"NA",Q3<>"C",Q3<>"NC",Q3<>"SF",Q3<>""),AND(S3<>"NA",S3<>"C",S3<>"NC",S3<>"SF",S3<>""),AND(U3<>"NA",U3<>"C",U3<>"NC",U3<>"SF",U3<>""),AND(W3<>"NA",W3<>"C",W3<>"NC",W3<>"SF",W3<>""),AND(Y3<>"NA",Y3<>"C",Y3<>"NC",Y3<>"SF",Y3<>""),AND(AA3<>"NA",AA3<>"C",AA3<>"NC",AA3<>"SF",AA3<>""),AND(AC3<>"NA",AC3<>"C",AC3<>"NC",AC3<>"SF",AC3<>"")),"FALSO",IF(AND(O3="NA",Q3="NA",S3="NA",U3="NA",W3="NA",Y3="NA",AA3="NA",AC3="NA"),"NA",IF(OR(O3="NC",Q3="NC",S3="NC",U3="NC",W3="NC",Y3="NC",AA3="NC",AC3="NC",O3="SF",Q3="SF",S3="SF",U3="SF",W3="SF",Y3="SF",AA3="SF",AC3="SF"),"NC",IF(OR(O3="C",Q3="C",S3="C",U3="C",W3="C",Y3="C",AA3="C",AC3="C"),"C",""))))) -> C | AG3: =IF(AND(AE3="C",AF3="C"),"UTILIZOU O PDA CORRETAMENTE",IF(AND(AE3="C",AF3="NC"),"UTILIZOU O PDA CORRETAMENTE. NÃO HÁ FOTOS DE TODAS AS ETAPAS",IF(AND(AE3="NC",AF3="NC"),"NÃO UTILIZOU O PDA",IF(AND(AE3="NA",AF3="NA"),"NÃO AVALIADO POR FALHA DE SINCRONISMO")))) -> UTILIZOU O PDA CORRETAMENTE | AH3: C | AI3: FREGUESIA DO Ó | AJ3: =E3 -> SÃO PAULO | AK3: ÁGUA
A4: ONMF - DIV MANUT SERV OPE FREGUESIA | B4: 2617975642 | C4: NIVELAR CAIXA DE PARADA | D4: REDE DE ÁGUA | E4: SÃO PAULO | F4: RUA DOUTOR SALLES MALHEIROS | G4: 220 | H4: A C/1 | I4: JD PERI | J4: NIVELADA CAIXA DE PARADA | L4: 46027.395 | M4: 46027.399 | N4: LUIZ CARLOS DA SILVA | O4: C | Q4: C | S4: C | U4: NA | W4: NA | Y4: NA | AA4: C | AC4: C | AE4: C | AF4: =IF(AND(O4="",Q4="",S4="",U4="",W4="",Y4="",AA4="",AC4=""),"",IF(OR(AND(O4<>"NA",O4<>"C",O4<>"NC",O4<>"SF",O4<>""),AND(Q4<>"NA",Q4<>"C",Q4<>"NC",Q4<>"SF",Q4<>""),AND(S4<>"NA",S4<>"C",S4<>"NC",S4<>"SF",S4<>""),AND(U4<>"NA",U4<>"C",U4<>"NC",U4<>"SF",U4<>""),AND(W4<>"NA",W4<>"C",W4<>"NC",W4<>"SF",W4<>""),AND(Y4<>"NA",Y4<>"C",Y4<>"NC",Y4<>"SF",Y4<>""),AND(AA4<>"NA",AA4<>"C",AA4<>"NC",AA4<>"SF",AA4<>""),AND(AC4<>"NA",AC4<>"C",AC4<>"NC",AC4<>"SF",AC4<>"")),"FALSO",IF(AND(O4="NA",Q4="NA",S4="NA",U4="NA",W4="NA",Y4="NA",AA4="NA",AC4="NA"),"NA",IF(OR(O4="NC",Q4="NC",S4="NC",U4="NC",W4="NC",Y4="NC",AA4="NC",AC4="NC",O4="SF",Q4="SF",S4="SF",U4="SF",W4="SF",Y4="SF",AA4="SF",AC4="SF"),"NC",IF(OR(O4="C",Q4="C",S4="C",U4="C",W4="C",Y4="C",AA4="C",AC4="C"),"C",""))))) -> C | AG4: =IF(AND(AE4="C",AF4="C"),"UTILIZOU O PDA CORRETAMENTE",IF(AND(AE4="C",AF4="NC"),"UTILIZOU O PDA CORRETAMENTE. NÃO HÁ FOTOS DE TODAS AS ETAPAS",IF(AND(AE4="NC",AF4="NC"),"NÃO UTILIZOU O PDA",IF(AND(AE4="NA",AF4="NA"),"NÃO AVALIADO POR FALHA DE SINCRONISMO")))) -> UTILIZOU O PDA CORRETAMENTE | AH4: C | AI4: FREGUESIA DO Ó | AJ4: =E4 -> SÃO PAULO | AK4: ÁGUA
A5: ONMF - DIV MANUT SERV OPE FREGUESIA | B5: 2692044832 | C5: VAZAMENTO DE ÁGUA COM INFILTRAÇÃO | D5: VAZAMENTO DE ÁGUA | E5: SÃO PAULO | F5: RUA EDUARDO LUIS TRINDADE | G5: 717 | I5: VL ESPANHOLA | J5: SUPRIMIDO RAMAL DE AGUA ABANDONADO | L5: 46027.417 | M5: 46027.424 | N5: LUIZ FERNANDO DIAS BARBOSA DE ALMEIDA | O5: C | Q5: C | S5: C | U5: C | W5: C | Y5: NA | AA5: C | AC5: C | AE5: C | AF5: =IF(AND(O5="",Q5="",S5="",U5="",W5="",Y5="",AA5="",AC5=""),"",IF(OR(AND(O5<>"NA",O5<>"C",O5<>"NC",O5<>"SF",O5<>""),AND(Q5<>"NA",Q5<>"C",Q5<>"NC",Q5<>"SF",Q5<>""),AND(S5<>"NA",S5<>"C",S5<>"NC",S5<>"SF",S5<>""),AND(U5<>"NA",U5<>"C",U5<>"NC",U5<>"SF",U5<>""),AND(W5<>"NA",W5<>"C",W5<>"NC",W5<>"SF",W5<>""),AND(Y5<>"NA",Y5<>"C",Y5<>"NC",Y5<>"SF",Y5<>""),AND(AA5<>"NA",AA5<>"C",AA5<>"NC",AA5<>"SF",AA5<>""),AND(AC5<>"NA",AC5<>"C",AC5<>"NC",AC5<>"SF",AC5<>"")),"FALSO",IF(AND(O5="NA",Q5="NA",S5="NA",U5="NA",W5="NA",Y5="NA",AA5="NA",AC5="NA"),"NA",IF(OR(O5="NC",Q5="NC",S5="NC",U5="NC",W5="NC",Y5="NC",AA5="NC",AC5="NC",O5="SF",Q5="SF",S5="SF",U5="SF",W5="SF",Y5="SF",AA5="SF",AC5="SF"),"NC",IF(OR(O5="C",Q5="C",S5="C",U5="C",W5="C",Y5="C",AA5="C",AC5="C"),"C",""))))) -> C | AG5: =IF(AND(AE5="C",AF5="C"),"UTILIZOU O PDA CORRETAMENTE",IF(AND(AE5="C",AF5="NC"),"UTILIZOU O PDA CORRETAMENTE. NÃO HÁ FOTOS DE TODAS AS ETAPAS",IF(AND(AE5="NC",AF5="NC"),"NÃO UTILIZOU O PDA",IF(AND(AE5="NA",AF5="NA"),"NÃO AVALIADO POR FALHA DE SINCRONISMO")))) -> UTILIZOU O PDA CORRETAMENTE | AH5: C | AI5: FREGUESIA DO Ó | AJ5: =E5 -> SÃO PAULO | AK5: ÁGUA
A6: ONMF - DIV MANUT SERV OPE FREGUESIA | B6: 2618125401 | C6: VAZAMENTO DE ÁGUA NO PASSEIO | D6: VAZAMENTO DE ÁGUA | E6: SÃO PAULO | F6: RUA NATIVIDADE DA SERRA | G6: 289 | I6: VL NOVA CACHOEIRINHA | J6: SUPRIMIDO RAMAL DE AGUA ABANDONADO | K6: suprimido no cavalete imóvel abandonado | L6: 46027.576 | M6: 46027.583 | N6: RAIMUNDO DA EXALTACAO | O6: NA | Q6: NA | S6: NA | U6: NA | W6: NA | Y6: NA | AA6: NA | AC6: NA | AD6: suprimido no cavalete imóvel abandonado | AE6: NA | AF6: =IF(AND(O6="",Q6="",S6="",U6="",W6="",Y6="",AA6="",AC6=""),"",IF(OR(AND(O6<>"NA",O6<>"C",O6<>"NC",O6<>"SF",O6<>""),AND(Q6<>"NA",Q6<>"C",Q6<>"NC",Q6<>"SF",Q6<>""),AND(S6<>"NA",S6<>"C",S6<>"NC",S6<>"SF",S6<>""),AND(U6<>"NA",U6<>"C",U6<>"NC",U6<>"SF",U6<>""),AND(W6<>"NA",W6<>"C",W6<>"NC",W6<>"SF",W6<>""),AND(Y6<>"NA",Y6<>"C",Y6<>"NC",Y6<>"SF",Y6<>""),AND(AA6<>"NA",AA6<>"C",AA6<>"NC",AA6<>"SF",AA6<>""),AND(AC6<>"NA",AC6<>"C",AC6<>"NC",AC6<>"SF",AC6<>"")),"FALSO",IF(AND(O6="NA",Q6="NA",S6="NA",U6="NA",W6="NA",Y6="NA",AA6="NA",AC6="NA"),"NA",IF(OR(O6="NC",Q6="NC",S6="NC",U6="NC",W6="NC",Y6="NC",AA6="NC",AC6="NC",O6="SF",Q6="SF",S6="SF",U6="SF",W6="SF",Y6="SF",AA6="SF",AC6="SF"),"NC",IF(OR(O6="C",Q6="C",S6="C",U6="C",W6="C",Y6="C",AA6="C",AC6="C"),"C",""))))) -> NA | AG6: =IF(AND(AE6="C",AF6="C"),"UTILIZOU O PDA CORRETAMENTE",IF(AND(AE6="C",AF6="NC"),"UTILIZOU O PDA CORRETAMENTE. NÃO HÁ FOTOS DE TODAS AS ETAPAS",IF(AND(AE6="NC",AF6="NC"),"NÃO UTILIZOU O PDA",IF(AND(AE6="NA",AF6="NA"),"NÃO AVALIADO POR FALHA DE SINCRONISMO")))) -> NÃO AVALIADO POR FALHA DE SINCRONISMO | AI6: FREGUESIA DO Ó | AJ6: =E6 -> SÃO PAULO | AK6: ÁGUA
A7: ONMF - DIV MANUT SERV OPE FREGUESIA | B7: 2618175841 | C7: VAZAMENTO DE ÁGUA NÃO VISÍVEL RAMAL | D7: VAZAMENTO DE ÁGUA | E7: SÃO PAULO | F7: RUA VELOSO DA FONSECA | G7: 55 | H7: C/1 | I7: V ALBERTINA | J7: SUPRIMIDO RAMAL AGUA ABAND NÃO VISIVEL | K7: sem reposição | L7: 46027.628 | M7: 46027.659 | N7: GENILSON MARTINS FERNANDES | O7: C | Q7: C | S7: C | U7: C | W7: C | Y7: NA | AA7: C | AC7: C | AE7: C | AF7: =IF(AND(O7="",Q7="",S7="",U7="",W7="",Y7="",AA7="",AC7=""),"",IF(OR(AND(O7<>"NA",O7<>"C",O7<>"NC",O7<>"SF",O7<>""),AND(Q7<>"NA",Q7<>"C",Q7<>"NC",Q7<>"SF",Q7<>""),AND(S7<>"NA",S7<>"C",S7<>"NC",S7<>"SF",S7<>""),AND(U7<>"NA",U7<>"C",U7<>"NC",U7<>"SF",U7<>""),AND(W7<>"NA",W7<>"C",W7<>"NC",W7<>"SF",W7<>""),AND(Y7<>"NA",Y7<>"C",Y7<>"NC",Y7<>"SF",Y7<>""),AND(AA7<>"NA",AA7<>"C",AA7<>"NC",AA7<>"SF",AA7<>""),AND(AC7<>"NA",AC7<>"C",AC7<>"NC",AC7<>"SF",AC7<>"")),"FALSO",IF(AND(O7="NA",Q7="NA",S7="NA",U7="NA",W7="NA",Y7="NA",AA7="NA",AC7="NA"),"NA",IF(OR(O7="NC",Q7="NC",S7="NC",U7="NC",W7="NC",Y7="NC",AA7="NC",AC7="NC",O7="SF",Q7="SF",S7="SF",U7="SF",W7="SF",Y7="SF",AA7="SF",AC7="SF"),"NC",IF(OR(O7="C",Q7="C",S7="C",U7="C",W7="C",Y7="C",AA7="C",AC7="C"),"C",""))))) -> C | AG7: =IF(AND(AE7="C",AF7="C"),"UTILIZOU O PDA CORRETAMENTE",IF(AND(AE7="C",AF7="NC"),"UTILIZOU O PDA CORRETAMENTE. NÃO HÁ FOTOS DE TODAS AS ETAPAS",IF(AND(AE7="NC",AF7="NC"),"NÃO UTILIZOU O PDA",IF(AND(AE7="NA",AF7="NA"),"NÃO AVALIADO POR FALHA DE SINCRONISMO")))) -> UTILIZOU O PDA CORRETAMENTE | AH7: C | AI7: FREGUESIA DO Ó | AJ7: =E7 -> SÃO PAULO | AK7: ÁGUA
A8: ONMF - DIV MANUT SERV OPE FREGUESIA | B8: 2618305876 | C8: TROCAR RAMAL DE ÁGUA PREVENTIVA | D8: RAMAL DE ÁGUA | E8: SÃO PAULO | F8: RUA ATAQUE | G8: 30 | I8: VL ESMERALDA | J8: TROCA DE RAMAL DE AGUA PREVENTIVA | K8: fotos estão nessa OS 2617309333 reposição em obra | L8: 46027.622 | M8: 46027.625 | N8: IZAQUEU FERREIRA DE SOUSA | O8: C | Q8: C | S8: C | U8: C | W8: C | Y8: C | AA8: C | AC8: C | AE8: C | AF8: =IF(AND(O8="",Q8="",S8="",U8="",W8="",Y8="",AA8="",AC8=""),"",IF(OR(AND(O8<>"NA",O8<>"C",O8<>"NC",O8<>"SF",O8<>""),AND(Q8<>"NA",Q8<>"C",Q8<>"NC",Q8<>"SF",Q8<>""),AND(S8<>"NA",S8<>"C",S8<>"NC",S8<>"SF",S8<>""),AND(U8<>"NA",U8<>"C",U8<>"NC",U8<>"SF",U8<>""),AND(W8<>"NA",W8<>"C",W8<>"NC",W8<>"SF",W8<>""),AND(Y8<>"NA",Y8<>"C",Y8<>"NC",Y8<>"SF",Y8<>""),AND(AA8<>"NA",AA8<>"C",AA8<>"NC",AA8<>"SF",AA8<>""),AND(AC8<>"NA",AC8<>"C",AC8<>"NC",AC8<>"SF",AC8<>"")),"FALSO",IF(AND(O8="NA",Q8="NA",S8="NA",U8="NA",W8="NA",Y8="NA",AA8="NA",AC8="NA"),"NA",IF(OR(O8="NC",Q8="NC",S8="NC",U8="NC",W8="NC",Y8="NC",AA8="NC",AC8="NC",O8="SF",Q8="SF",S8="SF",U8="SF",W8="SF",Y8="SF",AA8="SF",AC8="SF"),"NC",IF(OR(O8="C",Q8="C",S8="C",U8="C",W8="C",Y8="C",AA8="C",AC8="C"),"C",""))))) -> C | AG8: =IF(AND(AE8="C",AF8="C"),"UTILIZOU O PDA CORRETAMENTE",IF(AND(AE8="C",AF8="NC"),"UTILIZOU O PDA CORRETAMENTE. NÃO HÁ FOTOS DE TODAS AS ETAPAS",IF(AND(AE8="NC",AF8="NC"),"NÃO UTILIZOU O PDA",IF(AND(AE8="NA",AF8="NA"),"NÃO AVALIADO POR FALHA DE SINCRONISMO")))) -> UTILIZOU O PDA CORRETAMENTE | AH8: C | AI8: FREGUESIA DO Ó | AJ8: =E8 -> SÃO PAULO | AK8: ÁGUA
A9: ONMF - DIV MANUT SERV OPE FREGUESIA | B9: 2692041383 | C9: SONDAR RAMAL DE ÁGUA | D9: OUTROS SERVIÇOS DE ÁGUA | E9: SÃO PAULO | F9: RUA QUARTIM BARBOSA | G9: 134 | I9: V STA MARIA | J9: SONDAGEM DE RAMAL DE AGUA | L9: 46027.468 | M9: 46027.474 | N9: LUIZ FERNANDO DIAS BARBOSA DE ALMEIDA | O9: C | Q9: C | S9: C | U9: C | W9: C | Y9: NA | AA9: C | AC9: NC | AD9: AUSÊNCIA DE RÉGUA, TRENA E CARIMBO | AE9: C | AF9: =IF(AND(O9="",Q9="",S9="",U9="",W9="",Y9="",AA9="",AC9=""),"",IF(OR(AND(O9<>"NA",O9<>"C",O9<>"NC",O9<>"SF",O9<>""),AND(Q9<>"NA",Q9<>"C",Q9<>"NC",Q9<>"SF",Q9<>""),AND(S9<>"NA",S9<>"C",S9<>"NC",S9<>"SF",S9<>""),AND(U9<>"NA",U9<>"C",U9<>"NC",U9<>"SF",U9<>""),AND(W9<>"NA",W9<>"C",W9<>"NC",W9<>"SF",W9<>""),AND(Y9<>"NA",Y9<>"C",Y9<>"NC",Y9<>"SF",Y9<>""),AND(AA9<>"NA",AA9<>"C",AA9<>"NC",AA9<>"SF",AA9<>""),AND(AC9<>"NA",AC9<>"C",AC9<>"NC",AC9<>"SF",AC9<>"")),"FALSO",IF(AND(O9="NA",Q9="NA",S9="NA",U9="NA",W9="NA",Y9="NA",AA9="NA",AC9="NA"),"NA",IF(OR(O9="NC",Q9="NC",S9="NC",U9="NC",W9="NC",Y9="NC",AA9="NC",AC9="NC",O9="SF",Q9="SF",S9="SF",U9="SF",W9="SF",Y9="SF",AA9="SF",AC9="SF"),"NC",IF(OR(O9="C",Q9="C",S9="C",U9="C",W9="C",Y9="C",AA9="C",AC9="C"),"C",""))))) -> NC | AG9: =IF(AND(AE9="C",AF9="C"),"UTILIZOU O PDA CORRETAMENTE",IF(AND(AE9="C",AF9="NC"),"UTILIZOU O PDA CORRETAMENTE. NÃO HÁ FOTOS DE TODAS AS ETAPAS",IF(AND(AE9="NC",AF9="NC"),"NÃO UTILIZOU O PDA",IF(AND(AE9="NA",AF9="NA"),"NÃO AVALIADO POR FALHA DE SINCRONISMO")))) -> UTILIZOU O PDA CORRETAMENTE. NÃO HÁ FOTOS DE TODAS AS ETAPAS | AI9: FREGUESIA DO Ó | AJ9: =E9 -> SÃO PAULO | AK9: ÁGUA
A10: ONMF - DIV MANUT SERV OPE FREGUESIA | B10: 2617950354 | C10: TROCAR RAMAL DE ÁGUA - VAZ NÃO VISIVEL | D10: VAZAMENTO DE ÁGUA | E10: SÃO PAULO | F10: RUA MANUEL MADRUGA | G10: 72 | I10: VL MANOEL LOPES | J10: TROCA DE RAMAL DE AGUA NÃO VISIVEL | K10: as fotos tá na o.s 2617950354, mais ccv | L10: 46027.499 | M10: 46027.501 | N10: GENILSON MARTINS FERNANDES | O10: C | Q10: SF | S10: SF | U10: SF | W10: SF | Y10: SF | AA10: SF | AC10: SF | AE10: NC | AF10: =IF(AND(O10="",Q10="",S10="",U10="",W10="",Y10="",AA10="",AC10=""),"",IF(OR(AND(O10<>"NA",O10<>"C",O10<>"NC",O10<>"SF",O10<>""),AND(Q10<>"NA",Q10<>"C",Q10<>"NC",Q10<>"SF",Q10<>""),AND(S10<>"NA",S10<>"C",S10<>"NC",S10<>"SF",S10<>""),AND(U10<>"NA",U10<>"C",U10<>"NC",U10<>"SF",U10<>""),AND(W10<>"NA",W10<>"C",W10<>"NC",W10<>"SF",W10<>""),AND(Y10<>"NA",Y10<>"C",Y10<>"NC",Y10<>"SF",Y10<>""),AND(AA10<>"NA",AA10<>"C",AA10<>"NC",AA10<>"SF",AA10<>""),AND(AC10<>"NA",AC10<>"C",AC10<>"NC",AC10<>"SF",AC10<>"")),"FALSO",IF(AND(O10="NA",Q10="NA",S10="NA",U10="NA",W10="NA",Y10="NA",AA10="NA",AC10="NA"),"NA",IF(OR(O10="NC",Q10="NC",S10="NC",U10="NC",W10="NC",Y10="NC",AA10="NC",AC10="NC",O10="SF",Q10="SF",S10="SF",U10="SF",W10="SF",Y10="SF",AA10="SF",AC10="SF"),"NC",IF(OR(O10="C",Q10="C",S10="C",U10="C",W10="C",Y10="C",AA10="C",AC10="C"),"C",""))))) -> NC | AG10: =IF(AND(AE10="C",AF10="C"),"UTILIZOU O PDA CORRETAMENTE",IF(AND(AE10="C",AF10="NC"),"UTILIZOU O PDA CORRETAMENTE. NÃO HÁ FOTOS DE TODAS AS ETAPAS",IF(AND(AE10="NC",AF10="NC"),"NÃO UTILIZOU O PDA",IF(AND(AE10="NA",AF10="NA"),"NÃO AVALIADO POR FALHA DE SINCRONISMO")))) -> NÃO UTILIZOU O PDA | AH10: C | AI10: FREGUESIA DO Ó | AJ10: =E10 -> SÃO PAULO | AK10: ÁGUA
A11: ONMF - DIV MANUT SERV OPE FREGUESIA | B11: 2618310074 | C11: TROCAR RAMAL DE ÁGUA - VAZ NÃO VISIVEL | D11: VAZAMENTO DE ÁGUA | E11: SÃO PAULO | F11: RUA ESTADO DE RONDONIA | G11: 281 | I11: JD CIDADE PIRITUBA | J11: TROCA DE RAMAL DE AGUA NÃO VISIVEL | K11: fotos na os 2691986722 | L11: 46027.625 | M11: 46027.628 | N11: FRANCISCO CARLOS LEITE DA SILVA | O11: C | Q11: C | S11: C | U11: C | W11: C | Y11: C | AA11: C | AC11: C | AE11: C | AF11: =IF(AND(O11="",Q11="",S11="",U11="",W11="",Y11="",AA11="",AC11=""),"",IF(OR(AND(O11<>"NA",O11<>"C",O11<>"NC",O11<>"SF",O11<>""),AND(Q11<>"NA",Q11<>"C",Q11<>"NC",Q11<>"SF",Q11<>""),AND(S11<>"NA",S11<>"C",S11<>"NC",S11<>"SF",S11<>""),AND(U11<>"NA",U11<>"C",U11<>"NC",U11<>"SF",U11<>""),AND(W11<>"NA",W11<>"C",W11<>"NC",W11<>"SF",W11<>""),AND(Y11<>"NA",Y11<>"C",Y11<>"NC",Y11<>"SF",Y11<>""),AND(AA11<>"NA",AA11<>"C",AA11<>"NC",AA11<>"SF",AA11<>""),AND(AC11<>"NA",AC11<>"C",AC11<>"NC",AC11<>"SF",AC11<>"")),"FALSO",IF(AND(O11="NA",Q11="NA",S11="NA",U11="NA",W11="NA",Y11="NA",AA11="NA",AC11="NA"),"NA",IF(OR(O11="NC",Q11="NC",S11="NC",U11="NC",W11="NC",Y11="NC",AA11="NC",AC11="NC",O11="SF",Q11="SF",S11="SF",U11="SF",W11="SF",Y11="SF",AA11="SF",AC11="SF"),"NC",IF(OR(O11="C",Q11="C",S11="C",U11="C",W11="C",Y11="C",AA11="C",AC11="C"),"C",""))))) -> C | AG11: =IF(AND(AE11="C",AF11="C"),"UTILIZOU O PDA CORRETAMENTE",IF(AND(AE11="C",AF11="NC"),"UTILIZOU O PDA CORRETAMENTE. NÃO HÁ FOTOS DE TODAS AS ETAPAS",IF(AND(AE11="NC",AF11="NC"),"NÃO UTILIZOU O PDA",IF(AND(AE11="NA",AF11="NA"),"NÃO AVALIADO POR FALHA DE SINCRONISMO")))) -> UTILIZOU O PDA CORRETAMENTE | AH11: C | AI11: FREGUESIA DO Ó | AJ11: =E11 -> SÃO PAULO | AK11: ÁGUA
A12: ONMF - DIV MANUT SERV OPE FREGUESIA | B12: 2617963666 | C12: INCLUIR LIG DE ÁGUA EM CAV MÚLTIPLO S/V | D12: LIGAÇÃO DE ÁGUA | E12: SÃO PAULO | F12: RUA CACHOEIRA DOS ANTUNES | G12: 133 | H12: C/5 | I12: VL DIONISIA | J12: INCLUSÃO DE LIG DE AGUA EM CAV MULT S/V | K12: feita uma ligação ária de risco viela viela em obras criete vai fazer | L12: 46058.428 | M12: 46058.431 | N12: ADECARLOS DE SOUSA SANTOS | O12: SF | Q12: SF | S12: SF | U12: SF | W12: SF | Y12: SF | AA12: SF | AC12: SF | AE12: NC | AF12: =IF(AND(O12="",Q12="",S12="",U12="",W12="",Y12="",AA12="",AC12=""),"",IF(OR(AND(O12<>"NA",O12<>"C",O12<>"NC",O12<>"SF",O12<>""),AND(Q12<>"NA",Q12<>"C",Q12<>"NC",Q12<>"SF",Q12<>""),AND(S12<>"NA",S12<>"C",S12<>"NC",S12<>"SF",S12<>""),AND(U12<>"NA",U12<>"C",U12<>"NC",U12<>"SF",U12<>""),AND(W12<>"NA",W12<>"C",W12<>"NC",W12<>"SF",W12<>""),AND(Y12<>"NA",Y12<>"C",Y12<>"NC",Y12<>"SF",Y12<>""),AND(AA12<>"NA",AA12<>"C",AA12<>"NC",AA12<>"SF",AA12<>""),AND(AC12<>"NA",AC12<>"C",AC12<>"NC",AC12<>"SF",AC12<>"")),"FALSO",IF(AND(O12="NA",Q12="NA",S12="NA",U12="NA",W12="NA",Y12="NA",AA12="NA",AC12="NA"),"NA",IF(OR(O12="NC",Q12="NC",S12="NC",U12="NC",W12="NC",Y12="NC",AA12="NC",AC12="NC",O12="SF",Q12="SF",S12="SF",U12="SF",W12="SF",Y12="SF",AA12="SF",AC12="SF"),"NC",IF(OR(O12="C",Q12="C",S12="C",U12="C",W12="C",Y12="C",AA12="C",AC12="C"),"C",""))))) -> NC | AG12: =IF(AND(AE12="C",AF12="C"),"UTILIZOU O PDA CORRETAMENTE",IF(AND(AE12="C",AF12="NC"),"UTILIZOU O PDA CORRETAMENTE. NÃO HÁ FOTOS DE TODAS AS ETAPAS",IF(AND(AE12="NC",AF12="NC"),"NÃO UTILIZOU O PDA",IF(AND(AE12="NA",AF12="NA"),"NÃO AVALIADO POR FALHA DE SINCRONISMO")))) -> NÃO UTILIZOU O PDA | AH12: C | AI12: FREGUESIA DO Ó | AJ12: =E12 -> SÃO PAULO | AK12: ÁGUA
A13: ONMF - DIV MANUT SERV OPE FREGUESIA | B13: 2618378189 | C13: VAZAMENTO DE ÁGUA LEITO PAVIMENTADO | D13: VAZAMENTO DE ÁGUA | E13: SÃO PAULO | F13: AVENIDA SANTA INES | G13: 836 | H13: POCO LEIT. | I13: MANDAQUI | J13: SUPRIMIDO RAMAL DE AGUA ABANDONADO | L13: 46058.396 | M13: 46058.471 | N13: GENILSON MARTINS FERNANDES | O13: C | Q13: C | S13: C | U13: C | W13: C | Y13: NA | AA13: C | AC13: C | AE13: C | AF13: =IF(AND(O13="",Q13="",S13="",U13="",W13="",Y13="",AA13="",AC13=""),"",IF(OR(AND(O13<>"NA",O13<>"C",O13<>"NC",O13<>"SF",O13<>""),AND(Q13<>"NA",Q13<>"C",Q13<>"NC",Q13<>"SF",Q13<>""),AND(S13<>"NA",S13<>"C",S13<>"NC",S13<>"SF",S13<>""),AND(U13<>"NA",U13<>"C",U13<>"NC",U13<>"SF",U13<>""),AND(W13<>"NA",W13<>"C",W13<>"NC",W13<>"SF",W13<>""),AND(Y13<>"NA",Y13<>"C",Y13<>"NC",Y13<>"SF",Y13<>""),AND(AA13<>"NA",AA13<>"C",AA13<>"NC",AA13<>"SF",AA13<>""),AND(AC13<>"NA",AC13<>"C",AC13<>"NC",AC13<>"SF",AC13<>"")),"FALSO",IF(AND(O13="NA",Q13="NA",S13="NA",U13="NA",W13="NA",Y13="NA",AA13="NA",AC13="NA"),"NA",IF(OR(O13="NC",Q13="NC",S13="NC",U13="NC",W13="NC",Y13="NC",AA13="NC",AC13="NC",O13="SF",Q13="SF",S13="SF",U13="SF",W13="SF",Y13="SF",AA13="SF",AC13="SF"),"NC",IF(OR(O13="C",Q13="C",S13="C",U13="C",W13="C",Y13="C",AA13="C",AC13="C"),"C",""))))) -> C | AG13: =IF(AND(AE13="C",AF13="C"),"UTILIZOU O PDA CORRETAMENTE",IF(AND(AE13="C",AF13="NC"),"UTILIZOU O PDA CORRETAMENTE. NÃO HÁ FOTOS DE TODAS AS ETAPAS",IF(AND(AE13="NC",AF13="NC"),"NÃO UTILIZOU O PDA",IF(AND(AE13="NA",AF13="NA"),"NÃO AVALIADO POR FALHA DE SINCRONISMO")))) -> UTILIZOU O PDA CORRETAMENTE | AH13: C | AI13: FREGUESIA DO Ó | AJ13: =E13 -> SÃO PAULO | AK13: ÁGUA
A14: ONMF - DIV MANUT SERV OPE FREGUESIA | B14: 2617563429 | C14: INSTALAR VÁLVULA DE REDE DE ÁGUA | D14: REDE DE ÁGUA | E14: SÃO PAULO | F14: RUA CAROLINA SOARES | G14: 465 | I14: V DIVA | J14: INSTALADA VALVULA DE REDE DE AGUA | K14: FOTOS E REPOSIÇÃO NA OS 2617563355 REDE 225 | L14: 46058.25 | M14: 46058.251 | N14: ROMERO FRANCISCO DOS SANTOS | O14: C | Q14: C | S14: C | U14: C | W14: SF | Y14: NA | AA14: C | AC14: C | AE14: C | AF14: =IF(AND(O14="",Q14="",S14="",U14="",W14="",Y14="",AA14="",AC14=""),"",IF(OR(AND(O14<>"NA",O14<>"C",O14<>"NC",O14<>"SF",O14<>""),AND(Q14<>"NA",Q14<>"C",Q14<>"NC",Q14<>"SF",Q14<>""),AND(S14<>"NA",S14<>"C",S14<>"NC",S14<>"SF",S14<>""),AND(U14<>"NA",U14<>"C",U14<>"NC",U14<>"SF",U14<>""),AND(W14<>"NA",W14<>"C",W14<>"NC",W14<>"SF",W14<>""),AND(Y14<>"NA",Y14<>"C",Y14<>"NC",Y14<>"SF",Y14<>""),AND(AA14<>"NA",AA14<>"C",AA14<>"NC",AA14<>"SF",AA14<>""),AND(AC14<>"NA",AC14<>"C",AC14<>"NC",AC14<>"SF",AC14<>"")),"FALSO",IF(AND(O14="NA",Q14="NA",S14="NA",U14="NA",W14="NA",Y14="NA",AA14="NA",AC14="NA"),"NA",IF(OR(O14="NC",Q14="NC",S14="NC",U14="NC",W14="NC",Y14="NC",AA14="NC",AC14="NC",O14="SF",Q14="SF",S14="SF",U14="SF",W14="SF",Y14="SF",AA14="SF",AC14="SF"),"NC",IF(OR(O14="C",Q14="C",S14="C",U14="C",W14="C",Y14="C",AA14="C",AC14="C"),"C",""))))) -> NC | AG14: =IF(AND(AE14="C",AF14="C"),"UTILIZOU O PDA CORRETAMENTE",IF(AND(AE14="C",AF14="NC"),"UTILIZOU O PDA CORRETAMENTE. NÃO HÁ FOTOS DE TODAS AS ETAPAS",IF(AND(AE14="NC",AF14="NC"),"NÃO UTILIZOU O PDA",IF(AND(AE14="NA",AF14="NA"),"NÃO AVALIADO POR FALHA DE SINCRONISMO")))) -> UTILIZOU O PDA CORRETAMENTE. NÃO HÁ FOTOS DE TODAS AS ETAPAS | AH14: C | AI14: FREGUESIA DO Ó | AJ14: =E14 -> SÃO PAULO | AK14: ÁGUA
A15: ONMF - DIV MANUT SERV OPE FREGUESIA | B15: 2618384154 | C15: SONDAR REDE DE ÁGUA | D15: OUTROS SERVIÇOS DE ÁGUA | E15: SÃO PAULO | F15: RUA SANTA AUTA | G15: 83 | I15: FREGUESIA DO O | J15: SONDAGEM DE REDE DE AGUA | K15: S observação as foto está na os 2617628445 | L15: 46058.572 | M15: 46058.576 | N15: LUIZ CARLOS DA SILVA | O15: C | Q15: C | S15: C | U15: C | W15: NA | Y15: NA | AA15: C | AC15: C | AE15: C | AF15: =IF(AND(O15="",Q15="",S15="",U15="",W15="",Y15="",AA15="",AC15=""),"",IF(OR(AND(O15<>"NA",O15<>"C",O15<>"NC",O15<>"SF",O15<>""),AND(Q15<>"NA",Q15<>"C",Q15<>"NC",Q15<>"SF",Q15<>""),AND(S15<>"NA",S15<>"C",S15<>"NC",S15<>"SF",S15<>""),AND(U15<>"NA",U15<>"C",U15<>"NC",U15<>"SF",U15<>""),AND(W15<>"NA",W15<>"C",W15<>"NC",W15<>"SF",W15<>""),AND(Y15<>"NA",Y15<>"C",Y15<>"NC",Y15<>"SF",Y15<>""),AND(AA15<>"NA",AA15<>"C",AA15<>"NC",AA15<>"SF",AA15<>""),AND(AC15<>"NA",AC15<>"C",AC15<>"NC",AC15<>"SF",AC15<>"")),"FALSO",IF(AND(O15="NA",Q15="NA",S15="NA",U15="NA",W15="NA",Y15="NA",AA15="NA",AC15="NA"),"NA",IF(OR(O15="NC",Q15="NC",S15="NC",U15="NC",W15="NC",Y15="NC",AA15="NC",AC15="NC",O15="SF",Q15="SF",S15="SF",U15="SF",W15="SF",Y15="SF",AA15="SF",AC15="SF"),"NC",IF(OR(O15="C",Q15="C",S15="C",U15="C",W15="C",Y15="C",AA15="C",AC15="C"),"C",""))))) -> C | AG15: =IF(AND(AE15="C",AF15="C"),"UTILIZOU O PDA CORRETAMENTE",IF(AND(AE15="C",AF15="NC"),"UTILIZOU O PDA CORRETAMENTE. NÃO HÁ FOTOS DE TODAS AS ETAPAS",IF(AND(AE15="NC",AF15="NC"),"NÃO UTILIZOU O PDA",IF(AND(AE15="NA",AF15="NA"),"NÃO AVALIADO POR FALHA DE SINCRONISMO")))) -> UTILIZOU O PDA CORRETAMENTE | AH15: C | AI15: FREGUESIA DO Ó | AJ15: =E15 -> SÃO PAULO | AK15: ÁGUA
A16: ONMF - DIV MANUT SERV OPE FREGUESIA | B16: 2618386742 | C16: SONDAR REDE DE ÁGUA | D16: OUTROS SERVIÇOS DE ÁGUA | E16: SÃO PAULO | F16: RUA BENEDITO GUEDES DE OLIVEIRA | G16: 309 | I16: VL PALMEIRAS | J16: SONDAGEM DE REDE DE AGUA | K16: What's the observação as fotos está na oes2617628663 | L16: 46058.574 | M16: 46058.577 | N16: LUIZ CARLOS DA SILVA | O16: C | Q16: C | S16: C | U16: NA | W16: NA | Y16: NA | AA16: C | AC16: C | AE16: C | AF16: =IF(AND(O16="",Q16="",S16="",U16="",W16="",Y16="",AA16="",AC16=""),"",IF(OR(AND(O16<>"NA",O16<>"C",O16<>"NC",O16<>"SF",O16<>""),AND(Q16<>"NA",Q16<>"C",Q16<>"NC",Q16<>"SF",Q16<>""),AND(S16<>"NA",S16<>"C",S16<>"NC",S16<>"SF",S16<>""),AND(U16<>"NA",U16<>"C",U16<>"NC",U16<>"SF",U16<>""),AND(W16<>"NA",W16<>"C",W16<>"NC",W16<>"SF",W16<>""),AND(Y16<>"NA",Y16<>"C",Y16<>"NC",Y16<>"SF",Y16<>""),AND(AA16<>"NA",AA16<>"C",AA16<>"NC",AA16<>"SF",AA16<>""),AND(AC16<>"NA",AC16<>"C",AC16<>"NC",AC16<>"SF",AC16<>"")),"FALSO",IF(AND(O16="NA",Q16="NA",S16="NA",U16="NA",W16="NA",Y16="NA",AA16="NA",AC16="NA"),"NA",IF(OR(O16="NC",Q16="NC",S16="NC",U16="NC",W16="NC",Y16="NC",AA16="NC",AC16="NC",O16="SF",Q16="SF",S16="SF",U16="SF",W16="SF",Y16="SF",AA16="SF",AC16="SF"),"NC",IF(OR(O16="C",Q16="C",S16="C",U16="C",W16="C",Y16="C",AA16="C",AC16="C"),"C",""))))) -> C | AG16: =IF(AND(AE16="C",AF16="C"),"UTILIZOU O PDA CORRETAMENTE",IF(AND(AE16="C",AF16="NC"),"UTILIZOU O PDA CORRETAMENTE. NÃO HÁ FOTOS DE TODAS AS ETAPAS",IF(AND(AE16="NC",AF16="NC"),"NÃO UTILIZOU O PDA",IF(AND(AE16="NA",AF16="NA"),"NÃO AVALIADO POR FALHA DE SINCRONISMO")))) -> UTILIZOU O PDA CORRETAMENTE | AH16: C | AI16: FREGUESIA DO Ó | AJ16: =E16 -> SÃO PAULO | AK16: ÁGUA
A17: ONMF - DIV MANUT SERV OPE FREGUESIA | B17: 2692149978 | C17: TROCAR RAMAL DE ÁGUA | D17: VAZAMENTO DE ÁGUA | E17: SÃO PAULO | F17: RUA SANTA ROMANA | G17: 282 | I17: V PEREIRA CERCA | J17: TROCA DE RAMAL DE AGUA | K17: SERVIÇO EXECUTADO NO NUMERO 288. | L17: 46058.538 | M17: 46058.54 | N17: LUIZ FERNANDO DIAS BARBOSA DE ALMEIDA | O17: C | Q17: SF | S17: SF | U17: SF | W17: SF | Y17: SF | AA17: SF | AC17: NC | AD17: AUSÊNCIA DE RÉGUA, TRENA E CARIMBO | AE17: C | AF17: =IF(AND(O17="",Q17="",S17="",U17="",W17="",Y17="",AA17="",AC17=""),"",IF(OR(AND(O17<>"NA",O17<>"C",O17<>"NC",O17<>"SF",O17<>""),AND(Q17<>"NA",Q17<>"C",Q17<>"NC",Q17<>"SF",Q17<>""),AND(S17<>"NA",S17<>"C",S17<>"NC",S17<>"SF",S17<>""),AND(U17<>"NA",U17<>"C",U17<>"NC",U17<>"SF",U17<>""),AND(W17<>"NA",W17<>"C",W17<>"NC",W17<>"SF",W17<>""),AND(Y17<>"NA",Y17<>"C",Y17<>"NC",Y17<>"SF",Y17<>""),AND(AA17<>"NA",AA17<>"C",AA17<>"NC",AA17<>"SF",AA17<>""),AND(AC17<>"NA",AC17<>"C",AC17<>"NC",AC17<>"SF",AC17<>"")),"FALSO",IF(AND(O17="NA",Q17="NA",S17="NA",U17="NA",W17="NA",Y17="NA",AA17="NA",AC17="NA"),"NA",IF(OR(O17="NC",Q17="NC",S17="NC",U17="NC",W17="NC",Y17="NC",AA17="NC",AC17="NC",O17="SF",Q17="SF",S17="SF",U17="SF",W17="SF",Y17="SF",AA17="SF",AC17="SF"),"NC",IF(OR(O17="C",Q17="C",S17="C",U17="C",W17="C",Y17="C",AA17="C",AC17="C"),"C",""))))) -> NC | AG17: =IF(AND(AE17="C",AF17="C"),"UTILIZOU O PDA CORRETAMENTE",IF(AND(AE17="C",AF17="NC"),"UTILIZOU O PDA CORRETAMENTE. NÃO HÁ FOTOS DE TODAS AS ETAPAS",IF(AND(AE17="NC",AF17="NC"),"NÃO UTILIZOU O PDA",IF(AND(AE17="NA",AF17="NA"),"NÃO AVALIADO POR FALHA DE SINCRONISMO")))) -> UTILIZOU O PDA CORRETAMENTE. NÃO HÁ FOTOS DE TODAS AS ETAPAS | AH17: C | AI17: FREGUESIA DO Ó | AJ17: =E17 -> SÃO PAULO | AK17: ÁGUA
A18: ONMF - DIV MANUT SERV OPE FREGUESIA | B18: 2692161089 | C18: VAZAMENTO DE ÁGUA LEITO PAVIMENTADO | D18: VAZAMENTO DE ÁGUA | E18: SÃO PAULO | F18: RUA GUMERCINDO DE PAULA | G18: 265 | I18: JD MONTE ALEGRE | J18: SUPRIMIDO RAMAL DE AGUA ABANDONADO | L18: 46058.672 | M18: 46058.684 | N18: GENILSON MARTINS FERNANDES | O18: C | Q18: C | S18: C | U18: C | W18: C | Y18: NA | AA18: C | AC18: C | AE18: C | AF18: =IF(AND(O18="",Q18="",S18="",U18="",W18="",Y18="",AA18="",AC18=""),"",IF(OR(AND(O18<>"NA",O18<>"C",O18<>"NC",O18<>"SF",O18<>""),AND(Q18<>"NA",Q18<>"C",Q18<>"NC",Q18<>"SF",Q18<>""),AND(S18<>"NA",S18<>"C",S18<>"NC",S18<>"SF",S18<>""),AND(U18<>"NA",U18<>"C",U18<>"NC",U18<>"SF",U18<>""),AND(W18<>"NA",W18<>"C",W18<>"NC",W18<>"SF",W18<>""),AND(Y18<>"NA",Y18<>"C",Y18<>"NC",Y18<>"SF",Y18<>""),AND(AA18<>"NA",AA18<>"C",AA18<>"NC",AA18<>"SF",AA18<>""),AND(AC18<>"NA",AC18<>"C",AC18<>"NC",AC18<>"SF",AC18<>"")),"FALSO",IF(AND(O18="NA",Q18="NA",S18="NA",U18="NA",W18="NA",Y18="NA",AA18="NA",AC18="NA"),"NA",IF(OR(O18="NC",Q18="NC",S18="NC",U18="NC",W18="NC",Y18="NC",AA18="NC",AC18="NC",O18="SF",Q18="SF",S18="SF",U18="SF",W18="SF",Y18="SF",AA18="SF",AC18="SF"),"NC",IF(OR(O18="C",Q18="C",S18="C",U18="C",W18="C",Y18="C",AA18="C",AC18="C"),"C",""))))) -> C | AG18: =IF(AND(AE18="C",AF18="C"),"UTILIZOU O PDA CORRETAMENTE",IF(AND(AE18="C",AF18="NC"),"UTILIZOU O PDA CORRETAMENTE. NÃO HÁ FOTOS DE TODAS AS ETAPAS",IF(AND(AE18="NC",AF18="NC"),"NÃO UTILIZOU O PDA",IF(AND(AE18="NA",AF18="NA"),"NÃO AVALIADO POR FALHA DE SINCRONISMO")))) -> UTILIZOU O PDA CORRETAMENTE | AH18: C | AI18: FREGUESIA DO Ó | AJ18: =E18 -> SÃO PAULO | AK18: ÁGUA
A19: ONMF - DIV MANUT SERV OPE FREGUESIA | B19: 2692186761 | C19: SONDAR RAMAL DE ÁGUA | D19: OUTROS SERVIÇOS DE ÁGUA | E19: SÃO PAULO | F19: RUA GRACIANO ALTIERI | G19: 17 | H19: C/9 | I19: CASA VERDE ALTA | J19: SONDAGEM DE RAMAL DE AGUA | K19: Sei sinalização devido detro de uma viela | L19: 46058.632 | M19: 46058.633 | N19: ADECARLOS DE SOUSA SANTOS | O19: C | Q19: SF | S19: C | U19: C | W19: C | Y19: NA | AA19: C | AC19: C | AE19: C | AF19: =IF(AND(O19="",Q19="",S19="",U19="",W19="",Y19="",AA19="",AC19=""),"",IF(OR(AND(O19<>"NA",O19<>"C",O19<>"NC",O19<>"SF",O19<>""),AND(Q19<>"NA",Q19<>"C",Q19<>"NC",Q19<>"SF",Q19<>""),AND(S19<>"NA",S19<>"C",S19<>"NC",S19<>"SF",S19<>""),AND(U19<>"NA",U19<>"C",U19<>"NC",U19<>"SF",U19<>""),AND(W19<>"NA",W19<>"C",W19<>"NC",W19<>"SF",W19<>""),AND(Y19<>"NA",Y19<>"C",Y19<>"NC",Y19<>"SF",Y19<>""),AND(AA19<>"NA",AA19<>"C",AA19<>"NC",AA19<>"SF",AA19<>""),AND(AC19<>"NA",AC19<>"C",AC19<>"NC",AC19<>"SF",AC19<>"")),"FALSO",IF(AND(O19="NA",Q19="NA",S19="NA",U19="NA",W19="NA",Y19="NA",AA19="NA",AC19="NA"),"NA",IF(OR(O19="NC",Q19="NC",S19="NC",U19="NC",W19="NC",Y19="NC",AA19="NC",AC19="NC",O19="SF",Q19="SF",S19="SF",U19="SF",W19="SF",Y19="SF",AA19="SF",AC19="SF"),"NC",IF(OR(O19="C",Q19="C",S19="C",U19="C",W19="C",Y19="C",AA19="C",AC19="C"),"C",""))))) -> NC | AG19: =IF(AND(AE19="C",AF19="C"),"UTILIZOU O PDA CORRETAMENTE",IF(AND(AE19="C",AF19="NC"),"UTILIZOU O PDA CORRETAMENTE. NÃO HÁ FOTOS DE TODAS AS ETAPAS",IF(AND(AE19="NC",AF19="NC"),"NÃO UTILIZOU O PDA",IF(AND(AE19="NA",AF19="NA"),"NÃO AVALIADO POR FALHA DE SINCRONISMO")))) -> UTILIZOU O PDA CORRETAMENTE. NÃO HÁ FOTOS DE TODAS AS ETAPAS | AI19: FREGUESIA DO Ó | AJ19: =E19 -> SÃO PAULO | AK19: ÁGUA
A20: ONMF - DIV MANUT SERV OPE FREGUESIA | B20: 2618388931 | C20: VAZAMENTO DE ÁGUA NO PASSEIO | D20: VAZAMENTO DE ÁGUA | E20: SÃO PAULO | F20: RUA NICOLA NICODEMO | G20: 290 | I20: SITIO DO MANDAQUI | J20: SUPRIMIDO RAMAL DE AGUA ABANDONADO | K20: sem Reposição passeio terra imóvel abandonado | L20: 46086.433 | M20: 46086.609 | N20: RAIMUNDO DA EXALTACAO | O20: C | Q20: C | S20: SF | U20: C | W20: C | Y20: NA | AA20: C | AC20: C | AE20: C | AF20: =IF(AND(O20="",Q20="",S20="",U20="",W20="",Y20="",AA20="",AC20=""),"",IF(OR(AND(O20<>"NA",O20<>"C",O20<>"NC",O20<>"SF",O20<>""),AND(Q20<>"NA",Q20<>"C",Q20<>"NC",Q20<>"SF",Q20<>""),AND(S20<>"NA",S20<>"C",S20<>"NC",S20<>"SF",S20<>""),AND(U20<>"NA",U20<>"C",U20<>"NC",U20<>"SF",U20<>""),AND(W20<>"NA",W20<>"C",W20<>"NC",W20<>"SF",W20<>""),AND(Y20<>"NA",Y20<>"C",Y20<>"NC",Y20<>"SF",Y20<>""),AND(AA20<>"NA",AA20<>"C",AA20<>"NC",AA20<>"SF",AA20<>""),AND(AC20<>"NA",AC20<>"C",AC20<>"NC",AC20<>"SF",AC20<>"")),"FALSO",IF(AND(O20="NA",Q20="NA",S20="NA",U20="NA",W20="NA",Y20="NA",AA20="NA",AC20="NA"),"NA",IF(OR(O20="NC",Q20="NC",S20="NC",U20="NC",W20="NC",Y20="NC",AA20="NC",AC20="NC",O20="SF",Q20="SF",S20="SF",U20="SF",W20="SF",Y20="SF",AA20="SF",AC20="SF"),"NC",IF(OR(O20="C",Q20="C",S20="C",U20="C",W20="C",Y20="C",AA20="C",AC20="C"),"C",""))))) -> NC | AG20: =IF(AND(AE20="C",AF20="C"),"UTILIZOU O PDA CORRETAMENTE",IF(AND(AE20="C",AF20="NC"),"UTILIZOU O PDA CORRETAMENTE. NÃO HÁ FOTOS DE TODAS AS ETAPAS",IF(AND(AE20="NC",AF20="NC"),"NÃO UTILIZOU O PDA",IF(AND(AE20="NA",AF20="NA"),"NÃO AVALIADO POR FALHA DE SINCRONISMO")))) -> UTILIZOU O PDA CORRETAMENTE. NÃO HÁ FOTOS DE TODAS AS ETAPAS | AI20: FREGUESIA DO Ó | AJ20: =E20 -> SÃO PAULO | AK20: ÁGUA
A21: ONMF - DIV MANUT SERV OPE FREGUESIA | B21: 2618098864 | C21: VAZAMENTO DE ÁGUA NÃO VISÍVEL RAMAL | D21: VAZAMENTO DE ÁGUA | E21: SÃO PAULO | F21: RUA VICENTE IORIO | G21: 292 | I21: VL IORIO | J21: SONDAGEM DE REDE DE AGUA NÃO VISIVEL | L21: 46086.381 | M21: 46086.425 | N21: GENILSON MARTINS FERNANDES | O21: C | Q21: C | S21: C | U21: C | W21: C | Y21: NA | AA21: C | AC21: C | AE21: C | AF21: =IF(AND(O21="",Q21="",S21="",U21="",W21="",Y21="",AA21="",AC21=""),"",IF(OR(AND(O21<>"NA",O21<>"C",O21<>"NC",O21<>"SF",O21<>""),AND(Q21<>"NA",Q21<>"C",Q21<>"NC",Q21<>"SF",Q21<>""),AND(S21<>"NA",S21<>"C",S21<>"NC",S21<>"SF",S21<>""),AND(U21<>"NA",U21<>"C",U21<>"NC",U21<>"SF",U21<>""),AND(W21<>"NA",W21<>"C",W21<>"NC",W21<>"SF",W21<>""),AND(Y21<>"NA",Y21<>"C",Y21<>"NC",Y21<>"SF",Y21<>""),AND(AA21<>"NA",AA21<>"C",AA21<>"NC",AA21<>"SF",AA21<>""),AND(AC21<>"NA",AC21<>"C",AC21<>"NC",AC21<>"SF",AC21<>"")),"FALSO",IF(AND(O21="NA",Q21="NA",S21="NA",U21="NA",W21="NA",Y21="NA",AA21="NA",AC21="NA"),"NA",IF(OR(O21="NC",Q21="NC",S21="NC",U21="NC",W21="NC",Y21="NC",AA21="NC",AC21="NC",O21="SF",Q21="SF",S21="SF",U21="SF",W21="SF",Y21="SF",AA21="SF",AC21="SF"),"NC",IF(OR(O21="C",Q21="C",S21="C",U21="C",W21="C",Y21="C",AA21="C",AC21="C"),"C",""))))) -> C | AG21: =IF(AND(AE21="C",AF21="C"),"UTILIZOU O PDA CORRETAMENTE",IF(AND(AE21="C",AF21="NC"),"UTILIZOU O PDA CORRETAMENTE. NÃO HÁ FOTOS DE TODAS AS ETAPAS",IF(AND(AE21="NC",AF21="NC"),"NÃO UTILIZOU O PDA",IF(AND(AE21="NA",AF21="NA"),"NÃO AVALIADO POR FALHA DE SINCRONISMO")))) -> UTILIZOU O PDA CORRETAMENTE | AH21: C | AI21: FREGUESIA DO Ó | AJ21: =E21 -> SÃO PAULO | AK21: ÁGUA
A22: ONMF - DIV MANUT SERV OPE FREGUESIA | B22: 2618118501 | C22: VAZAMENTO DE ÁGUA NÃO VISÍVEL REDE | D22: VAZAMENTO DE ÁGUA | E22: SÃO PAULO | F22: RUA NOSSA SENHORA DA NATIVIDADE | G22: 89 | I22: PIQUERI | J22: SONDAGEM DE REDE DE AGUA NÃO VISIVEL | L22: 46086.602 | M22: 46086.628 | N22: GENILSON MARTINS FERNANDES | O22: C | Q22: C | S22: C | U22: C | W22: C | Y22: NA | AA22: C | AC22: C | AE22: C | AF22: =IF(AND(O22="",Q22="",S22="",U22="",W22="",Y22="",AA22="",AC22=""),"",IF(OR(AND(O22<>"NA",O22<>"C",O22<>"NC",O22<>"SF",O22<>""),AND(Q22<>"NA",Q22<>"C",Q22<>"NC",Q22<>"SF",Q22<>""),AND(S22<>"NA",S22<>"C",S22<>"NC",S22<>"SF",S22<>""),AND(U22<>"NA",U22<>"C",U22<>"NC",U22<>"SF",U22<>""),AND(W22<>"NA",W22<>"C",W22<>"NC",W22<>"SF",W22<>""),AND(Y22<>"NA",Y22<>"C",Y22<>"NC",Y22<>"SF",Y22<>""),AND(AA22<>"NA",AA22<>"C",AA22<>"NC",AA22<>"SF",AA22<>""),AND(AC22<>"NA",AC22<>"C",AC22<>"NC",AC22<>"SF",AC22<>"")),"FALSO",IF(AND(O22="NA",Q22="NA",S22="NA",U22="NA",W22="NA",Y22="NA",AA22="NA",AC22="NA"),"NA",IF(OR(O22="NC",Q22="NC",S22="NC",U22="NC",W22="NC",Y22="NC",AA22="NC",AC22="NC",O22="SF",Q22="SF",S22="SF",U22="SF",W22="SF",Y22="SF",AA22="SF",AC22="SF"),"NC",IF(OR(O22="C",Q22="C",S22="C",U22="C",W22="C",Y22="C",AA22="C",AC22="C"),"C",""))))) -> C | AG22: =IF(AND(AE22="C",AF22="C"),"UTILIZOU O PDA CORRETAMENTE",IF(AND(AE22="C",AF22="NC"),"UTILIZOU O PDA CORRETAMENTE. NÃO HÁ FOTOS DE TODAS AS ETAPAS",IF(AND(AE22="NC",AF22="NC"),"NÃO UTILIZOU O PDA",IF(AND(AE22="NA",AF22="NA"),"NÃO AVALIADO POR FALHA DE SINCRONISMO")))) -> UTILIZOU O PDA CORRETAMENTE | AH22: C | AI22: FREGUESIA DO Ó | AJ22: =E22 -> SÃO PAULO | AK22: ÁGUA
A23: ONMF - DIV MANUT SERV OPE FREGUESIA | B23: 2618416665 | C23: TROCAR RAMAL DE ÁGUA - VAZ NÃO VISIVEL | D23: VAZAMENTO DE ÁGUA | E23: SÃO PAULO | F23: RUA JOSE PEDRO D ORO | G23: 277 | I23: V SOUZA | J23: TROCA DE RAMAL DE AGUA NÃO VISIVEL | K23: VALA NÃO FOI ATERRADA, POIS O IMOVEL ESTA EM OBRA. | L23: 46086.419 | M23: 46086.42 | N23: RAIMUNDO DA EXALTACAO | O23: NA | Q23: NA | S23: NA | U23: NA | W23: NA | Y23: NA | AA23: NA | AC23: NA | AE23: NA | AF23: =IF(AND(O23="",Q23="",S23="",U23="",W23="",Y23="",AA23="",AC23=""),"",IF(OR(AND(O23<>"NA",O23<>"C",O23<>"NC",O23<>"SF",O23<>""),AND(Q23<>"NA",Q23<>"C",Q23<>"NC",Q23<>"SF",Q23<>""),AND(S23<>"NA",S23<>"C",S23<>"NC",S23<>"SF",S23<>""),AND(U23<>"NA",U23<>"C",U23<>"NC",U23<>"SF",U23<>""),AND(W23<>"NA",W23<>"C",W23<>"NC",W23<>"SF",W23<>""),AND(Y23<>"NA",Y23<>"C",Y23<>"NC",Y23<>"SF",Y23<>""),AND(AA23<>"NA",AA23<>"C",AA23<>"NC",AA23<>"SF",AA23<>""),AND(AC23<>"NA",AC23<>"C",AC23<>"NC",AC23<>"SF",AC23<>"")),"FALSO",IF(AND(O23="NA",Q23="NA",S23="NA",U23="NA",W23="NA",Y23="NA",AA23="NA",AC23="NA"),"NA",IF(OR(O23="NC",Q23="NC",S23="NC",U23="NC",W23="NC",Y23="NC",AA23="NC",AC23="NC",O23="SF",Q23="SF",S23="SF",U23="SF",W23="SF",Y23="SF",AA23="SF",AC23="SF"),"NC",IF(OR(O23="C",Q23="C",S23="C",U23="C",W23="C",Y23="C",AA23="C",AC23="C"),"C",""))))) -> NA | AG23: =IF(AND(AE23="C",AF23="C"),"UTILIZOU O PDA CORRETAMENTE",IF(AND(AE23="C",AF23="NC"),"UTILIZOU O PDA CORRETAMENTE. NÃO HÁ FOTOS DE TODAS AS ETAPAS",IF(AND(AE23="NC",AF23="NC"),"NÃO UTILIZOU O PDA",IF(AND(AE23="NA",AF23="NA"),"NÃO AVALIADO POR FALHA DE SINCRONISMO")))) -> NÃO AVALIADO POR FALHA DE SINCRONISMO | AH23: C | AI23: FREGUESIA DO Ó | AJ23: =E23 -> SÃO PAULO | AK23: ÁGUA
A24: ONMF - DIV MANUT SERV OPE FREGUESIA | B24: 2618417370 | C24: VAZAMENTO DE ÁGUA NÃO VISÍVEL CAVALETE | D24: VAZAMENTO DE ÁGUA | E24: SÃO PAULO | F24: RUA LUZIM | G24: 149 | I24: IMIRIM | J24: TROCA DE PE DE CAVALETE NÃO VISIVEL | K24: fotos na os 2618314686 | L24: 46086.522 | M24: 46086.524 | N24: ADECARLOS DE SOUSA SANTOS | O24: C | Q24: C | S24: C | U24: C | W24: C | Y24: NA | AA24: C | AC24: C | AE24: C | AF24: =IF(AND(O24="",Q24="",S24="",U24="",W24="",Y24="",AA24="",AC24=""),"",IF(OR(AND(O24<>"NA",O24<>"C",O24<>"NC",O24<>"SF",O24<>""),AND(Q24<>"NA",Q24<>"C",Q24<>"NC",Q24<>"SF",Q24<>""),AND(S24<>"NA",S24<>"C",S24<>"NC",S24<>"SF",S24<>""),AND(U24<>"NA",U24<>"C",U24<>"NC",U24<>"SF",U24<>""),AND(W24<>"NA",W24<>"C",W24<>"NC",W24<>"SF",W24<>""),AND(Y24<>"NA",Y24<>"C",Y24<>"NC",Y24<>"SF",Y24<>""),AND(AA24<>"NA",AA24<>"C",AA24<>"NC",AA24<>"SF",AA24<>""),AND(AC24<>"NA",AC24<>"C",AC24<>"NC",AC24<>"SF",AC24<>"")),"FALSO",IF(AND(O24="NA",Q24="NA",S24="NA",U24="NA",W24="NA",Y24="NA",AA24="NA",AC24="NA"),"NA",IF(OR(O24="NC",Q24="NC",S24="NC",U24="NC",W24="NC",Y24="NC",AA24="NC",AC24="NC",O24="SF",Q24="SF",S24="SF",U24="SF",W24="SF",Y24="SF",AA24="SF",AC24="SF"),"NC",IF(OR(O24="C",Q24="C",S24="C",U24="C",W24="C",Y24="C",AA24="C",AC24="C"),"C",""))))) -> C | AG24: =IF(AND(AE24="C",AF24="C"),"UTILIZOU O PDA CORRETAMENTE",IF(AND(AE24="C",AF24="NC"),"UTILIZOU O PDA CORRETAMENTE. NÃO HÁ FOTOS DE TODAS AS ETAPAS",IF(AND(AE24="NC",AF24="NC"),"NÃO UTILIZOU O PDA",IF(AND(AE24="NA",AF24="NA"),"NÃO AVALIADO POR FALHA DE SINCRONISMO")))) -> UTILIZOU O PDA CORRETAMENTE | AH24: C | AI24: FREGUESIA DO Ó | AJ24: =E24 -> SÃO PAULO | AK24: ÁGUA
A25: ONMF - DIV MANUT SERV OPE FREGUESIA | B25: 2618314686 | C25: VAZAMENTO DE ÁGUA NÃO VISÍVEL CAVALETE | D25: VAZAMENTO DE ÁGUA | E25: SÃO PAULO | F25: RUA LUZIM | G25: 149 | I25: IMIRIM | J25: TROCA DE PE DE CAVALETE NÃO VISIVEL | L25: 46086.478 | M25: 46086.48 | N25: ADECARLOS DE SOUSA SANTOS | O25: C | Q25: C | S25: C | U25: C | W25: C | Y25: NA | AA25: C | AC25: C | AE25: C | AF25: =IF(AND(O25="",Q25="",S25="",U25="",W25="",Y25="",AA25="",AC25=""),"",IF(OR(AND(O25<>"NA",O25<>"C",O25<>"NC",O25<>"SF",O25<>""),AND(Q25<>"NA",Q25<>"C",Q25<>"NC",Q25<>"SF",Q25<>""),AND(S25<>"NA",S25<>"C",S25<>"NC",S25<>"SF",S25<>""),AND(U25<>"NA",U25<>"C",U25<>"NC",U25<>"SF",U25<>""),AND(W25<>"NA",W25<>"C",W25<>"NC",W25<>"SF",W25<>""),AND(Y25<>"NA",Y25<>"C",Y25<>"NC",Y25<>"SF",Y25<>""),AND(AA25<>"NA",AA25<>"C",AA25<>"NC",AA25<>"SF",AA25<>""),AND(AC25<>"NA",AC25<>"C",AC25<>"NC",AC25<>"SF",AC25<>"")),"FALSO",IF(AND(O25="NA",Q25="NA",S25="NA",U25="NA",W25="NA",Y25="NA",AA25="NA",AC25="NA"),"NA",IF(OR(O25="NC",Q25="NC",S25="NC",U25="NC",W25="NC",Y25="NC",AA25="NC",AC25="NC",O25="SF",Q25="SF",S25="SF",U25="SF",W25="SF",Y25="SF",AA25="SF",AC25="SF"),"NC",IF(OR(O25="C",Q25="C",S25="C",U25="C",W25="C",Y25="C",AA25="C",AC25="C"),"C",""))))) -> C | AG25: =IF(AND(AE25="C",AF25="C"),"UTILIZOU O PDA CORRETAMENTE",IF(AND(AE25="C",AF25="NC"),"UTILIZOU O PDA CORRETAMENTE. NÃO HÁ FOTOS DE TODAS AS ETAPAS",IF(AND(AE25="NC",AF25="NC"),"NÃO UTILIZOU O PDA",IF(AND(AE25="NA",AF25="NA"),"NÃO AVALIADO POR FALHA DE SINCRONISMO")))) -> UTILIZOU O PDA CORRETAMENTE | AH25: C | AI25: FREGUESIA DO Ó | AJ25: =E25 -> SÃO PAULO | AK25: ÁGUA
A26: ONMF - DIV MANUT SERV OPE FREGUESIA | B26: 2618417646 | C26: SONDAR RAMAL DE ÁGUA | D26: OUTROS SERVIÇOS DE ÁGUA | E26: SÃO PAULO | F26: AVENIDA NOSSA SENHORA DO O | G26: 137 | I26: BAIRRO DO LIMAO | J26: SONDAGEM DE RAMAL DE AGUA | K26: fotos 2618380502 | L26: 46086.51 | M26: 46086.511 | N26: ROMERO FRANCISCO DOS SANTOS | O26: C | Q26: C | S26: SF | U26: SF | W26: SF | Y26: NA | AA26: SF | AC26: SF | AE26: NC | AF26: =IF(AND(O26="",Q26="",S26="",U26="",W26="",Y26="",AA26="",AC26=""),"",IF(OR(AND(O26<>"NA",O26<>"C",O26<>"NC",O26<>"SF",O26<>""),AND(Q26<>"NA",Q26<>"C",Q26<>"NC",Q26<>"SF",Q26<>""),AND(S26<>"NA",S26<>"C",S26<>"NC",S26<>"SF",S26<>""),AND(U26<>"NA",U26<>"C",U26<>"NC",U26<>"SF",U26<>""),AND(W26<>"NA",W26<>"C",W26<>"NC",W26<>"SF",W26<>""),AND(Y26<>"NA",Y26<>"C",Y26<>"NC",Y26<>"SF",Y26<>""),AND(AA26<>"NA",AA26<>"C",AA26<>"NC",AA26<>"SF",AA26<>""),AND(AC26<>"NA",AC26<>"C",AC26<>"NC",AC26<>"SF",AC26<>"")),"FALSO",IF(AND(O26="NA",Q26="NA",S26="NA",U26="NA",W26="NA",Y26="NA",AA26="NA",AC26="NA"),"NA",IF(OR(O26="NC",Q26="NC",S26="NC",U26="NC",W26="NC",Y26="NC",AA26="NC",AC26="NC",O26="SF",Q26="SF",S26="SF",U26="SF",W26="SF",Y26="SF",AA26="SF",AC26="SF"),"NC",IF(OR(O26="C",Q26="C",S26="C",U26="C",W26="C",Y26="C",AA26="C",AC26="C"),"C",""))))) -> NC | AG26: =IF(AND(AE26="C",AF26="C"),"UTILIZOU O PDA CORRETAMENTE",IF(AND(AE26="C",AF26="NC"),"UTILIZOU O PDA CORRETAMENTE. NÃO HÁ FOTOS DE TODAS AS ETAPAS",IF(AND(AE26="NC",AF26="NC"),"NÃO UTILIZOU O PDA",IF(AND(AE26="NA",AF26="NA"),"NÃO AVALIADO POR FALHA DE SINCRONISMO")))) -> NÃO UTILIZOU O PDA | AI26: FREGUESIA DO Ó | AJ26: =E26 -> SÃO PAULO | AK26: ÁGUA
A27: ONMF - DIV MANUT SERV OPE FREGUESIA | B27: 2618314530 | C27: VAZAMENTO DE ÁGUA NÃO VISÍVEL CAVALETE | D27: VAZAMENTO DE ÁGUA | E27: SÃO PAULO | F27: RUA MORATO DE OLIVEIRA | G27: 470 | I27: JD CACHOEIRA | J27: TROCA DE PE DE CAVALETE NÃO VISIVEL | L27: 46086.257 | M27: 46086.258 | N27: FLAVIO CARVALHO DOS SANTOS | O27: NA | Q27: NA | S27: NA | U27: NA | W27: NA | Y27: NA | AA27: NA | AC27: NA | AE27: NA | AF27: =IF(AND(O27="",Q27="",S27="",U27="",W27="",Y27="",AA27="",AC27=""),"",IF(OR(AND(O27<>"NA",O27<>"C",O27<>"NC",O27<>"SF",O27<>""),AND(Q27<>"NA",Q27<>"C",Q27<>"NC",Q27<>"SF",Q27<>""),AND(S27<>"NA",S27<>"C",S27<>"NC",S27<>"SF",S27<>""),AND(U27<>"NA",U27<>"C",U27<>"NC",U27<>"SF",U27<>""),AND(W27<>"NA",W27<>"C",W27<>"NC",W27<>"SF",W27<>""),AND(Y27<>"NA",Y27<>"C",Y27<>"NC",Y27<>"SF",Y27<>""),AND(AA27<>"NA",AA27<>"C",AA27<>"NC",AA27<>"SF",AA27<>""),AND(AC27<>"NA",AC27<>"C",AC27<>"NC",AC27<>"SF",AC27<>"")),"FALSO",IF(AND(O27="NA",Q27="NA",S27="NA",U27="NA",W27="NA",Y27="NA",AA27="NA",AC27="NA"),"NA",IF(OR(O27="NC",Q27="NC",S27="NC",U27="NC",W27="NC",Y27="NC",AA27="NC",AC27="NC",O27="SF",Q27="SF",S27="SF",U27="SF",W27="SF",Y27="SF",AA27="SF",AC27="SF"),"NC",IF(OR(O27="C",Q27="C",S27="C",U27="C",W27="C",Y27="C",AA27="C",AC27="C"),"C",""))))) -> NA | AG27: =IF(AND(AE27="C",AF27="C"),"UTILIZOU O PDA CORRETAMENTE",IF(AND(AE27="C",AF27="NC"),"UTILIZOU O PDA CORRETAMENTE. NÃO HÁ FOTOS DE TODAS AS ETAPAS",IF(AND(AE27="NC",AF27="NC"),"NÃO UTILIZOU O PDA",IF(AND(AE27="NA",AF27="NA"),"NÃO AVALIADO POR FALHA DE SINCRONISMO")))) -> NÃO AVALIADO POR FALHA DE SINCRONISMO | AI27: FREGUESIA DO Ó | AJ27: =E27 -> SÃO PAULO | AK27: ÁGUA
A28: ONMF - DIV MANUT SERV OPE FREGUESIA | B28: 2618314642 | C28: TROCAR RAMAL DE ÁGUA - VAZ NÃO VISIVEL | D28: VAZAMENTO DE ÁGUA | E28: SÃO PAULO | F28: RUA NORDESTE | G28: 126 | I28: CASA VERDE MEDIA | J28: TROCA DE RAMAL DE AGUA NÃO VISIVEL | K28: as fotos tá na o.s 2618314642, mais adicional de eletrofusão | L28: 46086.549 | M28: 46086.551 | N28: GENILSON MARTINS FERNANDES | O28: C | Q28: C | S28: C | U28: C | W28: C | Y28: C | AA28: C | AC28: C | AE28: C | AF28: =IF(AND(O28="",Q28="",S28="",U28="",W28="",Y28="",AA28="",AC28=""),"",IF(OR(AND(O28<>"NA",O28<>"C",O28<>"NC",O28<>"SF",O28<>""),AND(Q28<>"NA",Q28<>"C",Q28<>"NC",Q28<>"SF",Q28<>""),AND(S28<>"NA",S28<>"C",S28<>"NC",S28<>"SF",S28<>""),AND(U28<>"NA",U28<>"C",U28<>"NC",U28<>"SF",U28<>""),AND(W28<>"NA",W28<>"C",W28<>"NC",W28<>"SF",W28<>""),AND(Y28<>"NA",Y28<>"C",Y28<>"NC",Y28<>"SF",Y28<>""),AND(AA28<>"NA",AA28<>"C",AA28<>"NC",AA28<>"SF",AA28<>""),AND(AC28<>"NA",AC28<>"C",AC28<>"NC",AC28<>"SF",AC28<>"")),"FALSO",IF(AND(O28="NA",Q28="NA",S28="NA",U28="NA",W28="NA",Y28="NA",AA28="NA",AC28="NA"),"NA",IF(OR(O28="NC",Q28="NC",S28="NC",U28="NC",W28="NC",Y28="NC",AA28="NC",AC28="NC",O28="SF",Q28="SF",S28="SF",U28="SF",W28="SF",Y28="SF",AA28="SF",AC28="SF"),"NC",IF(OR(O28="C",Q28="C",S28="C",U28="C",W28="C",Y28="C",AA28="C",AC28="C"),"C",""))))) -> C | AG28: =IF(AND(AE28="C",AF28="C"),"UTILIZOU O PDA CORRETAMENTE",IF(AND(AE28="C",AF28="NC"),"UTILIZOU O PDA CORRETAMENTE. NÃO HÁ FOTOS DE TODAS AS ETAPAS",IF(AND(AE28="NC",AF28="NC"),"NÃO UTILIZOU O PDA",IF(AND(AE28="NA",AF28="NA"),"NÃO AVALIADO POR FALHA DE SINCRONISMO")))) -> UTILIZOU O PDA CORRETAMENTE | AH28: C | AI28: FREGUESIA DO Ó | AJ28: =E28 -> SÃO PAULO | AK28: ÁGUA
A29: ONMF - DIV MANUT SERV OPE FREGUESIA | B29: 2618314409 | C29: VAZAMENTO DE ÁGUA NÃO VISÍVEL CAVALETE | D29: VAZAMENTO DE ÁGUA | E29: SÃO PAULO | F29: RUA PROFESSOR RIVADAVIA DE CAMPOS | G29: 409 | H29: FDS C/1 | I29: VL MANOEL LOPES | J29: TROCA DE PE DE CAVALETE NÃO VISIVEL | L29: 46086.6 | M29: 46086.601 | N29: ADECARLOS DE SOUSA SANTOS | O29: NC | P29: FOTO DA FOTO | Q29: NC | R29: FOTO DA FOTO | S29: NC | T29: FOTO DA FOTO | U29: NC | V29: FOTO DA FOTO | W29: NC | X29: FOTO DA FOTO | Y29: NC | Z29: FOTO DA FOTO | AA29: NC | AB29: FOTO DA FOTO | AC29: NC | AD29: FOTO DA FOTO | AE29: NC | AF29: =IF(AND(O29="",Q29="",S29="",U29="",W29="",Y29="",AA29="",AC29=""),"",IF(OR(AND(O29<>"NA",O29<>"C",O29<>"NC",O29<>"SF",O29<>""),AND(Q29<>"NA",Q29<>"C",Q29<>"NC",Q29<>"SF",Q29<>""),AND(S29<>"NA",S29<>"C",S29<>"NC",S29<>"SF",S29<>""),AND(U29<>"NA",U29<>"C",U29<>"NC",U29<>"SF",U29<>""),AND(W29<>"NA",W29<>"C",W29<>"NC",W29<>"SF",W29<>""),AND(Y29<>"NA",Y29<>"C",Y29<>"NC",Y29<>"SF",Y29<>""),AND(AA29<>"NA",AA29<>"C",AA29<>"NC",AA29<>"SF",AA29<>""),AND(AC29<>"NA",AC29<>"C",AC29<>"NC",AC29<>"SF",AC29<>"")),"FALSO",IF(AND(O29="NA",Q29="NA",S29="NA",U29="NA",W29="NA",Y29="NA",AA29="NA",AC29="NA"),"NA",IF(OR(O29="NC",Q29="NC",S29="NC",U29="NC",W29="NC",Y29="NC",AA29="NC",AC29="NC",O29="SF",Q29="SF",S29="SF",U29="SF",W29="SF",Y29="SF",AA29="SF",AC29="SF"),"NC",IF(OR(O29="C",Q29="C",S29="C",U29="C",W29="C",Y29="C",AA29="C",AC29="C"),"C",""))))) -> NC | AG29: =IF(AND(AE29="C",AF29="C"),"UTILIZOU O PDA CORRETAMENTE",IF(AND(AE29="C",AF29="NC"),"UTILIZOU O PDA CORRETAMENTE. NÃO HÁ FOTOS DE TODAS AS ETAPAS",IF(AND(AE29="NC",AF29="NC"),"NÃO UTILIZOU O PDA",IF(AND(AE29="NA",AF29="NA"),"NÃO AVALIADO POR FALHA DE SINCRONISMO")))) -> NÃO UTILIZOU O PDA | AI29: FREGUESIA DO Ó | AJ29: =E29 -> SÃO PAULO | AK29: ÁGUA
A30: ONMF - DIV MANUT SERV OPE FREGUESIA | B30: 2618170210 | C30: TROCAR RAMAL DE ÁGUA PREVENTIVA | D30: RAMAL DE ÁGUA | E30: SÃO PAULO | F30: RUA COMENDADOR ARMANDO PEREIRA | G30: 426 | I30: JD STA MARCELINA | J30: TROCA DE RAMAL DE AGUA PREVENTIVA | K30: Passeio estendido | L30: 46117.356 | M30: 46117.476 | N30: IZAQUEU FERREIRA DE SOUSA | O30: C | Q30: C | S30: C | U30: C | W30: C | Y30: C | AA30: C | AC30: C | AE30: C | AF30: =IF(AND(O30="",Q30="",S30="",U30="",W30="",Y30="",AA30="",AC30=""),"",IF(OR(AND(O30<>"NA",O30<>"C",O30<>"NC",O30<>"SF",O30<>""),AND(Q30<>"NA",Q30<>"C",Q30<>"NC",Q30<>"SF",Q30<>""),AND(S30<>"NA",S30<>"C",S30<>"NC",S30<>"SF",S30<>""),AND(U30<>"NA",U30<>"C",U30<>"NC",U30<>"SF",U30<>""),AND(W30<>"NA",W30<>"C",W30<>"NC",W30<>"SF",W30<>""),AND(Y30<>"NA",Y30<>"C",Y30<>"NC",Y30<>"SF",Y30<>""),AND(AA30<>"NA",AA30<>"C",AA30<>"NC",AA30<>"SF",AA30<>""),AND(AC30<>"NA",AC30<>"C",AC30<>"NC",AC30<>"SF",AC30<>"")),"FALSO",IF(AND(O30="NA",Q30="NA",S30="NA",U30="NA",W30="NA",Y30="NA",AA30="NA",AC30="NA"),"NA",IF(OR(O30="NC",Q30="NC",S30="NC",U30="NC",W30="NC",Y30="NC",AA30="NC",AC30="NC",O30="SF",Q30="SF",S30="SF",U30="SF",W30="SF",Y30="SF",AA30="SF",AC30="SF"),"NC",IF(OR(O30="C",Q30="C",S30="C",U30="C",W30="C",Y30="C",AA30="C",AC30="C"),"C",""))))) -> C | AG30: =IF(AND(AE30="C",AF30="C"),"UTILIZOU O PDA CORRETAMENTE",IF(AND(AE30="C",AF30="NC"),"UTILIZOU O PDA CORRETAMENTE. NÃO HÁ FOTOS DE TODAS AS ETAPAS",IF(AND(AE30="NC",AF30="NC"),"NÃO UTILIZOU O PDA",IF(AND(AE30="NA",AF30="NA"),"NÃO AVALIADO POR FALHA DE SINCRONISMO")))) -> UTILIZOU O PDA CORRETAMENTE | AH30: C | AI30: FREGUESIA DO Ó | AJ30: =E30 -> SÃO PAULO | AK30: ÁGUA
A31: ONMF - DIV MANUT SERV OPE FREGUESIA | B31: 2617956061 | C31: TRANSFORMAÇÃO LIG EXIST SEM APROV RAMAL | D31: LIGAÇÃO DE ÁGUA | E31: SÃO PAULO | F31: RUA JOSE CARLOS RODRIGUES | G31: 261 | I31: V CONTINENTAL | J31: TRANSFORMAÇÃO LIG EXIST SEM APROV RAMAL | K31: foi feito um ligação sem reposição de passeio AD é obra | L31: 46117.363 | M31: 46117.463 | N31: GILTON APARECIDO GUIMARAES BARBOSA | O31: C | Q31: C | S31: C | U31: C | W31: C | Y31: C | AA31: C | AC31: C | AE31: C | AF31: =IF(AND(O31="",Q31="",S31="",U31="",W31="",Y31="",AA31="",AC31=""),"",IF(OR(AND(O31<>"NA",O31<>"C",O31<>"NC",O31<>"SF",O31<>""),AND(Q31<>"NA",Q31<>"C",Q31<>"NC",Q31<>"SF",Q31<>""),AND(S31<>"NA",S31<>"C",S31<>"NC",S31<>"SF",S31<>""),AND(U31<>"NA",U31<>"C",U31<>"NC",U31<>"SF",U31<>""),AND(W31<>"NA",W31<>"C",W31<>"NC",W31<>"SF",W31<>""),AND(Y31<>"NA",Y31<>"C",Y31<>"NC",Y31<>"SF",Y31<>""),AND(AA31<>"NA",AA31<>"C",AA31<>"NC",AA31<>"SF",AA31<>""),AND(AC31<>"NA",AC31<>"C",AC31<>"NC",AC31<>"SF",AC31<>"")),"FALSO",IF(AND(O31="NA",Q31="NA",S31="NA",U31="NA",W31="NA",Y31="NA",AA31="NA",AC31="NA"),"NA",IF(OR(O31="NC",Q31="NC",S31="NC",U31="NC",W31="NC",Y31="NC",AA31="NC",AC31="NC",O31="SF",Q31="SF",S31="SF",U31="SF",W31="SF",Y31="SF",AA31="SF",AC31="SF"),"NC",IF(OR(O31="C",Q31="C",S31="C",U31="C",W31="C",Y31="C",AA31="C",AC31="C"),"C",""))))) -> C | AG31: =IF(AND(AE31="C",AF31="C"),"UTILIZOU O PDA CORRETAMENTE",IF(AND(AE31="C",AF31="NC"),"UTILIZOU O PDA CORRETAMENTE. NÃO HÁ FOTOS DE TODAS AS ETAPAS",IF(AND(AE31="NC",AF31="NC"),"NÃO UTILIZOU O PDA",IF(AND(AE31="NA",AF31="NA"),"NÃO AVALIADO POR FALHA DE SINCRONISMO")))) -> UTILIZOU O PDA CORRETAMENTE | AH31: C | AI31: FREGUESIA DO Ó | AJ31: =E31 -> SÃO PAULO | AK31: ÁGUA
A32: ONMF - DIV MANUT SERV OPE FREGUESIA | B32: 2618134132 | C32: LIGAÇÃO DE ÁGUA S/V | D32: LIGAÇÃO DE ÁGUA | E32: SÃO PAULO | F32: RUA RIO VERDE | G32: 1026 | I32: MOINHO VELHO | J32: LIGAÇÃO DE ÁGUA S/V | K32: sem reposição de passeio AD é obra | L32: 46117.48 | M32: 46117.541 | N32: GILTON APARECIDO GUIMARAES BARBOSA | O32: C | Q32: C | S32: C | U32: C | W32: C | Y32: C | AA32: C | AC32: C | AE32: C | AF32: =IF(AND(O32="",Q32="",S32="",U32="",W32="",Y32="",AA32="",AC32=""),"",IF(OR(AND(O32<>"NA",O32<>"C",O32<>"NC",O32<>"SF",O32<>""),AND(Q32<>"NA",Q32<>"C",Q32<>"NC",Q32<>"SF",Q32<>""),AND(S32<>"NA",S32<>"C",S32<>"NC",S32<>"SF",S32<>""),AND(U32<>"NA",U32<>"C",U32<>"NC",U32<>"SF",U32<>""),AND(W32<>"NA",W32<>"C",W32<>"NC",W32<>"SF",W32<>""),AND(Y32<>"NA",Y32<>"C",Y32<>"NC",Y32<>"SF",Y32<>""),AND(AA32<>"NA",AA32<>"C",AA32<>"NC",AA32<>"SF",AA32<>""),AND(AC32<>"NA",AC32<>"C",AC32<>"NC",AC32<>"SF",AC32<>"")),"FALSO",IF(AND(O32="NA",Q32="NA",S32="NA",U32="NA",W32="NA",Y32="NA",AA32="NA",AC32="NA"),"NA",IF(OR(O32="NC",Q32="NC",S32="NC",U32="NC",W32="NC",Y32="NC",AA32="NC",AC32="NC",O32="SF",Q32="SF",S32="SF",U32="SF",W32="SF",Y32="SF",AA32="SF",AC32="SF"),"NC",IF(OR(O32="C",Q32="C",S32="C",U32="C",W32="C",Y32="C",AA32="C",AC32="C"),"C",""))))) -> C | AG32: =IF(AND(AE32="C",AF32="C"),"UTILIZOU O PDA CORRETAMENTE",IF(AND(AE32="C",AF32="NC"),"UTILIZOU O PDA CORRETAMENTE. NÃO HÁ FOTOS DE TODAS AS ETAPAS",IF(AND(AE32="NC",AF32="NC"),"NÃO UTILIZOU O PDA",IF(AND(AE32="NA",AF32="NA"),"NÃO AVALIADO POR FALHA DE SINCRONISMO")))) -> UTILIZOU O PDA CORRETAMENTE | AH32: C | AI32: FREGUESIA DO Ó | AJ32: =E32 -> SÃO PAULO | AK32: ÁGUA
