Workbook

Sheet GRÁFICOS - PIRITUBA
A2: POLO PIRITUBA
A4: ACOMPANHAMENTO EM CAMPO
A5: ='DADOS - PIRITUBA'!B4 -> Período: 01/03/2026 à 31/03/2026
A7: ÍNDICE TECNOLÓGICO
B20: O Índice Tecnológico pode ser obtido através da fórmula:
B22: IT = {[97 + 3 (Kc/100)] x Ks/100}
B24: Onde:
B25: IT = Índice Tecnológico
B26: Kc = Fator do Canteiro
B27: Ks = Média de Notas das LVs
B29: Estando acima de 80% o IT é considerado satisfatório.
A31: Nota: O Índice Tecnológico não foi calculado, pois a avaliação de Canteiro ainda não foi realizada.
A34: ACOMPANHAMENTO DE LISTAS DE VERIFICAÇÃO - LVS
B36: Índice de Conformidade (%) | E36: Quantidade de LVs
B51: TIPO DE SERVIÇO | C51: QUANTIDADE DE LVS ACIMA DE 80%
B52: Água | C52: 0
B53: Esgoto | C53: 0
B54: Reposição | C54: 0
A57: CONFORMIDADE POR CRITÉRIO DE AVALIAÇÃO
A84: OLHAR DIGITAL
A85: ='DADOS - PIRITUBA'!B4 -> Período: 01/03/2026 à 31/03/2026
B86: ÍNDICE DE QUALIDADE SABESP - IQS (%) - MARÇO
B101: ÍNDICE DE QUALIDADE SABESP - IQS (%)
B102: Tipo de Serviço | C102: Fotos Avaliadas | D102: Fotos NC | E102: Fotos Conforme | F102: Não Conforme (%) | G102: Conforme (%)
B103: Água | C103: =D103+E103 -> 751 | D103: =COUNTIF(ÁGUA!AF:AF,"Nc") -> 133 | E103: =COUNTIF(ÁGUA!AF:AF,"c") -> 618 | F103: =IFERROR(D103/C103,"-") -> 0.1770972 | G103: =IFERROR(100%-F103,"-") -> 0.8229028
B104: Esgoto | C104: =D104+E104 -> 160 | D104: =COUNTIF(ESGOTO!AF:AF,"NC") -> 149 | E104: =COUNTIF(ESGOTO!AF:AF,"C") -> 11 | F104: =IFERROR(D104/C104,"-") -> 0.93125 | G104: =IFERROR(100%-F104,"-") -> 0.06875
B105: Cavalete | C105: =D105+E105 -> 717 | D105: =COUNTIF(CAVALETE!Z:Z,"nc") -> 505 | E105: =COUNTIF(CAVALETE!Z:Z,"C") -> 212 | F105: =IFERROR(D105/C105,"-") -> 0.70432357 | G105: =IFERROR(100%-F105,"-") -> 0.29567643
B106: Reposição | C106: =D106+E106 -> 81 | D106: =COUNTIF(REPOSIÇÃO!AF:AF,"nC") -> 81 | E106: =COUNTIF(REPOSIÇÃO!AF:AF,"c") -> 0 | F106: =IFERROR(D106/C106,"-") -> 1 | G106: =IFERROR(100%-F106,"-") -> 0
F107: IQS (%): | G107: =IFERROR(AVERAGE(G103,G104,G105,G106), "-") -> 0.29683231

Sheet CAPA
C18: RELATÓRIO PARCIAL
C20: CONTROLE TECNOLÓGICO
C21: ='DADOS - PIRITUBA'!B4 -> Período: 01/03/2026 à 31/03/2026
C35: POLO PIRITUBA
C36: CONTRATADA AUDITADA: PASSARELLI
C37: CONTRATO: 11522787
C41: SÃO PAULO
C42: 2026

Sheet DADOS - PIRITUBA
B2: PIRITUBA
B3: ACOMPANHAMENTO EM CAMPO
B4: Período: 01/03/2026 à 31/03/2026
B6: ÍNDICE TECNOLÓGICO (%)
B7: IT (%)
D9: ÍNDICE DE CONFORMIDADE (%)
B10: Tipo de Serviço | C10: IC (%) | E10: Quantidade de LVs
B11: Água | C11: 1 | E11: 100
B12: Esgoto | C12: 0.5 | E12: 50
B13: Reposição | C13: 0.1 | E13: 1
B15: PIRITUBA | E15: FALTAM | F15: =('GRÁFICOS - ÁGUA'!B8+'GRÁFICOS - ESGOTO'!B8+'GRÁFICOS - CAVALETE'!B8+'GRÁFICOS - REPOSIÇÃO'!B8) -> 27
B16: QUALIDADE | C16: 0
B17: PRAZO | C17: 0
B18: SEGURANÇA | C18: 0
B19: ORGANIZAÇÃO | C19: 0
B22: OLHAR DIGITAL
B24: ÍNDICE DE QUALIDADE SABESP - IQS (%)
B25: Tipo de Serviço | C25: Fotos Avaliadas | D25: Fotos NC | E25: Fotos Conforme | F25: Não Conforme (%) | G25: Conforme (%)
B26: Água | C26: =D26+E26 -> 751 | D26: =COUNTIF(ÁGUA!AF:AF,"Nc") -> 133 | E26: =COUNTIF(ÁGUA!AF:AF,"c") -> 618 | F26: =IFERROR(D26/C26,"-") -> 0.1770972 | G26: =IFERROR(100%-F26,"-") -> 0.8229028
B27: Esgoto | C27: =D27+E27 -> 160 | D27: =COUNTIF(ESGOTO!AF:AF,"NC") -> 149 | E27: =COUNTIF(ESGOTO!AF:AF,"C") -> 11 | F27: =IFERROR(D27/C27,"-") -> 0.93125 | G27: =IFERROR(100%-F27,"-") -> 0.06875
B28: Cavalete | C28: =D28+E28 -> 717 | D28: =COUNTIF(CAVALETE!Z:Z,"nc") -> 505 | E28: =COUNTIF(CAVALETE!Z:Z,"C") -> 212 | F28: =IFERROR(D28/C28,"-") -> 0.70432357 | G28: =IFERROR(100%-F28,"-") -> 0.29567643
B29: Reposição | C29: =D29+E29 -> 81 | D29: =COUNTIF(REPOSIÇÃO!AF:AF,"nC") -> 81 | E29: =COUNTIF(REPOSIÇÃO!AF:AF,"c") -> 0 | F29: =IFERROR(D29/C29,"-") -> 1 | G29: =IFERROR(100%-F29,"-") -> 0
B30: Total | C30: =SUM(C26:C29) -> 1709 | D30: =SUM(D26:D29) -> 868 | E30: =SUM(E26:E29) -> 841 | F30: =IFERROR(AVERAGE(F26,F27,F28,F29),"-") -> 0.70316769 | G30: =IFERROR(AVERAGE(G26,G27,G28,G29),"-") -> 0.29683231
F31: IQS Não Conforme (%): | G31: IQS (%):
B33: TEMPO DE EXECUÇÃO
B34: Tipo de Serviço | C34: Avaliados | D34: Não Conforme | E34: Conforme | F34: Não Conforme (%) | G34: Conforme (%)
B35: Água | C35: =D35+E35 -> 751 | D35: =COUNTIF(ÁGUA!AE:AE,"Nc") -> 20 | E35: =COUNTIF(ÁGUA!AE:AE,"c") -> 731 | F35: =IFERROR(D35/C35,"-") -> 0.026631158 | G35: =IFERROR(E35/C35,"-") -> 0.97336884
B36: Esgoto | C36: =D36+E36 -> 160 | D36: =COUNTIF(ESGOTO!AE:AE,"NC") -> 22 | E36: =COUNTIF(ESGOTO!AE:AE,"C") -> 138 | F36: =IFERROR(D36/C36,"-") -> 0.1375 | G36: =IFERROR(E36/C36,"-") -> 0.8625
B37: Cavalete | C37: =D37+E37 -> 717 | D37: =COUNTIF(CAVALETE!Y:Y,"NC") -> 113 | E37: =COUNTIF(CAVALETE!Y:Y,"C") -> 604 | F37: =IFERROR(D37/C37,"-") -> 0.15760112 | G37: =IFERROR(E37/C37,"-") -> 0.84239888
B38: Reposição | C38: =D38+E38 -> 81 | D38: =COUNTIF(REPOSIÇÃO!AE:AE,"nC") -> 2 | E38: =COUNTIF(REPOSIÇÃO!AE:AE,"c") -> 79 | F38: =IFERROR(D38/C38,"-") -> 0.024691358 | G38: =IFERROR(E38/C38,"-") -> 0.97530864
B40: BAIXA DE MATERIAIS
B41: Tipo de Serviço | C41: Avaliados | D41: Não Conforme | E41: Conforme | F41: Não Conforme (%) | G41: Conforme (%)
B42: Água | C42: =D42+E42 -> 662 | D42: =COUNTIF(ÁGUA!AH:AH,"Nc") -> 0 | E42: =COUNTIF(ÁGUA!AH:AH,"c") -> 662 | F42: =IFERROR(D42/C42,"-") -> 0 | G42: =IFERROR(E42/C42,"-") -> 1
B43: Esgoto | C43: =D43+E43 -> 193 | D43: =COUNTIF(ESGOTO!AH:AH,"NC") -> 0 | E43: =COUNTIF(ESGOTO!AH:AH,"C") -> 193 | F43: =IFERROR(D43/C43,"-") -> 0 | G43: =IFERROR(E43/C43,"-") -> 1
B44: Cavalete | C44: =D44+E44 -> 463 | D44: =COUNTIF(CAVALETE!AB:AB,"NC") -> 0 | E44: =COUNTIF(CAVALETE!AB:AB,"C") -> 463 | F44: =IFERROR(D44/C44,"-") -> 0 | G44: =IFERROR(E44/C44,"-") -> 1
B46: ÁGUA
B48: TEMPO DE EXECUÇÃO
B49: Tipo de Serviço | C49: Avaliados | D49: Não Conforme | E49: Conforme | F49: Não Conforme (%) | G49: Conforme (%)
B50: Água | C50: =D50+E50 -> 751 | D50: =COUNTIF(ÁGUA!AE:AE,"NC") -> 20 | E50: =COUNTIF(ÁGUA!AE:AE,"C") -> 731 | F50: =IFERROR(D50/C50,"-") -> 0.026631158 | G50: =IFERROR(E50/C50,"-") -> 0.97336884
B52: ÍNDICE DE QUALIDADE SABESP - IQS (%)
...

Sheet GRÁFICOS - ÁGUA
A1: AMOSTRA
B3: EXECUTADOS | D3: AVALIADOS
B4: =COUNTIF(ÁGUA!A:A,"ONMP - DIV MANUT SERV OPE PIRITUBA") -> 798 | D4: ='DADOS - PIRITUBA'!C26 -> 751
B5: VERIFICADOS | C5: (%) | D5: SEM EVIDÊNCIAS | E5: (%) | I5: =440/6 -> 73.333333
B6: ='DADOS - PIRITUBA'!C26+'GRÁFICOS - ÁGUA'!D8 -> 798 | C6: =IFERROR(B6/B4,"-") -> 1 | D6: =COUNTIFS(ÁGUA!O:O,"SF",ÁGUA!Q:Q,"SF",ÁGUA!S:S,"SF",ÁGUA!U:U,"SF",ÁGUA!W:W,"SF",ÁGUA!Y:Y,"SF",ÁGUA!AC:AC,"SF",ÁGUA!AA:AA,"SF") -> 5 | E6: =IFERROR(D6/B4,"-") -> 0.0062656642
B7: NÃO VERIFICADOS | C7: (%) | D7: NÃO SINCRONIZADOS | E7: (%)
B8: =B4-B6 -> 0 | C8: =IFERROR(B8/B4,"-") -> 0 | D8: =COUNTIFS(ÁGUA!O:O,"na",ÁGUA!Q:Q,"na",ÁGUA!S:S,"na",ÁGUA!U:U,"na",ÁGUA!W:W,"na",ÁGUA!Y:Y,"na",ÁGUA!AC:AC,"na",ÁGUA!AA:AA,"na") -> 47 | E8: =IFERROR(D8/B4,"-") -> 0.058897243
A11: RESULTADO
A40: AVALIAÇÃO DE MATERIAIS
A69: CONFORMIDADE POR ETAPAS DE SERVIÇO
A103: EQUIPES - CONFORMIDADES

Sheet ÁGUA
A1: Unidade Executante | B1: Número OS | C1: Descrição TSS | D1: Família | E1: Município | F1: Endereço | G1: Número | H1: Complemento | I1: Bairro | J1: Resultado | K1: Nota Execução/Não Execução | L1: Data Início Execução | M1: Data Fim Execução | N1: EQUIPE | O1: FACHADA | P1: Observação Fachada | Q1: SINALIZAÇÃO | R1: Observação Sinalização | S1: ENCERADO | T1: Observação encerado | U1: GEOMETRIA | V1: Observação Geometria | W1: BERÇO DE AREIA | X1: Observação Berço de Areia | Y1: ESTANQUEIDADE | Z1: Observaçao Estanqueidade | AA1: .COMPACTAÇÃO | AB1: Observação Compactação | AC1: FINALIZAÇÃO | AD1: Observação Finalização | AE1: Tempo de execução | AF1: Sequência de Fotos | AG1: Observações | AH1: Baixa de materias | AI1: POLO | AJ1: MUNICÍPIO | AK1: CARACTERÍSTICA DO SERVIÇO
A2: ONMP - DIV MANUT SERV OPE PIRITUBA | B2: 2617928572 | C2: VAZAMENTO DE ÁGUA NÃO VISÍVEL REDE | D2: VAZAMENTO DE ÁGUA | E2: SÃO PAULO | F2: TRAVESSA MURACATI | G2: 102 | I2: V MANGALOT | J2: SUPRIMIDO RAMAL AGUA ABAND NÃO VISIVEL | L2: 46143.292 | M2: 46143.292 | N2: PAULO ADRIANO BORGES DA SILVA | O2: NA | Q2: NA | S2: NA | U2: NA | W2: NA | Y2: NA | AA2: NA | AC2: NA | AE2: NA | AF2: =IF(AND(O2="",Q2="",S2="",U2="",W2="",Y2="",AA2="",AC2=""),"",IF(OR(AND(O2<>"NA",O2<>"C",O2<>"NC",O2<>"SF",O2<>""),AND(Q2<>"NA",Q2<>"C",Q2<>"NC",Q2<>"SF",Q2<>""),AND(S2<>"NA",S2<>"C",S2<>"NC",S2<>"SF",S2<>""),AND(U2<>"NA",U2<>"C",U2<>"NC",U2<>"SF",U2<>""),AND(W2<>"NA",W2<>"C",W2<>"NC",W2<>"SF",W2<>""),AND(Y2<>"NA",Y2<>"C",Y2<>"NC",Y2<>"SF",Y2<>""),AND(AA2<>"NA",AA2<>"C",AA2<>"NC",AA2<>"SF",AA2<>""),AND(AC2<>"NA",AC2<>"C",AC2<>"NC",AC2<>"SF",AC2<>"")),"FALSO",IF(AND(O2="NA",Q2="NA",S2="NA",U2="NA",W2="NA",Y2="NA",AA2="NA",AC2="NA"),"NA",IF(OR(O2="NC",Q2="NC",S2="NC",U2="NC",W2="NC",Y2="NC",AA2="NC",AC2="NC",O2="SF",Q2="SF",S2="SF",U2="SF",W2="SF",Y2="SF",AA2="SF",AC2="SF"),"NC",IF(OR(O2="C",Q2="C",S2="C",U2="C",W2="C",Y2="C",AA2="C",AC2="C"),"C",""))))) -> NA | AG2: =IF(AND(AE2="C",AF2="C"),"UTILIZOU O PDA CORRETAMENTE",IF(AND(AE2="C",AF2="NC"),"UTILIZOU O PDA CORRETAMENTE. NÃO HÁ FOTOS DE TODAS AS ETAPAS",IF(AND(AE2="NC",AF2="NC"),"NÃO UTILIZOU O PDA",IF(AND(AE2="NA",AF2="NA"),"NÃO AVALIADO POR FALHA DE SINCRONISMO")))) -> NÃO AVALIADO POR FALHA DE SINCRONISMO | AI2: PIRITUBA | AJ2: =E2 -> SÃO PAULO | AK2: ÁGUA
A3: ONMP - DIV MANUT SERV OPE PIRITUBA | B3: 2617564075 | C3: TRANSFORMAÇÃO LIG NOVA COM APROV RAMAL | D3: LIGAÇÃO DE ÁGUA | E3: SÃO PAULO | F3: AVENIDA RAIMUNDO PEREIRA DE MAGALHAES | G3: 10095 | H3: C/2 | I3: PIRITUBA | J3: TRANSFORMAÇÃO LIG NOVA COM APROV RAMAL | L3: 46143.422 | M3: 46143.423 | N3: ADRIANO SIMAO LINHARES | O3: C | Q3: NA | S3: NA | U3: NA | W3: NA | Y3: NA | AA3: NA | AC3: C | AE3: C | AF3: =IF(AND(O3="",Q3="",S3="",U3="",W3="",Y3="",AA3="",AC3=""),"",IF(OR(AND(O3<>"NA",O3<>"C",O3<>"NC",O3<>"SF",O3<>""),AND(Q3<>"NA",Q3<>"C",Q3<>"NC",Q3<>"SF",Q3<>""),AND(S3<>"NA",S3<>"C",S3<>"NC",S3<>"SF",S3<>""),AND(U3<>"NA",U3<>"C",U3<>"NC",U3<>"SF",U3<>""),AND(W3<>"NA",W3<>"C",W3<>"NC",W3<>"SF",W3<>""),AND(Y3<>"NA",Y3<>"C",Y3<>"NC",Y3<>"SF",Y3<>""),AND(AA3<>"NA",AA3<>"C",AA3<>"NC",AA3<>"SF",AA3<>""),AND(AC3<>"NA",AC3<>"C",AC3<>"NC",AC3<>"SF",AC3<>"")),"FALSO",IF(AND(O3="NA",Q3="NA",S3="NA",U3="NA",W3="NA",Y3="NA",AA3="NA",AC3="NA"),"NA",IF(OR(O3="NC",Q3="NC",S3="NC",U3="NC",W3="NC",Y3="NC",AA3="NC",AC3="NC",O3="SF",Q3="SF",S3="SF",U3="SF",W3="SF",Y3="SF",AA3="SF",AC3="SF"),"NC",IF(OR(O3="C",Q3="C",S3="C",U3="C",W3="C",Y3="C",AA3="C",AC3="C"),"C",""))))) -> C | AG3: =IF(AND(AE3="C",AF3="C"),"UTILIZOU O PDA CORRETAMENTE",IF(AND(AE3="C",AF3="NC"),"UTILIZOU O PDA CORRETAMENTE. NÃO HÁ FOTOS DE TODAS AS ETAPAS",IF(AND(AE3="NC",AF3="NC"),"NÃO UTILIZOU O PDA",IF(AND(AE3="NA",AF3="NA"),"NÃO AVALIADO POR FALHA DE SINCRONISMO")))) -> UTILIZOU O PDA CORRETAMENTE | AH3: C | AI3: PIRITUBA | AJ3: =E3 -> SÃO PAULO | AK3: ÁGUA
A4: ONMP - DIV MANUT SERV OPE PIRITUBA | B4: 2617564074 | C4: TRANSFORMAÇÃO LIG EXIST COM APROV RAMAL | D4: LIGAÇÃO DE ÁGUA | E4: SÃO PAULO | F4: AVENIDA RAIMUNDO PEREIRA DE MAGALHAES | G4: 10095 | H4: C/1 | I4: PIRITUBA | J4: TRANSFORMAÇÃO LIG EXIST COM APROV RAMAL | L4: 46143.423 | M4: 46143.424 | N4: ADRIANO SIMAO LINHARES | O4: C | Q4: NA | S4: NA | U4: NA | W4: NA | Y4: NA | AA4: NA | AC4: C | AE4: C | AF4: =IF(AND(O4="",Q4="",S4="",U4="",W4="",Y4="",AA4="",AC4=""),"",IF(OR(AND(O4<>"NA",O4<>"C",O4<>"NC",O4<>"SF",O4<>""),AND(Q4<>"NA",Q4<>"C",Q4<>"NC",Q4<>"SF",Q4<>""),AND(S4<>"NA",S4<>"C",S4<>"NC",S4<>"SF",S4<>""),AND(U4<>"NA",U4<>"C",U4<>"NC",U4<>"SF",U4<>""),AND(W4<>"NA",W4<>"C",W4<>"NC",W4<>"SF",W4<>""),AND(Y4<>"NA",Y4<>"C",Y4<>"NC",Y4<>"SF",Y4<>""),AND(AA4<>"NA",AA4<>"C",AA4<>"NC",AA4<>"SF",AA4<>""),AND(AC4<>"NA",AC4<>"C",AC4<>"NC",AC4<>"SF",AC4<>"")),"FALSO",IF(AND(O4="NA",Q4="NA",S4="NA",U4="NA",W4="NA",Y4="NA",AA4="NA",AC4="NA"),"NA",IF(OR(O4="NC",Q4="NC",S4="NC",U4="NC",W4="NC",Y4="NC",AA4="NC",AC4="NC",O4="SF",Q4="SF",S4="SF",U4="SF",W4="SF",Y4="SF",AA4="SF",AC4="SF"),"NC",IF(OR(O4="C",Q4="C",S4="C",U4="C",W4="C",Y4="C",AA4="C",AC4="C"),"C",""))))) -> C | AG4: =IF(AND(AE4="C",AF4="C"),"UTILIZOU O PDA CORRETAMENTE",IF(AND(AE4="C",AF4="NC"),"UTILIZOU O PDA CORRETAMENTE. NÃO HÁ FOTOS DE TODAS AS ETAPAS",IF(AND(AE4="NC",AF4="NC"),"NÃO UTILIZOU O PDA",IF(AND(AE4="NA",AF4="NA"),"NÃO AVALIADO POR FALHA DE SINCRONISMO")))) -> UTILIZOU O PDA CORRETAMENTE | AH4: C | AI4: PIRITUBA | AJ4: =E4 -> SÃO PAULO | AK4: ÁGUA
A5: ONMP - DIV MANUT SERV OPE PIRITUBA | B5: 2617733834 | C5: TRANSFORMAÇÃO LIG EXIST COM APROV RAMAL | D5: LIGAÇÃO DE ÁGUA | E5: SÃO PAULO | F5: AVENIDA RAIMUNDO PEREIRA DE MAGALHAES | G5: 2901 | H5: C/1 | I5: JD IRIS | J5: TRANSFORMAÇÃO LIG EXIST COM APROV RAMAL | L5: 46143.453 | M5: 46143.464 | N5: ADRIANO SIMAO LINHARES | O5: C | Q5: NA | S5: NA | U5: NA | W5: NA | Y5: NA | AA5: NA | AC5: C | AE5: C | AF5: =IF(AND(O5="",Q5="",S5="",U5="",W5="",Y5="",AA5="",AC5=""),"",IF(OR(AND(O5<>"NA",O5<>"C",O5<>"NC",O5<>"SF",O5<>""),AND(Q5<>"NA",Q5<>"C",Q5<>"NC",Q5<>"SF",Q5<>""),AND(S5<>"NA",S5<>"C",S5<>"NC",S5<>"SF",S5<>""),AND(U5<>"NA",U5<>"C",U5<>"NC",U5<>"SF",U5<>""),AND(W5<>"NA",W5<>"C",W5<>"NC",W5<>"SF",W5<>""),AND(Y5<>"NA",Y5<>"C",Y5<>"NC",Y5<>"SF",Y5<>""),AND(AA5<>"NA",AA5<>"C",AA5<>"NC",AA5<>"SF",AA5<>""),AND(AC5<>"NA",AC5<>"C",AC5<>"NC",AC5<>"SF",AC5<>"")),"FALSO",IF(AND(O5="NA",Q5="NA",S5="NA",U5="NA",W5="NA",Y5="NA",AA5="NA",AC5="NA"),"NA",IF(OR(O5="NC",Q5="NC",S5="NC",U5="NC",W5="NC",Y5="NC",AA5="NC",AC5="NC",O5="SF",Q5="SF",S5="SF",U5="SF",W5="SF",Y5="SF",AA5="SF",AC5="SF"),"NC",IF(OR(O5="C",Q5="C",S5="C",U5="C",W5="C",Y5="C",AA5="C",AC5="C"),"C",""))))) -> C | AG5: =IF(AND(AE5="C",AF5="C"),"UTILIZOU O PDA CORRETAMENTE",IF(AND(AE5="C",AF5="NC"),"UTILIZOU O PDA CORRETAMENTE. NÃO HÁ FOTOS DE TODAS AS ETAPAS",IF(AND(AE5="NC",AF5="NC"),"NÃO UTILIZOU O PDA",IF(AND(AE5="NA",AF5="NA"),"NÃO AVALIADO POR FALHA DE SINCRONISMO")))) -> UTILIZOU O PDA CORRETAMENTE | AH5: C | AI5: PIRITUBA | AJ5: =E5 -> SÃO PAULO | AK5: ÁGUA
A6: ONMP - DIV MANUT SERV OPE PIRITUBA | B6: 2617733862 | C6: TRANSFORMAÇÃO LIG NOVA COM APROV RAMAL | D6: LIGAÇÃO DE ÁGUA | E6: SÃO PAULO | F6: AVENIDA RAIMUNDO PEREIRA DE MAGALHAES | G6: 2901 | H6: C/2 | I6: JD IRIS | J6: TRANSFORMAÇÃO LIG NOVA COM APROV RAMAL | L6: 46143.464 | M6: 46143.467 | N6: ADRIANO SIMAO LINHARES | O6: C | Q6: NA | S6: NA | U6: NA | W6: NA | Y6: NA | AA6: NA | AC6: C | AE6: C | AF6: =IF(AND(O6="",Q6="",S6="",U6="",W6="",Y6="",AA6="",AC6=""),"",IF(OR(AND(O6<>"NA",O6<>"C",O6<>"NC",O6<>"SF",O6<>""),AND(Q6<>"NA",Q6<>"C",Q6<>"NC",Q6<>"SF",Q6<>""),AND(S6<>"NA",S6<>"C",S6<>"NC",S6<>"SF",S6<>""),AND(U6<>"NA",U6<>"C",U6<>"NC",U6<>"SF",U6<>""),AND(W6<>"NA",W6<>"C",W6<>"NC",W6<>"SF",W6<>""),AND(Y6<>"NA",Y6<>"C",Y6<>"NC",Y6<>"SF",Y6<>""),AND(AA6<>"NA",AA6<>"C",AA6<>"NC",AA6<>"SF",AA6<>""),AND(AC6<>"NA",AC6<>"C",AC6<>"NC",AC6<>"SF",AC6<>"")),"FALSO",IF(AND(O6="NA",Q6="NA",S6="NA",U6="NA",W6="NA",Y6="NA",AA6="NA",AC6="NA"),"NA",IF(OR(O6="NC",Q6="NC",S6="NC",U6="NC",W6="NC",Y6="NC",AA6="NC",AC6="NC",O6="SF",Q6="SF",S6="SF",U6="SF",W6="SF",Y6="SF",AA6="SF",AC6="SF"),"NC",IF(OR(O6="C",Q6="C",S6="C",U6="C",W6="C",Y6="C",AA6="C",AC6="C"),"C",""))))) -> C | AG6: =IF(AND(AE6="C",AF6="C"),"UTILIZOU O PDA CORRETAMENTE",IF(AND(AE6="C",AF6="NC"),"UTILIZOU O PDA CORRETAMENTE. NÃO HÁ FOTOS DE TODAS AS ETAPAS",IF(AND(AE6="NC",AF6="NC"),"NÃO UTILIZOU O PDA",IF(AND(AE6="NA",AF6="NA"),"NÃO AVALIADO POR FALHA DE SINCRONISMO")))) -> UTILIZOU O PDA CORRETAMENTE | AH6: C | AI6: PIRITUBA | AJ6: =E6 -> SÃO PAULO | AK6: ÁGUA
A7: ONMP - DIV MANUT SERV OPE PIRITUBA | B7: 2616905705 | C7: SUBSTITUIR LIGAÇÃO DE AGUA | D7: LIGAÇÃO DE ÁGUA | E7: SÃO PAULO | F7: RUA DOUTOR MARIO MAURO RAMOS MATTOSO | G7: 238 | I7: JD STA MONICA | J7: SUBSTITUIDA LIGAÇÃO DE AGUA | L7: 46143.497 | M7: 46143.535 | N7: JORGE LUIZ RODRIGUES DE OLIVEIRA | O7: C | Q7: SF | S7: C | U7: C | W7: SF | Y7: NA | AA7: SF | AC7: NC | AD7: FALTA RÉGUA E TRENA | AE7: C | AF7: =IF(AND(O7="",Q7="",S7="",U7="",W7="",Y7="",AA7="",AC7=""),"",IF(OR(AND(O7<>"NA",O7<>"C",O7<>"NC",O7<>"SF",O7<>""),AND(Q7<>"NA",Q7<>"C",Q7<>"NC",Q7<>"SF",Q7<>""),AND(S7<>"NA",S7<>"C",S7<>"NC",S7<>"SF",S7<>""),AND(U7<>"NA",U7<>"C",U7<>"NC",U7<>"SF",U7<>""),AND(W7<>"NA",W7<>"C",W7<>"NC",W7<>"SF",W7<>""),AND(Y7<>"NA",Y7<>"C",Y7<>"NC",Y7<>"SF",Y7<>""),AND(AA7<>"NA",AA7<>"C",AA7<>"NC",AA7<>"SF",AA7<>""),AND(AC7<>"NA",AC7<>"C",AC7<>"NC",AC7<>"SF",AC7<>"")),"FALSO",IF(AND(O7="NA",Q7="NA",S7="NA",U7="NA",W7="NA",Y7="NA",AA7="NA",AC7="NA"),"NA",IF(OR(O7="NC",Q7="NC",S7="NC",U7="NC",W7="NC",Y7="NC",AA7="NC",AC7="NC",O7="SF",Q7="SF",S7="SF",U7="SF",W7="SF",Y7="SF",AA7="SF",AC7="SF"),"NC",IF(OR(O7="C",Q7="C",S7="C",U7="C",W7="C",Y7="C",AA7="C",AC7="C"),"C",""))))) -> NC | AG7: =IF(AND(AE7="C",AF7="C"),"UTILIZOU O PDA CORRETAMENTE",IF(AND(AE7="C",AF7="NC"),"UTILIZOU O PDA CORRETAMENTE. NÃO HÁ FOTOS DE TODAS AS ETAPAS",IF(AND(AE7="NC",AF7="NC"),"NÃO UTILIZOU O PDA",IF(AND(AE7="NA",AF7="NA"),"NÃO AVALIADO POR FALHA DE SINCRONISMO")))) -> UTILIZOU O PDA CORRETAMENTE. NÃO HÁ FOTOS DE TODAS AS ETAPAS | AH7: C | AI7: PIRITUBA | AJ7: =E7 -> SÃO PAULO | AK7: ÁGUA
A8: ONMP - DIV MANUT SERV OPE PIRITUBA | B8: 2617994869 | C8: VAZAMENTO DE ÁGUA NÃO VISÍVEL RAMAL | D8: VAZAMENTO DE ÁGUA | E8: SÃO PAULO | F8: RUA NARCISO CASTELO BRANCO | G8: 79 | I8: JD RINCAO | J8: SUPRIMIDO RAMAL AGUA ABAND NÃO VISIVEL | L8: 46143 | M8: 46143.003 | N8: PAULO ADRIANO BORGES DA SILVA | O8: NA | Q8: NA | S8: NA | U8: NA | W8: NA | Y8: NA | AA8: NA | AC8: NA | AE8: NA | AF8: =IF(AND(O8="",Q8="",S8="",U8="",W8="",Y8="",AA8="",AC8=""),"",IF(OR(AND(O8<>"NA",O8<>"C",O8<>"NC",O8<>"SF",O8<>""),AND(Q8<>"NA",Q8<>"C",Q8<>"NC",Q8<>"SF",Q8<>""),AND(S8<>"NA",S8<>"C",S8<>"NC",S8<>"SF",S8<>""),AND(U8<>"NA",U8<>"C",U8<>"NC",U8<>"SF",U8<>""),AND(W8<>"NA",W8<>"C",W8<>"NC",W8<>"SF",W8<>""),AND(Y8<>"NA",Y8<>"C",Y8<>"NC",Y8<>"SF",Y8<>""),AND(AA8<>"NA",AA8<>"C",AA8<>"NC",AA8<>"SF",AA8<>""),AND(AC8<>"NA",AC8<>"C",AC8<>"NC",AC8<>"SF",AC8<>"")),"FALSO",IF(AND(O8="NA",Q8="NA",S8="NA",U8="NA",W8="NA",Y8="NA",AA8="NA",AC8="NA"),"NA",IF(OR(O8="NC",Q8="NC",S8="NC",U8="NC",W8="NC",Y8="NC",AA8="NC",AC8="NC",O8="SF",Q8="SF",S8="SF",U8="SF",W8="SF",Y8="SF",AA8="SF",AC8="SF"),"NC",IF(OR(O8="C",Q8="C",S8="C",U8="C",W8="C",Y8="C",AA8="C",AC8="C"),"C",""))))) -> NA | AG8: =IF(AND(AE8="C",AF8="C"),"UTILIZOU O PDA CORRETAMENTE",IF(AND(AE8="C",AF8="NC"),"UTILIZOU O PDA CORRETAMENTE. NÃO HÁ FOTOS DE TODAS AS ETAPAS",IF(AND(AE8="NC",AF8="NC"),"NÃO UTILIZOU O PDA",IF(AND(AE8="NA",AF8="NA"),"NÃO AVALIADO POR FALHA DE SINCRONISMO")))) -> NÃO AVALIADO POR FALHA DE SINCRONISMO | AH8: C | AI8: PIRITUBA | AJ8: =E8 -> SÃO PAULO | AK8: ÁGUA
A9: ONMP - DIV MANUT SERV OPE PIRITUBA | B9: 2618111511 | C9: TROCAR RAMAL DE ÁGUA PREVENTIVA | D9: RAMAL DE ÁGUA | E9: SÃO PAULO | F9: RUA SANTA CRUZ DO PIAUI | G9: 158 | I9: CONJ RES JD CANAA | J9: TROCA DE RAMAL DE AGUA PREVENTIVA | L9: 46143 | M9: 46143.001 | N9: MARCOS PEREIRA DE OLIVEIRA | O9: NA | Q9: NA | S9: NA | U9: NA | W9: NA | Y9: NA | AA9: NA | AC9: NA | AE9: NA | AF9: =IF(AND(O9="",Q9="",S9="",U9="",W9="",Y9="",AA9="",AC9=""),"",IF(OR(AND(O9<>"NA",O9<>"C",O9<>"NC",O9<>"SF",O9<>""),AND(Q9<>"NA",Q9<>"C",Q9<>"NC",Q9<>"SF",Q9<>""),AND(S9<>"NA",S9<>"C",S9<>"NC",S9<>"SF",S9<>""),AND(U9<>"NA",U9<>"C",U9<>"NC",U9<>"SF",U9<>""),AND(W9<>"NA",W9<>"C",W9<>"NC",W9<>"SF",W9<>""),AND(Y9<>"NA",Y9<>"C",Y9<>"NC",Y9<>"SF",Y9<>""),AND(AA9<>"NA",AA9<>"C",AA9<>"NC",AA9<>"SF",AA9<>""),AND(AC9<>"NA",AC9<>"C",AC9<>"NC",AC9<>"SF",AC9<>"")),"FALSO",IF(AND(O9="NA",Q9="NA",S9="NA",U9="NA",W9="NA",Y9="NA",AA9="NA",AC9="NA"),"NA",IF(OR(O9="NC",Q9="NC",S9="NC",U9="NC",W9="NC",Y9="NC",AA9="NC",AC9="NC",O9="SF",Q9="SF",S9="SF",U9="SF",W9="SF",Y9="SF",AA9="SF",AC9="SF"),"NC",IF(OR(O9="C",Q9="C",S9="C",U9="C",W9="C",Y9="C",AA9="C",AC9="C"),"C",""))))) -> NA | AG9: =IF(AND(AE9="C",AF9="C"),"UTILIZOU O PDA CORRETAMENTE",IF(AND(AE9="C",AF9="NC"),"UTILIZOU O PDA CORRETAMENTE. NÃO HÁ FOTOS DE TODAS AS ETAPAS",IF(AND(AE9="NC",AF9="NC"),"NÃO UTILIZOU O PDA",IF(AND(AE9="NA",AF9="NA"),"NÃO AVALIADO POR FALHA DE SINCRONISMO")))) -> NÃO AVALIADO POR FALHA DE SINCRONISMO | AH9: C | AI9: PIRITUBA | AJ9: =E9 -> SÃO PAULO | AK9: ÁGUA
A10: ONMP - DIV MANUT SERV OPE PIRITUBA | B10: 2617997277 | C10: VAZAMENTO DE ÁGUA NÃO VISÍVEL CAVALETE | D10: VAZAMENTO DE ÁGUA | E10: SÃO PAULO | F10: RUA SOLANEA | G10: 146 | H10: C/1 | I10: JD ANHANGUERA | J10: TROCA DE PE DE CAVALETE NÃO VISIVEL | L10: 46143 | M10: 46143.003 | N10: MARCOS PEREIRA DE OLIVEIRA | O10: NC | P10: FOTO DA FOTO | Q10: NC | R10: FOTO DA FOTO | S10: NC | T10: FOTO DA FOTO | U10: NC | V10: FOTO DA FOTO | W10: NC | X10: FOTO DA FOTO | Y10: NC | Z10: FOTO DA FOTO | AA10: NC | AB10: FOTO DA FOTO | AC10: NC | AD10: FOTO DA FOTO | AE10: NC | AF10: =IF(AND(O10="",Q10="",S10="",U10="",W10="",Y10="",AA10="",AC10=""),"",IF(OR(AND(O10<>"NA",O10<>"C",O10<>"NC",O10<>"SF",O10<>""),AND(Q10<>"NA",Q10<>"C",Q10<>"NC",Q10<>"SF",Q10<>""),AND(S10<>"NA",S10<>"C",S10<>"NC",S10<>"SF",S10<>""),AND(U10<>"NA",U10<>"C",U10<>"NC",U10<>"SF",U10<>""),AND(W10<>"NA",W10<>"C",W10<>"NC",W10<>"SF",W10<>""),AND(Y10<>"NA",Y10<>"C",Y10<>"NC",Y10<>"SF",Y10<>""),AND(AA10<>"NA",AA10<>"C",AA10<>"NC",AA10<>"SF",AA10<>""),AND(AC10<>"NA",AC10<>"C",AC10<>"NC",AC10<>"SF",AC10<>"")),"FALSO",IF(AND(O10="NA",Q10="NA",S10="NA",U10="NA",W10="NA",Y10="NA",AA10="NA",AC10="NA"),"NA",IF(OR(O10="NC",Q10="NC",S10="NC",U10="NC",W10="NC",Y10="NC",AA10="NC",AC10="NC",O10="SF",Q10="SF",S10="SF",U10="SF",W10="SF",Y10="SF",AA10="SF",AC10="SF"),"NC",IF(OR(O10="C",Q10="C",S10="C",U10="C",W10="C",Y10="C",AA10="C",AC10="C"),"C",""))))) -> NC | AG10: =IF(AND(AE10="C",AF10="C"),"UTILIZOU O PDA CORRETAMENTE",IF(AND(AE10="C",AF10="NC"),"UTILIZOU O PDA CORRETAMENTE. NÃO HÁ FOTOS DE TODAS AS ETAPAS",IF(AND(AE10="NC",AF10="NC"),"NÃO UTILIZOU O PDA",IF(AND(AE10="NA",AF10="NA"),"NÃO AVALIADO POR FALHA DE SINCRONISMO")))) -> NÃO UTILIZOU O PDA | AH10: C | AI10: PIRITUBA | AJ10: =E10 -> SÃO PAULO | AK10: ÁGUA
A11: ONMP - DIV MANUT SERV OPE PIRITUBA | B11: 2618003910 | C11: TROCAR RAMAL DE ÁGUA PREVENTIVA | D11: RAMAL DE ÁGUA | E11: SÃO PAULO | F11: TRAVESSA DAS ROSAS | G11: 37 | I11: RECANTO DOS HUMILDES | J11: TROCA DE RAMAL DE AGUA PREVENTIVA | L11: 46143.292 | M11: 46143.292 | N11: MARCOS PEREIRA DE OLIVEIRA | O11: NA | Q11: NA | S11: NA | U11: NA | W11: NA | Y11: NA | AA11: NA | AC11: NA | AE11: NA | AF11: =IF(AND(O11="",Q11="",S11="",U11="",W11="",Y11="",AA11="",AC11=""),"",IF(OR(AND(O11<>"NA",O11<>"C",O11<>"NC",O11<>"SF",O11<>""),AND(Q11<>"NA",Q11<>"C",Q11<>"NC",Q11<>"SF",Q11<>""),AND(S11<>"NA",S11<>"C",S11<>"NC",S11<>"SF",S11<>""),AND(U11<>"NA",U11<>"C",U11<>"NC",U11<>"SF",U11<>""),AND(W11<>"NA",W11<>"C",W11<>"NC",W11<>"SF",W11<>""),AND(Y11<>"NA",Y11<>"C",Y11<>"NC",Y11<>"SF",Y11<>""),AND(AA11<>"NA",AA11<>"C",AA11<>"NC",AA11<>"SF",AA11<>""),AND(AC11<>"NA",AC11<>"C",AC11<>"NC",AC11<>"SF",AC11<>"")),"FALSO",IF(AND(O11="NA",Q11="NA",S11="NA",U11="NA",W11="NA",Y11="NA",AA11="NA",AC11="NA"),"NA",IF(OR(O11="NC",Q11="NC",S11="NC",U11="NC",W11="NC",Y11="NC",AA11="NC",AC11="NC",O11="SF",Q11="SF",S11="SF",U11="SF",W11="SF",Y11="SF",AA11="SF",AC11="SF"),"NC",IF(OR(O11="C",Q11="C",S11="C",U11="C",W11="C",Y11="C",AA11="C",AC11="C"),"C",""))))) -> NA | AG11: =IF(AND(AE11="C",AF11="C"),"UTILIZOU O PDA CORRETAMENTE",IF(AND(AE11="C",AF11="NC"),"UTILIZOU O PDA CORRETAMENTE. NÃO HÁ FOTOS DE TODAS AS ETAPAS",IF(AND(AE11="NC",AF11="NC"),"NÃO UTILIZOU O PDA",IF(AND(AE11="NA",AF11="NA"),"NÃO AVALIADO POR FALHA DE SINCRONISMO")))) -> NÃO AVALIADO POR FALHA DE SINCRONISMO | AH11: C | AI11: PIRITUBA | AJ11: =E11 -> SÃO PAULO | AK11: ÁGUA
A12: ONMP - DIV MANUT SERV OPE PIRITUBA | B12: 2618108938 | C12: VAZAMENTO DE ÁGUA NÃO VISÍVEL RAMAL | D12: VAZAMENTO DE ÁGUA | E12: SÃO PAULO | F12: RUA ALBERTO CALLIX | G12: 64 | H12: C/1 | I12: JD ANHANGUERA | J12: SUPRIMIDO RAMAL AGUA ABAND NÃO VISIVEL | L12: 46144.292 | M12: 46144.292 | N12: GILBERTO JOSE DA SILVA | O12: NC | P12: FOTO DA FOTO | Q12: NC | R12: FOTO DA FOTO | S12: NC | T12: FOTO DA FOTO | U12: NC | V12: FOTO DA FOTO | W12: NC | X12: FOTO DA FOTO | Y12: NC | Z12: FOTO DA FOTO | AA12: NC | AB12: FOTO DA FOTO | AC12: NC | AD12: FOTO DA FOTO | AE12: NC | AF12: =IF(AND(O12="",Q12="",S12="",U12="",W12="",Y12="",AA12="",AC12=""),"",IF(OR(AND(O12<>"NA",O12<>"C",O12<>"NC",O12<>"SF",O12<>""),AND(Q12<>"NA",Q12<>"C",Q12<>"NC",Q12<>"SF",Q12<>""),AND(S12<>"NA",S12<>"C",S12<>"NC",S12<>"SF",S12<>""),AND(U12<>"NA",U12<>"C",U12<>"NC",U12<>"SF",U12<>""),AND(W12<>"NA",W12<>"C",W12<>"NC",W12<>"SF",W12<>""),AND(Y12<>"NA",Y12<>"C",Y12<>"NC",Y12<>"SF",Y12<>""),AND(AA12<>"NA",AA12<>"C",AA12<>"NC",AA12<>"SF",AA12<>""),AND(AC12<>"NA",AC12<>"C",AC12<>"NC",AC12<>"SF",AC12<>"")),"FALSO",IF(AND(O12="NA",Q12="NA",S12="NA",U12="NA",W12="NA",Y12="NA",AA12="NA",AC12="NA"),"NA",IF(OR(O12="NC",Q12="NC",S12="NC",U12="NC",W12="NC",Y12="NC",AA12="NC",AC12="NC",O12="SF",Q12="SF",S12="SF",U12="SF",W12="SF",Y12="SF",AA12="SF",AC12="SF"),"NC",IF(OR(O12="C",Q12="C",S12="C",U12="C",W12="C",Y12="C",AA12="C",AC12="C"),"C",""))))) -> NC | AG12: =IF(AND(AE12="C",AF12="C"),"UTILIZOU O PDA CORRETAMENTE",IF(AND(AE12="C",AF12="NC"),"UTILIZOU O PDA CORRETAMENTE. NÃO HÁ FOTOS DE TODAS AS ETAPAS",IF(AND(AE12="NC",AF12="NC"),"NÃO UTILIZOU O PDA",IF(AND(AE12="NA",AF12="NA"),"NÃO AVALIADO POR FALHA DE SINCRONISMO")))) -> NÃO UTILIZOU O PDA | AH12: C | AI12: PIRITUBA | AJ12: =E12 -> SÃO PAULO | AK12: ÁGUA
A13: ONMP - DIV MANUT SERV OPE PIRITUBA | B13: 2618109873 | C13: VAZAMENTO DE ÁGUA NÃO VISÍVEL RAMAL | D13: VAZAMENTO DE ÁGUA | E13: SÃO PAULO | F13: RUA ADALBERTO KURT | G13: 53 | I13: JD LIBANO | J13: SUPRIMIDO RAMAL AGUA ABAND NÃO VISIVEL | L13: 46143.097 | M13: 46143.159 | N13: ELCIO DE SOUZA FARIA | O13: C | Q13: SF | S13: SF | U13: NC | V13: FORA DO PADRÃO | W13: C | Y13: SF | AA13: SF | AC13: NC | AD13: BAIXA INDEVIDA | AE13: C | AF13: =IF(AND(O13="",Q13="",S13="",U13="",W13="",Y13="",AA13="",AC13=""),"",IF(OR(AND(O13<>"NA",O13<>"C",O13<>"NC",O13<>"SF",O13<>""),AND(Q13<>"NA",Q13<>"C",Q13<>"NC",Q13<>"SF",Q13<>""),AND(S13<>"NA",S13<>"C",S13<>"NC",S13<>"SF",S13<>""),AND(U13<>"NA",U13<>"C",U13<>"NC",U13<>"SF",U13<>""),AND(W13<>"NA",W13<>"C",W13<>"NC",W13<>"SF",W13<>""),AND(Y13<>"NA",Y13<>"C",Y13<>"NC",Y13<>"SF",Y13<>""),AND(AA13<>"NA",AA13<>"C",AA13<>"NC",AA13<>"SF",AA13<>""),AND(AC13<>"NA",AC13<>"C",AC13<>"NC",AC13<>"SF",AC13<>"")),"FALSO",IF(AND(O13="NA",Q13="NA",S13="NA",U13="NA",W13="NA",Y13="NA",AA13="NA",AC13="NA"),"NA",IF(OR(O13="NC",Q13="NC",S13="NC",U13="NC",W13="NC",Y13="NC",AA13="NC",AC13="NC",O13="SF",Q13="SF",S13="SF",U13="SF",W13="SF",Y13="SF",AA13="SF",AC13="SF"),"NC",IF(OR(O13="C",Q13="C",S13="C",U13="C",W13="C",Y13="C",AA13="C",AC13="C"),"C",""))))) -> NC | AG13: =IF(AND(AE13="C",AF13="C"),"UTILIZOU O PDA CORRETAMENTE",IF(AND(AE13="C",AF13="NC"),"UTILIZOU O PDA CORRETAMENTE. NÃO HÁ FOTOS DE TODAS AS ETAPAS",IF(AND(AE13="NC",AF13="NC"),"NÃO UTILIZOU O PDA",IF(AND(AE13="NA",AF13="NA"),"NÃO AVALIADO POR FALHA DE SINCRONISMO")))) -> UTILIZOU O PDA CORRETAMENTE. NÃO HÁ FOTOS DE TODAS AS ETAPAS | AH13: C | AI13: PIRITUBA | AJ13: =E13 -> SÃO PAULO | AK13: ÁGUA
A14: ONMP - DIV MANUT SERV OPE PIRITUBA | B14: 2617930772 | C14: LIGAÇÃO DE ÁGUA EM CAVALETE MULTIPLO | D14: LIGAÇÃO DE ÁGUA | E14: SÃO PAULO | F14: RUA PIRACICABA | G14: 65 | H14: Casa C/1 | I14: PQ ANHANGUERA | J14: LIGAÇÃO DE AGUA EM CAVALETE MÚLTIPLO | L14: 46143.692 | M14: 46143.695 | N14: JORGE LUIZ RODRIGUES DE OLIVEIRA | O14: C | Q14: SF | S14: SF | U14: SF | W14: SF | Y14: NA | AA14: SF | AC14: NC | AD14: FALTA A FOTO DA FINALIZAÇÃO DA VALA ABERTA | AE14: C | AF14: =IF(AND(O14="",Q14="",S14="",U14="",W14="",Y14="",AA14="",AC14=""),"",IF(OR(AND(O14<>"NA",O14<>"C",O14<>"NC",O14<>"SF",O14<>""),AND(Q14<>"NA",Q14<>"C",Q14<>"NC",Q14<>"SF",Q14<>""),AND(S14<>"NA",S14<>"C",S14<>"NC",S14<>"SF",S14<>""),AND(U14<>"NA",U14<>"C",U14<>"NC",U14<>"SF",U14<>""),AND(W14<>"NA",W14<>"C",W14<>"NC",W14<>"SF",W14<>""),AND(Y14<>"NA",Y14<>"C",Y14<>"NC",Y14<>"SF",Y14<>""),AND(AA14<>"NA",AA14<>"C",AA14<>"NC",AA14<>"SF",AA14<>""),AND(AC14<>"NA",AC14<>"C",AC14<>"NC",AC14<>"SF",AC14<>"")),"FALSO",IF(AND(O14="NA",Q14="NA",S14="NA",U14="NA",W14="NA",Y14="NA",AA14="NA",AC14="NA"),"NA",IF(OR(O14="NC",Q14="NC",S14="NC",U14="NC",W14="NC",Y14="NC",AA14="NC",AC14="NC",O14="SF",Q14="SF",S14="SF",U14="SF",W14="SF",Y14="SF",AA14="SF",AC14="SF"),"NC",IF(OR(O14="C",Q14="C",S14="C",U14="C",W14="C",Y14="C",AA14="C",AC14="C"),"C",""))))) -> NC | AG14: =IF(AND(AE14="C",AF14="C"),"UTILIZOU O PDA CORRETAMENTE",IF(AND(AE14="C",AF14="NC"),"UTILIZOU O PDA CORRETAMENTE. NÃO HÁ FOTOS DE TODAS AS ETAPAS",IF(AND(AE14="NC",AF14="NC"),"NÃO UTILIZOU O PDA",IF(AND(AE14="NA",AF14="NA"),"NÃO AVALIADO POR FALHA DE SINCRONISMO")))) -> UTILIZOU O PDA CORRETAMENTE. NÃO HÁ FOTOS DE TODAS AS ETAPAS | AH14: C | AI14: PIRITUBA | AJ14: =E14 -> SÃO PAULO | AK14: ÁGUA
A15: ONMP - DIV MANUT SERV OPE PIRITUBA | B15: 2617930775 | C15: LIGAÇÃO DE ÁGUA EM CAVALETE MULTIPLO | D15: LIGAÇÃO DE ÁGUA | E15: SÃO PAULO | F15: RUA PIRACICABA | G15: 65 | H15: Casa C/2 | I15: PQ ANHANGUERA | J15: LIGAÇÃO DE AGUA EM CAVALETE MÚLTIPLO | L15: 46143.696 | M15: 46143.697 | N15: JORGE LUIZ RODRIGUES DE OLIVEIRA | O15: C | Q15: SF | S15: SF | U15: SF | W15: SF | Y15: NA | AA15: SF | AC15: NC | AD15: FALTA A FOTO DA FINALIZAÇÃO DA VALA ABERTA | AE15: C | AF15: =IF(AND(O15="",Q15="",S15="",U15="",W15="",Y15="",AA15="",AC15=""),"",IF(OR(AND(O15<>"NA",O15<>"C",O15<>"NC",O15<>"SF",O15<>""),AND(Q15<>"NA",Q15<>"C",Q15<>"NC",Q15<>"SF",Q15<>""),AND(S15<>"NA",S15<>"C",S15<>"NC",S15<>"SF",S15<>""),AND(U15<>"NA",U15<>"C",U15<>"NC",U15<>"SF",U15<>""),AND(W15<>"NA",W15<>"C",W15<>"NC",W15<>"SF",W15<>""),AND(Y15<>"NA",Y15<>"C",Y15<>"NC",Y15<>"SF",Y15<>""),AND(AA15<>"NA",AA15<>"C",AA15<>"NC",AA15<>"SF",AA15<>""),AND(AC15<>"NA",AC15<>"C",AC15<>"NC",AC15<>"SF",AC15<>"")),"FALSO",IF(AND(O15="NA",Q15="NA",S15="NA",U15="NA",W15="NA",Y15="NA",AA15="NA",AC15="NA"),"NA",IF(OR(O15="NC",Q15="NC",S15="NC",U15="NC",W15="NC",Y15="NC",AA15="NC",AC15="NC",O15="SF",Q15="SF",S15="SF",U15="SF",W15="SF",Y15="SF",AA15="SF",AC15="SF"),"NC",IF(OR(O15="C",Q15="C",S15="C",U15="C",W15="C",Y15="C",AA15="C",AC15="C"),"C",""))))) -> NC | AG15: =IF(AND(AE15="C",AF15="C"),"UTILIZOU O PDA CORRETAMENTE",IF(AND(AE15="C",AF15="NC"),"UTILIZOU O PDA CORRETAMENTE. NÃO HÁ FOTOS DE TODAS AS ETAPAS",IF(AND(AE15="NC",AF15="NC"),"NÃO UTILIZOU O PDA",IF(AND(AE15="NA",AF15="NA"),"NÃO AVALIADO POR FALHA DE SINCRONISMO")))) -> UTILIZOU O PDA CORRETAMENTE. NÃO HÁ FOTOS DE TODAS AS ETAPAS | AH15: C | AI15: PIRITUBA | AJ15: =E15 -> SÃO PAULO | AK15: ÁGUA
A16: ONMP - DIV MANUT SERV OPE PIRITUBA | B16: 2617930777 | C16: LIGAÇÃO DE ÁGUA EM CAVALETE MULTIPLO | D16: LIGAÇÃO DE ÁGUA | E16: SÃO PAULO | F16: RUA PIRACICABA | G16: 65 | H16: Casa C/3 | I16: PQ ANHANGUERA | J16: LIGAÇÃO DE AGUA EM CAVALETE MÚLTIPLO | L16: 46143.697 | M16: 46143.698 | N16: JORGE LUIZ RODRIGUES DE OLIVEIRA | O16: C | Q16: SF | S16: SF | U16: SF | W16: SF | Y16: NA | AA16: SF | AC16: NC | AD16: FALTA A FOTO DA FINALIZAÇÃO DA VALA ABERTA | AE16: C | AF16: =IF(AND(O16="",Q16="",S16="",U16="",W16="",Y16="",AA16="",AC16=""),"",IF(OR(AND(O16<>"NA",O16<>"C",O16<>"NC",O16<>"SF",O16<>""),AND(Q16<>"NA",Q16<>"C",Q16<>"NC",Q16<>"SF",Q16<>""),AND(S16<>"NA",S16<>"C",S16<>"NC",S16<>"SF",S16<>""),AND(U16<>"NA",U16<>"C",U16<>"NC",U16<>"SF",U16<>""),AND(W16<>"NA",W16<>"C",W16<>"NC",W16<>"SF",W16<>""),AND(Y16<>"NA",Y16<>"C",Y16<>"NC",Y16<>"SF",Y16<>""),AND(AA16<>"NA",AA16<>"C",AA16<>"NC",AA16<>"SF",AA16<>""),AND(AC16<>"NA",AC16<>"C",AC16<>"NC",AC16<>"SF",AC16<>"")),"FALSO",IF(AND(O16="NA",Q16="NA",S16="NA",U16="NA",W16="NA",Y16="NA",AA16="NA",AC16="NA"),"NA",IF(OR(O16="NC",Q16="NC",S16="NC",U16="NC",W16="NC",Y16="NC",AA16="NC",AC16="NC",O16="SF",Q16="SF",S16="SF",U16="SF",W16="SF",Y16="SF",AA16="SF",AC16="SF"),"NC",IF(OR(O16="C",Q16="C",S16="C",U16="C",W16="C",Y16="C",AA16="C",AC16="C"),"C",""))))) -> NC | AG16: =IF(AND(AE16="C",AF16="C"),"UTILIZOU O PDA CORRETAMENTE",IF(AND(AE16="C",AF16="NC"),"UTILIZOU O PDA CORRETAMENTE. NÃO HÁ FOTOS DE TODAS AS ETAPAS",IF(AND(AE16="NC",AF16="NC"),"NÃO UTILIZOU O PDA",IF(AND(AE16="NA",AF16="NA"),"NÃO AVALIADO POR FALHA DE SINCRONISMO")))) -> UTILIZOU O PDA CORRETAMENTE. NÃO HÁ FOTOS DE TODAS AS ETAPAS | AH16: C | AI16: PIRITUBA | AJ16: =E16 -> SÃO PAULO | AK16: ÁGUA
A17: ONMP - DIV MANUT SERV OPE PIRITUBA | B17: 2617930787 | C17: LIGAÇÃO DE ÁGUA EM CAVALETE MULTIPLO | D17: LIGAÇÃO DE ÁGUA | E17: SÃO PAULO | F17: RUA PIRACICABA | G17: 65 | H17: Casa C/4 | I17: PQ ANHANGUERA | J17: LIGAÇÃO DE AGUA EM CAVALETE MÚLTIPLO | L17: 46143.699 | M17: 46143.699 | N17: JORGE LUIZ RODRIGUES DE OLIVEIRA | O17: C | Q17: SF | S17: SF | U17: SF | W17: SF | Y17: NA | AA17: SF | AC17: NC | AD17: FALTA A FOTO DA FINALIZAÇÃO DA VALA ABERTA | AE17: C | AF17: =IF(AND(O17="",Q17="",S17="",U17="",W17="",Y17="",AA17="",AC17=""),"",IF(OR(AND(O17<>"NA",O17<>"C",O17<>"NC",O17<>"SF",O17<>""),AND(Q17<>"NA",Q17<>"C",Q17<>"NC",Q17<>"SF",Q17<>""),AND(S17<>"NA",S17<>"C",S17<>"NC",S17<>"SF",S17<>""),AND(U17<>"NA",U17<>"C",U17<>"NC",U17<>"SF",U17<>""),AND(W17<>"NA",W17<>"C",W17<>"NC",W17<>"SF",W17<>""),AND(Y17<>"NA",Y17<>"C",Y17<>"NC",Y17<>"SF",Y17<>""),AND(AA17<>"NA",AA17<>"C",AA17<>"NC",AA17<>"SF",AA17<>""),AND(AC17<>"NA",AC17<>"C",AC17<>"NC",AC17<>"SF",AC17<>"")),"FALSO",IF(AND(O17="NA",Q17="NA",S17="NA",U17="NA",W17="NA",Y17="NA",AA17="NA",AC17="NA"),"NA",IF(OR(O17="NC",Q17="NC",S17="NC",U17="NC",W17="NC",Y17="NC",AA17="NC",AC17="NC",O17="SF",Q17="SF",S17="SF",U17="SF",W17="SF",Y17="SF",AA17="SF",AC17="SF"),"NC",IF(OR(O17="C",Q17="C",S17="C",U17="C",W17="C",Y17="C",AA17="C",AC17="C"),"C",""))))) -> NC | AG17: =IF(AND(AE17="C",AF17="C"),"UTILIZOU O PDA CORRETAMENTE",IF(AND(AE17="C",AF17="NC"),"UTILIZOU O PDA CORRETAMENTE. NÃO HÁ FOTOS DE TODAS AS ETAPAS",IF(AND(AE17="NC",AF17="NC"),"NÃO UTILIZOU O PDA",IF(AND(AE17="NA",AF17="NA"),"NÃO AVALIADO POR FALHA DE SINCRONISMO")))) -> UTILIZOU O PDA CORRETAMENTE. NÃO HÁ FOTOS DE TODAS AS ETAPAS | AH17: C | AI17: PIRITUBA | AJ17: =E17 -> SÃO PAULO | AK17: ÁGUA
A18: ONMP - DIV MANUT SERV OPE PIRITUBA | B18: 2692087713 | C18: SONDAR RAMAL DE ÁGUA | D18: OUTROS SERVIÇOS DE ÁGUA | E18: SÃO PAULO | F18: RUA DECIO ARAUJO | G18: 19 | I18: ESTANCIA JARAGUA | J18: SONDAGEM DE RAMAL DE AGUA | K18: foi feito sondagem trata-se de vazamento interno | L18: 46143.102 | M18: 46143.104 | N18: BRUNO GONCALVES DA COSTA | O18: C | Q18: NA | S18: SF | U18: SF | W18: SF | Y18: NA | AA18: SF | AC18: SF | AE18: C | AF18: =IF(AND(O18="",Q18="",S18="",U18="",W18="",Y18="",AA18="",AC18=""),"",IF(OR(AND(O18<>"NA",O18<>"C",O18<>"NC",O18<>"SF",O18<>""),AND(Q18<>"NA",Q18<>"C",Q18<>"NC",Q18<>"SF",Q18<>""),AND(S18<>"NA",S18<>"C",S18<>"NC",S18<>"SF",S18<>""),AND(U18<>"NA",U18<>"C",U18<>"NC",U18<>"SF",U18<>""),AND(W18<>"NA",W18<>"C",W18<>"NC",W18<>"SF",W18<>""),AND(Y18<>"NA",Y18<>"C",Y18<>"NC",Y18<>"SF",Y18<>""),AND(AA18<>"NA",AA18<>"C",AA18<>"NC",AA18<>"SF",AA18<>""),AND(AC18<>"NA",AC18<>"C",AC18<>"NC",AC18<>"SF",AC18<>"")),"FALSO",IF(AND(O18="NA",Q18="NA",S18="NA",U18="NA",W18="NA",Y18="NA",AA18="NA",AC18="NA"),"NA",IF(OR(O18="NC",Q18="NC",S18="NC",U18="NC",W18="NC",Y18="NC",AA18="NC",AC18="NC",O18="SF",Q18="SF",S18="SF",U18="SF",W18="SF",Y18="SF",AA18="SF",AC18="SF"),"NC",IF(OR(O18="C",Q18="C",S18="C",U18="C",W18="C",Y18="C",AA18="C",AC18="C"),"C",""))))) -> NC | AG18: =IF(AND(AE18="C",AF18="C"),"UTILIZOU O PDA CORRETAMENTE",IF(AND(AE18="C",AF18="NC"),"UTILIZOU O PDA CORRETAMENTE. NÃO HÁ FOTOS DE TODAS AS ETAPAS",IF(AND(AE18="NC",AF18="NC"),"NÃO UTILIZOU O PDA",IF(AND(AE18="NA",AF18="NA"),"NÃO AVALIADO POR FALHA DE SINCRONISMO")))) -> UTILIZOU O PDA CORRETAMENTE. NÃO HÁ FOTOS DE TODAS AS ETAPAS | AI18: PIRITUBA | AJ18: =E18 -> SÃO PAULO | AK18: ÁGUA
A19: ONMP - DIV MANUT SERV OPE PIRITUBA | B19: 2617619673 | C19: TRANSFORMAÇÃO LIG EXIST COM APROV RAMAL | D19: LIGAÇÃO DE ÁGUA | E19: SÃO PAULO | F19: RUA PASCOAL FERNANDES | G19: 124 | H19: C/1 | I19: V STA EDWIGES | J19: TRANSFORMAÇÃO LIG EXIST COM APROV RAMAL | L19: 46143.476 | M19: 46143.478 | N19: ADRIANO SIMAO LINHARES | O19: C | Q19: NA | S19: NA | U19: NA | W19: NA | Y19: NA | AA19: NA | AC19: SF | AE19: C | AF19: =IF(AND(O19="",Q19="",S19="",U19="",W19="",Y19="",AA19="",AC19=""),"",IF(OR(AND(O19<>"NA",O19<>"C",O19<>"NC",O19<>"SF",O19<>""),AND(Q19<>"NA",Q19<>"C",Q19<>"NC",Q19<>"SF",Q19<>""),AND(S19<>"NA",S19<>"C",S19<>"NC",S19<>"SF",S19<>""),AND(U19<>"NA",U19<>"C",U19<>"NC",U19<>"SF",U19<>""),AND(W19<>"NA",W19<>"C",W19<>"NC",W19<>"SF",W19<>""),AND(Y19<>"NA",Y19<>"C",Y19<>"NC",Y19<>"SF",Y19<>""),AND(AA19<>"NA",AA19<>"C",AA19<>"NC",AA19<>"SF",AA19<>""),AND(AC19<>"NA",AC19<>"C",AC19<>"NC",AC19<>"SF",AC19<>"")),"FALSO",IF(AND(O19="NA",Q19="NA",S19="NA",U19="NA",W19="NA",Y19="NA",AA19="NA",AC19="NA"),"NA",IF(OR(O19="NC",Q19="NC",S19="NC",U19="NC",W19="NC",Y19="NC",AA19="NC",AC19="NC",O19="SF",Q19="SF",S19="SF",U19="SF",W19="SF",Y19="SF",AA19="SF",AC19="SF"),"NC",IF(OR(O19="C",Q19="C",S19="C",U19="C",W19="C",Y19="C",AA19="C",AC19="C"),"C",""))))) -> NC | AG19: =IF(AND(AE19="C",AF19="C"),"UTILIZOU O PDA CORRETAMENTE",IF(AND(AE19="C",AF19="NC"),"UTILIZOU O PDA CORRETAMENTE. NÃO HÁ FOTOS DE TODAS AS ETAPAS",IF(AND(AE19="NC",AF19="NC"),"NÃO UTILIZOU O PDA",IF(AND(AE19="NA",AF19="NA"),"NÃO AVALIADO POR FALHA DE SINCRONISMO")))) -> UTILIZOU O PDA CORRETAMENTE. NÃO HÁ FOTOS DE TODAS AS ETAPAS | AH19: C | AI19: PIRITUBA | AJ19: =E19 -> SÃO PAULO | AK19: ÁGUA
A20: ONMP - DIV MANUT SERV OPE PIRITUBA | B20: 2617776522 | C20: TRANSFORMAÇÃO LIG NOVA COM APROV RAMAL | D20: LIGAÇÃO DE ÁGUA | E20: SÃO PAULO | F20: RUA PIERRE LAFAGE | G20: 142 | H20: C/4 | I20: V JARAGUA | J20: TRANSFORMAÇÃO LIG NOVA COM APROV RAMAL | L20: 46143.506 | M20: 46143.648 | N20: ADRIANO SIMAO LINHARES | O20: C | Q20: NA | S20: NA | U20: NA | W20: NA | Y20: NA | AA20: NA | AC20: SF | AE20: C | AF20: =IF(AND(O20="",Q20="",S20="",U20="",W20="",Y20="",AA20="",AC20=""),"",IF(OR(AND(O20<>"NA",O20<>"C",O20<>"NC",O20<>"SF",O20<>""),AND(Q20<>"NA",Q20<>"C",Q20<>"NC",Q20<>"SF",Q20<>""),AND(S20<>"NA",S20<>"C",S20<>"NC",S20<>"SF",S20<>""),AND(U20<>"NA",U20<>"C",U20<>"NC",U20<>"SF",U20<>""),AND(W20<>"NA",W20<>"C",W20<>"NC",W20<>"SF",W20<>""),AND(Y20<>"NA",Y20<>"C",Y20<>"NC",Y20<>"SF",Y20<>""),AND(AA20<>"NA",AA20<>"C",AA20<>"NC",AA20<>"SF",AA20<>""),AND(AC20<>"NA",AC20<>"C",AC20<>"NC",AC20<>"SF",AC20<>"")),"FALSO",IF(AND(O20="NA",Q20="NA",S20="NA",U20="NA",W20="NA",Y20="NA",AA20="NA",AC20="NA"),"NA",IF(OR(O20="NC",Q20="NC",S20="NC",U20="NC",W20="NC",Y20="NC",AA20="NC",AC20="NC",O20="SF",Q20="SF",S20="SF",U20="SF",W20="SF",Y20="SF",AA20="SF",AC20="SF"),"NC",IF(OR(O20="C",Q20="C",S20="C",U20="C",W20="C",Y20="C",AA20="C",AC20="C"),"C",""))))) -> NC | AG20: =IF(AND(AE20="C",AF20="C"),"UTILIZOU O PDA CORRETAMENTE",IF(AND(AE20="C",AF20="NC"),"UTILIZOU O PDA CORRETAMENTE. NÃO HÁ FOTOS DE TODAS AS ETAPAS",IF(AND(AE20="NC",AF20="NC"),"NÃO UTILIZOU O PDA",IF(AND(AE20="NA",AF20="NA"),"NÃO AVALIADO POR FALHA DE SINCRONISMO")))) -> UTILIZOU O PDA CORRETAMENTE. NÃO HÁ FOTOS DE TODAS AS ETAPAS | AH20: C | AI20: PIRITUBA | AJ20: =E20 -> SÃO PAULO | AK20: ÁGUA
A21: ONMP - DIV MANUT SERV OPE PIRITUBA | B21: 2617776506 | C21: TRANSFORMAÇÃO LIG NOVA COM APROV RAMAL | D21: LIGAÇÃO DE ÁGUA | E21: SÃO PAULO | F21: RUA PIERRE LAFAGE | G21: 142 | H21: C/2 | I21: V JARAGUA | J21: TRANSFORMAÇÃO LIG NOVA COM APROV RAMAL | L21: 46143.651 | M21: 46143.651 | N21: ADRIANO SIMAO LINHARES | O21: C | Q21: NA | S21: NA | U21: NA | W21: NA | Y21: NA | AA21: NA | AC21: SF | AE21: C | AF21: =IF(AND(O21="",Q21="",S21="",U21="",W21="",Y21="",AA21="",AC21=""),"",IF(OR(AND(O21<>"NA",O21<>"C",O21<>"NC",O21<>"SF",O21<>""),AND(Q21<>"NA",Q21<>"C",Q21<>"NC",Q21<>"SF",Q21<>""),AND(S21<>"NA",S21<>"C",S21<>"NC",S21<>"SF",S21<>""),AND(U21<>"NA",U21<>"C",U21<>"NC",U21<>"SF",U21<>""),AND(W21<>"NA",W21<>"C",W21<>"NC",W21<>"SF",W21<>""),AND(Y21<>"NA",Y21<>"C",Y21<>"NC",Y21<>"SF",Y21<>""),AND(AA21<>"NA",AA21<>"C",AA21<>"NC",AA21<>"SF",AA21<>""),AND(AC21<>"NA",AC21<>"C",AC21<>"NC",AC21<>"SF",AC21<>"")),"FALSO",IF(AND(O21="NA",Q21="NA",S21="NA",U21="NA",W21="NA",Y21="NA",AA21="NA",AC21="NA"),"NA",IF(OR(O21="NC",Q21="NC",S21="NC",U21="NC",W21="NC",Y21="NC",AA21="NC",AC21="NC",O21="SF",Q21="SF",S21="SF",U21="SF",W21="SF",Y21="SF",AA21="SF",AC21="SF"),"NC",IF(OR(O21="C",Q21="C",S21="C",U21="C",W21="C",Y21="C",AA21="C",AC21="C"),"C",""))))) -> NC | AG21: =IF(AND(AE21="C",AF21="C"),"UTILIZOU O PDA CORRETAMENTE",IF(AND(AE21="C",AF21="NC"),"UTILIZOU O PDA CORRETAMENTE. NÃO HÁ FOTOS DE TODAS AS ETAPAS",IF(AND(AE21="NC",AF21="NC"),"NÃO UTILIZOU O PDA",IF(AND(AE21="NA",AF21="NA"),"NÃO AVALIADO POR FALHA DE SINCRONISMO")))) -> UTILIZOU O PDA CORRETAMENTE. NÃO HÁ FOTOS DE TODAS AS ETAPAS | AH21: C | AI21: PIRITUBA | AJ21: =E21 -> SÃO PAULO | AK21: ÁGUA
A22: ONMP - DIV MANUT SERV OPE PIRITUBA | B22: 2617776504 | C22: TRANSFORMAÇÃO LIG EXIST COM APROV RAMAL | D22: LIGAÇÃO DE ÁGUA | E22: SÃO PAULO | F22: RUA PIERRE LAFAGE | G22: 142 | H22: C/1 | I22: V JARAGUA | J22: TRANSFORMAÇÃO LIG EXIST COM APROV RAMAL | L22: 46143.65 | M22: 46143.651 | N22: ADRIANO SIMAO LINHARES | O22: C | Q22: NA | S22: NA | U22: NA | W22: NA | Y22: NA | AA22: NA | AC22: SF | AE22: C | AF22: =IF(AND(O22="",Q22="",S22="",U22="",W22="",Y22="",AA22="",AC22=""),"",IF(OR(AND(O22<>"NA",O22<>"C",O22<>"NC",O22<>"SF",O22<>""),AND(Q22<>"NA",Q22<>"C",Q22<>"NC",Q22<>"SF",Q22<>""),AND(S22<>"NA",S22<>"C",S22<>"NC",S22<>"SF",S22<>""),AND(U22<>"NA",U22<>"C",U22<>"NC",U22<>"SF",U22<>""),AND(W22<>"NA",W22<>"C",W22<>"NC",W22<>"SF",W22<>""),AND(Y22<>"NA",Y22<>"C",Y22<>"NC",Y22<>"SF",Y22<>""),AND(AA22<>"NA",AA22<>"C",AA22<>"NC",AA22<>"SF",AA22<>""),AND(AC22<>"NA",AC22<>"C",AC22<>"NC",AC22<>"SF",AC22<>"")),"FALSO",IF(AND(O22="NA",Q22="NA",S22="NA",U22="NA",W22="NA",Y22="NA",AA22="NA",AC22="NA"),"NA",IF(OR(O22="NC",Q22="NC",S22="NC",U22="NC",W22="NC",Y22="NC",AA22="NC",AC22="NC",O22="SF",Q22="SF",S22="SF",U22="SF",W22="SF",Y22="SF",AA22="SF",AC22="SF"),"NC",IF(OR(O22="C",Q22="C",S22="C",U22="C",W22="C",Y22="C",AA22="C",AC22="C"),"C",""))))) -> NC | AG22: =IF(AND(AE22="C",AF22="C"),"UTILIZOU O PDA CORRETAMENTE",IF(AND(AE22="C",AF22="NC"),"UTILIZOU O PDA CORRETAMENTE. NÃO HÁ FOTOS DE TODAS AS ETAPAS",IF(AND(AE22="NC",AF22="NC"),"NÃO UTILIZOU O PDA",IF(AND(AE22="NA",AF22="NA"),"NÃO AVALIADO POR FALHA DE SINCRONISMO")))) -> UTILIZOU O PDA CORRETAMENTE. NÃO HÁ FOTOS DE TODAS AS ETAPAS | AH22: C | AI22: PIRITUBA | AJ22: =E22 -> SÃO PAULO | AK22: ÁGUA
A23: ONMP - DIV MANUT SERV OPE PIRITUBA | B23: 2617776509 | C23: TRANSFORMAÇÃO LIG NOVA COM APROV RAMAL | D23: LIGAÇÃO DE ÁGUA | E23: SÃO PAULO | F23: RUA PIERRE LAFAGE | G23: 142 | H23: C/3 | I23: V JARAGUA | J23: TRANSFORMAÇÃO LIG NOVA COM APROV RAMAL | L23: 46143.649 | M23: 46143.649 | N23: ADRIANO SIMAO LINHARES | O23: C | Q23: SF | S23: SF | U23: SF | W23: SF | Y23: NA | AA23: SF | AC23: SF | AE23: C | AF23: =IF(AND(O23="",Q23="",S23="",U23="",W23="",Y23="",AA23="",AC23=""),"",IF(OR(AND(O23<>"NA",O23<>"C",O23<>"NC",O23<>"SF",O23<>""),AND(Q23<>"NA",Q23<>"C",Q23<>"NC",Q23<>"SF",Q23<>""),AND(S23<>"NA",S23<>"C",S23<>"NC",S23<>"SF",S23<>""),AND(U23<>"NA",U23<>"C",U23<>"NC",U23<>"SF",U23<>""),AND(W23<>"NA",W23<>"C",W23<>"NC",W23<>"SF",W23<>""),AND(Y23<>"NA",Y23<>"C",Y23<>"NC",Y23<>"SF",Y23<>""),AND(AA23<>"NA",AA23<>"C",AA23<>"NC",AA23<>"SF",AA23<>""),AND(AC23<>"NA",AC23<>"C",AC23<>"NC",AC23<>"SF",AC23<>"")),"FALSO",IF(AND(O23="NA",Q23="NA",S23="NA",U23="NA",W23="NA",Y23="NA",AA23="NA",AC23="NA"),"NA",IF(OR(O23="NC",Q23="NC",S23="NC",U23="NC",W23="NC",Y23="NC",AA23="NC",AC23="NC",O23="SF",Q23="SF",S23="SF",U23="SF",W23="SF",Y23="SF",AA23="SF",AC23="SF"),"NC",IF(OR(O23="C",Q23="C",S23="C",U23="C",W23="C",Y23="C",AA23="C",AC23="C"),"C",""))))) -> NC | AG23: =IF(AND(AE23="C",AF23="C"),"UTILIZOU O PDA CORRETAMENTE",IF(AND(AE23="C",AF23="NC"),"UTILIZOU O PDA CORRETAMENTE. NÃO HÁ FOTOS DE TODAS AS ETAPAS",IF(AND(AE23="NC",AF23="NC"),"NÃO UTILIZOU O PDA",IF(AND(AE23="NA",AF23="NA"),"NÃO AVALIADO POR FALHA DE SINCRONISMO")))) -> UTILIZOU O PDA CORRETAMENTE. NÃO HÁ FOTOS DE TODAS AS ETAPAS | AH23: C | AI23: PIRITUBA | AJ23: =E23 -> SÃO PAULO | AK23: ÁGUA
A24: ONMP - DIV MANUT SERV OPE PIRITUBA | B24: 2692114144 | C24: TROCAR RAMAL DE ÁGUA | D24: VAZAMENTO DE ÁGUA | E24: SÃO PAULO | F24: RUA OLGA BENARIO | G24: 72 | H24: C/2 | I24: JD ELISA MARIA | J24: TROCA DE RAMAL DE AGUA | K24: sem reposição cliente ciente esta em obras no local | L24: 46143.16 | M24: 46143.175 | N24: JUVENAL MORAIS DA SILVA | O24: C | Q24: NC | R24: FALTA PLACA DE ESTREITAMENTO DE PISTA E 50M | S24: SF | U24: C | W24: C | Y24: SF | AA24: SF | AC24: NC | AD24: BAIXA INDEVIDA, FALTA RÉGUA E TRENA | AE24: C | AF24: =IF(AND(O24="",Q24="",S24="",U24="",W24="",Y24="",AA24="",AC24=""),"",IF(OR(AND(O24<>"NA",O24<>"C",O24<>"NC",O24<>"SF",O24<>""),AND(Q24<>"NA",Q24<>"C",Q24<>"NC",Q24<>"SF",Q24<>""),AND(S24<>"NA",S24<>"C",S24<>"NC",S24<>"SF",S24<>""),AND(U24<>"NA",U24<>"C",U24<>"NC",U24<>"SF",U24<>""),AND(W24<>"NA",W24<>"C",W24<>"NC",W24<>"SF",W24<>""),AND(Y24<>"NA",Y24<>"C",Y24<>"NC",Y24<>"SF",Y24<>""),AND(AA24<>"NA",AA24<>"C",AA24<>"NC",AA24<>"SF",AA24<>""),AND(AC24<>"NA",AC24<>"C",AC24<>"NC",AC24<>"SF",AC24<>"")),"FALSO",IF(AND(O24="NA",Q24="NA",S24="NA",U24="NA",W24="NA",Y24="NA",AA24="NA",AC24="NA"),"NA",IF(OR(O24="NC",Q24="NC",S24="NC",U24="NC",W24="NC",Y24="NC",AA24="NC",AC24="NC",O24="SF",Q24="SF",S24="SF",U24="SF",W24="SF",Y24="SF",AA24="SF",AC24="SF"),"NC",IF(OR(O24="C",Q24="C",S24="C",U24="C",W24="C",Y24="C",AA24="C",AC24="C"),"C",""))))) -> NC | AG24: =IF(AND(AE24="C",AF24="C"),"UTILIZOU O PDA CORRETAMENTE",IF(AND(AE24="C",AF24="NC"),"UTILIZOU O PDA CORRETAMENTE. NÃO HÁ FOTOS DE TODAS AS ETAPAS",IF(AND(AE24="NC",AF24="NC"),"NÃO UTILIZOU O PDA",IF(AND(AE24="NA",AF24="NA"),"NÃO AVALIADO POR FALHA DE SINCRONISMO")))) -> UTILIZOU O PDA CORRETAMENTE. NÃO HÁ FOTOS DE TODAS AS ETAPAS | AH24: C | AI24: PIRITUBA | AJ24: =E24 -> SÃO PAULO | AK24: ÁGUA
A25: ONMP - DIV MANUT SERV OPE PIRITUBA | B25: 2692133869 | C25: VAZAMENTO DE ÁGUA NO PASSEIO | D25: VAZAMENTO DE ÁGUA | E25: SÃO PAULO | F25: RUA LINO PINTO DOS SANTOS | G25: 102 | I25: JD FELICIDADE | J25: SUPRIMIDO RAMAL DE AGUA ABANDONADO | L25: 46143.625 | M25: 46143.626 | N25: PAULO ADRIANO BORGES DA SILVA | O25: NA | Q25: NA | S25: NA | U25: NA | W25: NA | Y25: NA | AA25: NA | AC25: NA | AE25: NA | AF25: =IF(AND(O25="",Q25="",S25="",U25="",W25="",Y25="",AA25="",AC25=""),"",IF(OR(AND(O25<>"NA",O25<>"C",O25<>"NC",O25<>"SF",O25<>""),AND(Q25<>"NA",Q25<>"C",Q25<>"NC",Q25<>"SF",Q25<>""),AND(S25<>"NA",S25<>"C",S25<>"NC",S25<>"SF",S25<>""),AND(U25<>"NA",U25<>"C",U25<>"NC",U25<>"SF",U25<>""),AND(W25<>"NA",W25<>"C",W25<>"NC",W25<>"SF",W25<>""),AND(Y25<>"NA",Y25<>"C",Y25<>"NC",Y25<>"SF",Y25<>""),AND(AA25<>"NA",AA25<>"C",AA25<>"NC",AA25<>"SF",AA25<>""),AND(AC25<>"NA",AC25<>"C",AC25<>"NC",AC25<>"SF",AC25<>"")),"FALSO",IF(AND(O25="NA",Q25="NA",S25="NA",U25="NA",W25="NA",Y25="NA",AA25="NA",AC25="NA"),"NA",IF(OR(O25="NC",Q25="NC",S25="NC",U25="NC",W25="NC",Y25="NC",AA25="NC",AC25="NC",O25="SF",Q25="SF",S25="SF",U25="SF",W25="SF",Y25="SF",AA25="SF",AC25="SF"),"NC",IF(OR(O25="C",Q25="C",S25="C",U25="C",W25="C",Y25="C",AA25="C",AC25="C"),"C",""))))) -> NA | AG25: =IF(AND(AE25="C",AF25="C"),"UTILIZOU O PDA CORRETAMENTE",IF(AND(AE25="C",AF25="NC"),"UTILIZOU O PDA CORRETAMENTE. NÃO HÁ FOTOS DE TODAS AS ETAPAS",IF(AND(AE25="NC",AF25="NC"),"NÃO UTILIZOU O PDA",IF(AND(AE25="NA",AF25="NA"),"NÃO AVALIADO POR FALHA DE SINCRONISMO")))) -> NÃO AVALIADO POR FALHA DE SINCRONISMO | AH25: C | AI25: PIRITUBA | AJ25: =E25 -> SÃO PAULO | AK25: ÁGUA
A26: ONMP - DIV MANUT SERV OPE PIRITUBA | B26: 2618109873 | C26: TROCAR RAMAL DE ÁGUA - VAZ NÃO VISIVEL | D26: VAZAMENTO DE ÁGUA | E26: SÃO PAULO | F26: RUA ADALBERTO KURT | G26: 53 | I26: JD LIBANO | J26: TROCA DE RAMAL DE AGUA NÃO VISIVEL | L26: 46143.16 | M26: 46143.222 | N26: ELCIO DE SOUZA FARIA | O26: C | Q26: SF | S26: SF | U26: NC | V26: FORA DO PADRÃO | W26: C | Y26: SF | AA26: SF | AC26: NC | AD26: BAIXA INDEVIDA | AE26: C | AF26: =IF(AND(O26="",Q26="",S26="",U26="",W26="",Y26="",AA26="",AC26=""),"",IF(OR(AND(O26<>"NA",O26<>"C",O26<>"NC",O26<>"SF",O26<>""),AND(Q26<>"NA",Q26<>"C",Q26<>"NC",Q26<>"SF",Q26<>""),AND(S26<>"NA",S26<>"C",S26<>"NC",S26<>"SF",S26<>""),AND(U26<>"NA",U26<>"C",U26<>"NC",U26<>"SF",U26<>""),AND(W26<>"NA",W26<>"C",W26<>"NC",W26<>"SF",W26<>""),AND(Y26<>"NA",Y26<>"C",Y26<>"NC",Y26<>"SF",Y26<>""),AND(AA26<>"NA",AA26<>"C",AA26<>"NC",AA26<>"SF",AA26<>""),AND(AC26<>"NA",AC26<>"C",AC26<>"NC",AC26<>"SF",AC26<>"")),"FALSO",IF(AND(O26="NA",Q26="NA",S26="NA",U26="NA",W26="NA",Y26="NA",AA26="NA",AC26="NA"),"NA",IF(OR(O26="NC",Q26="NC",S26="NC",U26="NC",W26="NC",Y26="NC",AA26="NC",AC26="NC",O26="SF",Q26="SF",S26="SF",U26="SF",W26="SF",Y26="SF",AA26="SF",AC26="SF"),"NC",IF(OR(O26="C",Q26="C",S26="C",U26="C",W26="C",Y26="C",AA26="C",AC26="C"),"C",""))))) -> NC | AG26: =IF(AND(AE26="C",AF26="C"),"UTILIZOU O PDA CORRETAMENTE",IF(AND(AE26="C",AF26="NC"),"UTILIZOU O PDA CORRETAMENTE. NÃO HÁ FOTOS DE TODAS AS ETAPAS",IF(AND(AE26="NC",AF26="NC"),"NÃO UTILIZOU O PDA",IF(AND(AE26="NA",AF26="NA"),"NÃO AVALIADO POR FALHA DE SINCRONISMO")))) -> UTILIZOU O PDA CORRETAMENTE. NÃO HÁ FOTOS DE TODAS AS ETAPAS | AH26: C | AI26: PIRITUBA | AJ26: =E26 -> SÃO PAULO | AK26: ÁGUA
A27: ONMP - DIV MANUT SERV OPE PIRITUBA | B27: 2618109873 | C27: VAZAMENTO DE ÁGUA NÃO VISÍVEL CAVALETE | D27: VAZAMENTO DE ÁGUA | E27: SÃO PAULO | F27: RUA ADALBERTO KURT | G27: 53 | I27: JD LIBANO | J27: TROCA DE PE DE CAVALETE NÃO VISIVEL | L27: 46143.223 | M27: 46143.223 | N27: ELCIO DE SOUZA FARIA | O27: C | Q27: NA | S27: NA | U27: NA | W27: NA | Y27: NA | AA27: NA | AC27: NC | AD27: FALTA LACRE | AE27: C | AF27: =IF(AND(O27="",Q27="",S27="",U27="",W27="",Y27="",AA27="",AC27=""),"",IF(OR(AND(O27<>"NA",O27<>"C",O27<>"NC",O27<>"SF",O27<>""),AND(Q27<>"NA",Q27<>"C",Q27<>"NC",Q27<>"SF",Q27<>""),AND(S27<>"NA",S27<>"C",S27<>"NC",S27<>"SF",S27<>""),AND(U27<>"NA",U27<>"C",U27<>"NC",U27<>"SF",U27<>""),AND(W27<>"NA",W27<>"C",W27<>"NC",W27<>"SF",W27<>""),AND(Y27<>"NA",Y27<>"C",Y27<>"NC",Y27<>"SF",Y27<>""),AND(AA27<>"NA",AA27<>"C",AA27<>"NC",AA27<>"SF",AA27<>""),AND(AC27<>"NA",AC27<>"C",AC27<>"NC",AC27<>"SF",AC27<>"")),"FALSO",IF(AND(O27="NA",Q27="NA",S27="NA",U27="NA",W27="NA",Y27="NA",AA27="NA",AC27="NA"),"NA",IF(OR(O27="NC",Q27="NC",S27="NC",U27="NC",W27="NC",Y27="NC",AA27="NC",AC27="NC",O27="SF",Q27="SF",S27="SF",U27="SF",W27="SF",Y27="SF",AA27="SF",AC27="SF"),"NC",IF(OR(O27="C",Q27="C",S27="C",U27="C",W27="C",Y27="C",AA27="C",AC27="C"),"C",""))))) -> NC | AG27: =IF(AND(AE27="C",AF27="C"),"UTILIZOU O PDA CORRETAMENTE",IF(AND(AE27="C",AF27="NC"),"UTILIZOU O PDA CORRETAMENTE. NÃO HÁ FOTOS DE TODAS AS ETAPAS",IF(AND(AE27="NC",AF27="NC"),"NÃO UTILIZOU O PDA",IF(AND(AE27="NA",AF27="NA"),"NÃO AVALIADO POR FALHA DE SINCRONISMO")))) -> UTILIZOU O PDA CORRETAMENTE. NÃO HÁ FOTOS DE TODAS AS ETAPAS | AI27: PIRITUBA | AJ27: =E27 -> SÃO PAULO | AK27: ÁGUA
A28: ONMP - DIV MANUT SERV OPE PIRITUBA | B28: 2617971478 | C28: SONDAR REDE DE ÁGUA | D28: OUTROS SERVIÇOS DE ÁGUA | E28: SÃO PAULO | F28: RUA ILHA DOS SETE ENGENHOS | G28: 90 | H28: C/2 | I28: JARAGUA | J28: SONDAGEM DE REDE DE AGUA | K28: necessário geofone no local | L28: 46143.479 | M28: 46143.484 | N28: WELVES DE SOUSA BRITO | O28: C | Q28: C | S28: NC | T28: NÃO UTILIZADO | U28: C | W28: SF | Y28: NA | AA28: SF | AC28: SF | AE28: C | AF28: =IF(AND(O28="",Q28="",S28="",U28="",W28="",Y28="",AA28="",AC28=""),"",IF(OR(AND(O28<>"NA",O28<>"C",O28<>"NC",O28<>"SF",O28<>""),AND(Q28<>"NA",Q28<>"C",Q28<>"NC",Q28<>"SF",Q28<>""),AND(S28<>"NA",S28<>"C",S28<>"NC",S28<>"SF",S28<>""),AND(U28<>"NA",U28<>"C",U28<>"NC",U28<>"SF",U28<>""),AND(W28<>"NA",W28<>"C",W28<>"NC",W28<>"SF",W28<>""),AND(Y28<>"NA",Y28<>"C",Y28<>"NC",Y28<>"SF",Y28<>""),AND(AA28<>"NA",AA28<>"C",AA28<>"NC",AA28<>"SF",AA28<>""),AND(AC28<>"NA",AC28<>"C",AC28<>"NC",AC28<>"SF",AC28<>"")),"FALSO",IF(AND(O28="NA",Q28="NA",S28="NA",U28="NA",W28="NA",Y28="NA",AA28="NA",AC28="NA"),"NA",IF(OR(O28="NC",Q28="NC",S28="NC",U28="NC",W28="NC",Y28="NC",AA28="NC",AC28="NC",O28="SF",Q28="SF",S28="SF",U28="SF",W28="SF",Y28="SF",AA28="SF",AC28="SF"),"NC",IF(OR(O28="C",Q28="C",S28="C",U28="C",W28="C",Y28="C",AA28="C",AC28="C"),"C",""))))) -> NC | AG28: =IF(AND(AE28="C",AF28="C"),"UTILIZOU O PDA CORRETAMENTE",IF(AND(AE28="C",AF28="NC"),"UTILIZOU O PDA CORRETAMENTE. NÃO HÁ FOTOS DE TODAS AS ETAPAS",IF(AND(AE28="NC",AF28="NC"),"NÃO UTILIZOU O PDA",IF(AND(AE28="NA",AF28="NA"),"NÃO AVALIADO POR FALHA DE SINCRONISMO")))) -> UTILIZOU O PDA CORRETAMENTE. NÃO HÁ FOTOS DE TODAS AS ETAPAS | AH28: C | AI28: PIRITUBA | AJ28: =E28 -> SÃO PAULO | AK28: ÁGUA
A29: ONMP - DIV MANUT SERV OPE PIRITUBA | B29: 2618304847 | C29: VAZAMENTO DE ÁGUA LEITO PAVIMENTADO | D29: VAZAMENTO DE ÁGUA | E29: SÃO PAULO | F29: RUA RODOLFO PEREIRA LIMA | G29: 144 | H29: C/1 | I29: V TEREZINHA | J29: SUPRIMIDO RAMAL DE AGUA ABANDONADO | K29: equipe pedro | L29: 46144.292 | M29: 46144.292 | N29: JHENIFER APARECIDA ALVES LIMA | O29: NA | Q29: NA | S29: NA | U29: NA | W29: NA | Y29: NA | AA29: NA | AC29: NA | AE29: NA | AF29: =IF(AND(O29="",Q29="",S29="",U29="",W29="",Y29="",AA29="",AC29=""),"",IF(OR(AND(O29<>"NA",O29<>"C",O29<>"NC",O29<>"SF",O29<>""),AND(Q29<>"NA",Q29<>"C",Q29<>"NC",Q29<>"SF",Q29<>""),AND(S29<>"NA",S29<>"C",S29<>"NC",S29<>"SF",S29<>""),AND(U29<>"NA",U29<>"C",U29<>"NC",U29<>"SF",U29<>""),AND(W29<>"NA",W29<>"C",W29<>"NC",W29<>"SF",W29<>""),AND(Y29<>"NA",Y29<>"C",Y29<>"NC",Y29<>"SF",Y29<>""),AND(AA29<>"NA",AA29<>"C",AA29<>"NC",AA29<>"SF",AA29<>""),AND(AC29<>"NA",AC29<>"C",AC29<>"NC",AC29<>"SF",AC29<>"")),"FALSO",IF(AND(O29="NA",Q29="NA",S29="NA",U29="NA",W29="NA",Y29="NA",AA29="NA",AC29="NA"),"NA",IF(OR(O29="NC",Q29="NC",S29="NC",U29="NC",W29="NC",Y29="NC",AA29="NC",AC29="NC",O29="SF",Q29="SF",S29="SF",U29="SF",W29="SF",Y29="SF",AA29="SF",AC29="SF"),"NC",IF(OR(O29="C",Q29="C",S29="C",U29="C",W29="C",Y29="C",AA29="C",AC29="C"),"C",""))))) -> NA | AG29: =IF(AND(AE29="C",AF29="C"),"UTILIZOU O PDA CORRETAMENTE",IF(AND(AE29="C",AF29="NC"),"UTILIZOU O PDA CORRETAMENTE. NÃO HÁ FOTOS DE TODAS AS ETAPAS",IF(AND(AE29="NC",AF29="NC"),"NÃO UTILIZOU O PDA",IF(AND(AE29="NA",AF29="NA"),"NÃO AVALIADO POR FALHA DE SINCRONISMO")))) -> NÃO AVALIADO POR FALHA DE SINCRONISMO | AH29: C | AI29: PIRITUBA | AJ29: =E29 -> SÃO PAULO | AK29: ÁGUA
A30: ONMP - DIV MANUT SERV OPE PIRITUBA | B30: 2618310146 | C30: TROCAR RAMAL DE ÁGUA PREVENTIVA | D30: RAMAL DE ÁGUA | E30: SÃO PAULO | F30: RUA DELSUC ALVES DE MAGALHAES | G30: 528 | I30: JD BRITANIA | J30: TROCA DE RAMAL DE AGUA PREVENTIVA | K30: na mesma vala 522 | L30: 46143.536 | M30: 46143.539 | N30: GILBERTO JOSE DA SILVA | O30: SF | Q30: SF | S30: SF | U30: SF | W30: SF | Y30: SF | AA30: SF | AC30: SF | AE30: NC | AF30: =IF(AND(O30="",Q30="",S30="",U30="",W30="",Y30="",AA30="",AC30=""),"",IF(OR(AND(O30<>"NA",O30<>"C",O30<>"NC",O30<>"SF",O30<>""),AND(Q30<>"NA",Q30<>"C",Q30<>"NC",Q30<>"SF",Q30<>""),AND(S30<>"NA",S30<>"C",S30<>"NC",S30<>"SF",S30<>""),AND(U30<>"NA",U30<>"C",U30<>"NC",U30<>"SF",U30<>""),AND(W30<>"NA",W30<>"C",W30<>"NC",W30<>"SF",W30<>""),AND(Y30<>"NA",Y30<>"C",Y30<>"NC",Y30<>"SF",Y30<>""),AND(AA30<>"NA",AA30<>"C",AA30<>"NC",AA30<>"SF",AA30<>""),AND(AC30<>"NA",AC30<>"C",AC30<>"NC",AC30<>"SF",AC30<>"")),"FALSO",IF(AND(O30="NA",Q30="NA",S30="NA",U30="NA",W30="NA",Y30="NA",AA30="NA",AC30="NA"),"NA",IF(OR(O30="NC",Q30="NC",S30="NC",U30="NC",W30="NC",Y30="NC",AA30="NC",AC30="NC",O30="SF",Q30="SF",S30="SF",U30="SF",W30="SF",Y30="SF",AA30="SF",AC30="SF"),"NC",IF(OR(O30="C",Q30="C",S30="C",U30="C",W30="C",Y30="C",AA30="C",AC30="C"),"C",""))))) -> NC | AG30: =IF(AND(AE30="C",AF30="C"),"UTILIZOU O PDA CORRETAMENTE",IF(AND(AE30="C",AF30="NC"),"UTILIZOU O PDA CORRETAMENTE. NÃO HÁ FOTOS DE TODAS AS ETAPAS",IF(AND(AE30="NC",AF30="NC"),"NÃO UTILIZOU O PDA",IF(AND(AE30="NA",AF30="NA"),"NÃO AVALIADO POR FALHA DE SINCRONISMO")))) -> NÃO UTILIZOU O PDA | AH30: C | AI30: PIRITUBA | AJ30: =E30 -> SÃO PAULO | AK30: ÁGUA
A31: ONMP - DIV MANUT SERV OPE PIRITUBA | B31: 2692137419 | C31: VAZAMENTO DE ÁGUA LEITO PAVIMENTADO | D31: VAZAMENTO DE ÁGUA | E31: SÃO PAULO | F31: RUA BRIOSO | G31: 13 | H31: C/2 | I31: JD DO RUSSO | J31: TROCA DE RAMAL DE AGUA | L31: 46144.461 | M31: 46144.528 | N31: WELVES DE SOUSA BRITO | O31: C | Q31: C | S31: SF | U31: C | W31: SF | Y31: SF | AA31: SF | AC31: NC | AD31: BAIXA INDEVIDA, FALTA RÉGUA, TRENA E CARIMBO | AE31: C | AF31: =IF(AND(O31="",Q31="",S31="",U31="",W31="",Y31="",AA31="",AC31=""),"",IF(OR(AND(O31<>"NA",O31<>"C",O31<>"NC",O31<>"SF",O31<>""),AND(Q31<>"NA",Q31<>"C",Q31<>"NC",Q31<>"SF",Q31<>""),AND(S31<>"NA",S31<>"C",S31<>"NC",S31<>"SF",S31<>""),AND(U31<>"NA",U31<>"C",U31<>"NC",U31<>"SF",U31<>""),AND(W31<>"NA",W31<>"C",W31<>"NC",W31<>"SF",W31<>""),AND(Y31<>"NA",Y31<>"C",Y31<>"NC",Y31<>"SF",Y31<>""),AND(AA31<>"NA",AA31<>"C",AA31<>"NC",AA31<>"SF",AA31<>""),AND(AC31<>"NA",AC31<>"C",AC31<>"NC",AC31<>"SF",AC31<>"")),"FALSO",IF(AND(O31="NA",Q31="NA",S31="NA",U31="NA",W31="NA",Y31="NA",AA31="NA",AC31="NA"),"NA",IF(OR(O31="NC",Q31="NC",S31="NC",U31="NC",W31="NC",Y31="NC",AA31="NC",AC31="NC",O31="SF",Q31="SF",S31="SF",U31="SF",W31="SF",Y31="SF",AA31="SF",AC31="SF"),"NC",IF(OR(O31="C",Q31="C",S31="C",U31="C",W31="C",Y31="C",AA31="C",AC31="C"),"C",""))))) -> NC | AG31: =IF(AND(AE31="C",AF31="C"),"UTILIZOU O PDA CORRETAMENTE",IF(AND(AE31="C",AF31="NC"),"UTILIZOU O PDA CORRETAMENTE. NÃO HÁ FOTOS DE TODAS AS ETAPAS",IF(AND(AE31="NC",AF31="NC"),"NÃO UTILIZOU O PDA",IF(AND(AE31="NA",AF31="NA"),"NÃO AVALIADO POR FALHA DE SINCRONISMO")))) -> UTILIZOU O PDA CORRETAMENTE. NÃO HÁ FOTOS DE TODAS AS ETAPAS | AH31: C | AI31: PIRITUBA | AJ31: =E31 -> SÃO PAULO | AK31: ÁGUA
A32: ONMP - DIV MANUT SERV OPE PIRITUBA | B32: 2692078384 | C32: TROCAR RAMAL DE ÁGUA | D32: VAZAMENTO DE ÁGUA | E32: SÃO PAULO | F32: RUA DELSUC ALVES DE MAGALHAES | G32: 522 | I32: JD BRITANIA | J32: TROCA DE RAMAL DE AGUA | L32: 46143.319 | M32: 46143.331 | N32: GILBERTO JOSE DA SILVA | O32: C | Q32: C | S32: SF | U32: C | W32: C | Y32: SF | AA32: SF | AC32: NC | AD32: BAIXA INDEVIDA | AE32: C | AF32: =IF(AND(O32="",Q32="",S32="",U32="",W32="",Y32="",AA32="",AC32=""),"",IF(OR(AND(O32<>"NA",O32<>"C",O32<>"NC",O32<>"SF",O32<>""),AND(Q32<>"NA",Q32<>"C",Q32<>"NC",Q32<>"SF",Q32<>""),AND(S32<>"NA",S32<>"C",S32<>"NC",S32<>"SF",S32<>""),AND(U32<>"NA",U32<>"C",U32<>"NC",U32<>"SF",U32<>""),AND(W32<>"NA",W32<>"C",W32<>"NC",W32<>"SF",W32<>""),AND(Y32<>"NA",Y32<>"C",Y32<>"NC",Y32<>"SF",Y32<>""),AND(AA32<>"NA",AA32<>"C",AA32<>"NC",AA32<>"SF",AA32<>""),AND(AC32<>"NA",AC32<>"C",AC32<>"NC",AC32<>"SF",AC32<>"")),"FALSO",IF(AND(O32="NA",Q32="NA",S32="NA",U32="NA",W32="NA",Y32="NA",AA32="NA",AC32="NA"),"NA",IF(OR(O32="NC",Q32="NC",S32="NC",U32="NC",W32="NC",Y32="NC",AA32="NC",AC32="NC",O32="SF",Q32="SF",S32="SF",U32="SF",W32="SF",Y32="SF",AA32="SF",AC32="SF"),"NC",IF(OR(O32="C",Q32="C",S32="C",U32="C",W32="C",Y32="C",AA32="C",AC32="C"),"C",""))))) -> NC | AG32: =IF(AND(AE32="C",AF32="C"),"UTILIZOU O PDA CORRETAMENTE",IF(AND(AE32="C",AF32="NC"),"UTILIZOU O PDA CORRETAMENTE. NÃO HÁ FOTOS DE TODAS AS ETAPAS",IF(AND(AE32="NC",AF32="NC"),"NÃO UTILIZOU O PDA",IF(AND(AE32="NA",AF32="NA"),"NÃO AVALIADO POR FALHA DE SINCRONISMO")))) -> UTILIZOU O PDA CORRETAMENTE. NÃO HÁ FOTOS DE TODAS AS ETAPAS | AH32: C | AI32: PIRITUBA | AJ32: =E32 -> SÃO PAULO | AK32: ÁGUA
