Workbook

Sheet CAPA
C18: RELATÓRIO PARCIAL
C20: CONTROLE TECNOLÓGICO
C21: ='DADOS - GOPOÚVA'!B4 -> Período: 01/03/2026 à 31/03/2026
C35: POLO GOPOÚVA
C36: CONTRATADA AUDITADA: CONSÓRCIO GOPOÚVA I
C37: CONTRATO: 00.238/25
C41: SÃO PAULO
C42: 2026

Sheet DADOS - GOPOÚVA
B2: GOPOÚVA
B3: ACOMPANHAMENTO EM CAMPO
B4: Período: 01/03/2026 à 31/03/2026
B6: ÍNDICE TECNOLÓGICO (%)
B7: IT (%)
D9: ÍNDICE DE CONFORMIDADE (%)
B10: Tipo de Serviço | C10: IC (%) | E10: Quantidade de LVs
B11: Água | C11: 0.9946 | E11: 48
B12: Esgoto | C12: 0.9909 | E12: 25
B13: Reposição | E13: 32
B14: Pós 60 | E14: 285
B16: GOPOÚVA | E16: FALTAM | F16: =('GRÁFICOS - ÁGUA'!B8+'GRÁFICOS - ESGOTO'!B8+'GRÁFICOS - CAVALETE'!B8+'GRÁFICOS - REPOSIÇÃO'!B8) -> 1375
B17: QUALIDADE | C17: 0
B18: PRAZO | C18: 0
B19: SEGURANÇA | C19: 0
B20: ORGANIZAÇÃO | C20: 0
B23: OLHAR DIGITAL
B25: ÍNDICE DE QUALIDADE SABESP - IQS (%)
B26: Tipo de Serviço | C26: Fotos Avaliadas | D26: Fotos NC | E26: Fotos Conforme | F26: Não Conforme (%) | G26: Conforme (%)
B27: Água | C27: =D27+E27 -> 446 | D27: =COUNTIF(ÁGUA!AF:AF,"Nc") -> 59 | E27: =COUNTIF(ÁGUA!AF:AF,"c") -> 387 | F27: =IFERROR(D27/C27,"-") -> 0.132287 | G27: =IFERROR(100%-F27,"-") -> 0.867713
B28: Esgoto | C28: =D28+E28 -> 23 | D28: =COUNTIF(ESGOTO!AF:AF,"NC") -> 6 | E28: =COUNTIF(ESGOTO!AF:AF,"C") -> 17 | F28: =IFERROR(D28/C28,"-") -> 0.26086957 | G28: =IFERROR(100%-F28,"-") -> 0.73913043
B29: Cavalete | C29: =D29+E29 -> 351 | D29: =COUNTIF(CAVALETE!Z:Z,"nc") -> 23 | E29: =COUNTIF(CAVALETE!Z:Z,"C") -> 328 | F29: =IFERROR(D29/C29,"-") -> 0.065527066 | G29: =IFERROR(100%-F29,"-") -> 0.93447293
B30: Reposição | C30: =D30+E30 -> 219 | D30: =COUNTIF(REPOSIÇÃO!AF:AF,"nC") -> 113 | E30: =COUNTIF(REPOSIÇÃO!AF:AF,"c") -> 106 | F30: =IFERROR(D30/C30,"-") -> 0.51598174 | G30: =IFERROR(100%-F30,"-") -> 0.48401826
B31: Total | C31: =SUM(C27:C30) -> 1039 | D31: =SUM(D27:D30) -> 201 | E31: =SUM(E27:E30) -> 838 | F31: =IFERROR(AVERAGE(F27,F28,F29,F30),"-") -> 0.24366634 | G31: =IFERROR(AVERAGE(G27,G28,G29,G30),"-") -> 0.75633366
F32: IQS Não Conforme (%): | G32: IQS (%):
B34: TEMPO DE EXECUÇÃO
B35: Tipo de Serviço | C35: Avaliados | D35: Não Conforme | E35: Conforme | F35: Não Conforme (%) | G35: Conforme (%)
B36: Água | C36: =D36+E36 -> 446 | D36: =COUNTIF(ÁGUA!AE:AE,"Nc") -> 12 | E36: =COUNTIF(ÁGUA!AE:AE,"c") -> 434 | F36: =IFERROR(D36/C36,"-") -> 0.02690583 | G36: =IFERROR(E36/C36,"-") -> 0.97309417
B37: Esgoto | C37: =D37+E37 -> 23 | D37: =COUNTIF(ESGOTO!AE:AE,"NC") -> 3 | E37: =COUNTIF(ESGOTO!AE:AE,"C") -> 20 | F37: =IFERROR(D37/C37,"-") -> 0.13043478 | G37: =IFERROR(E37/C37,"-") -> 0.86956522
B38: Cavalete | C38: =D38+E38 -> 351 | D38: =COUNTIF(CAVALETE!Y:Y,"NC") -> 11 | E38: =COUNTIF(CAVALETE!Y:Y,"C") -> 340 | F38: =IFERROR(D38/C38,"-") -> 0.031339031 | G38: =IFERROR(E38/C38,"-") -> 0.96866097
B39: Reposição | C39: =D39+E39 -> 217 | D39: =COUNTIF(REPOSIÇÃO!AE:AE,"nC") -> 95 | E39: =COUNTIF(REPOSIÇÃO!AE:AE,"c") -> 122 | F39: =IFERROR(D39/C39,"-") -> 0.43778802 | G39: =IFERROR(E39/C39,"-") -> 0.56221198
B41: BAIXA DE MATERIAIS
B42: Tipo de Serviço | C42: Avaliados | D42: Não Conforme | E42: Conforme | F42: Não Conforme (%) | G42: Conforme (%)
B43: Água | C43: =D43+E43 -> 488 | D43: =COUNTIF(ÁGUA!AH:AH,"Nc") -> 0 | E43: =COUNTIF(ÁGUA!AH:AH,"c") -> 488 | F43: =IFERROR(D43/C43,"-") -> 0 | G43: =IFERROR(E43/C43,"-") -> 1
B44: Esgoto | C44: =D44+E44 -> 289 | D44: =COUNTIF(ESGOTO!AH:AH,"NC") -> 0 | E44: =COUNTIF(ESGOTO!AH:AH,"C") -> 289 | F44: =IFERROR(D44/C44,"-") -> 0 | G44: =IFERROR(E44/C44,"-") -> 1
B45: Cavalete | C45: =D45+E45 -> 331 | D45: =COUNTIF(CAVALETE!AB:AB,"NC") -> 0 | E45: =COUNTIF(CAVALETE!AB:AB,"C") -> 331 | F45: =IFERROR(D45/C45,"-") -> 0 | G45: =IFERROR(E45/C45,"-") -> 1
B47: ÁGUA
B49: TEMPO DE EXECUÇÃO
B50: Tipo de Serviço | C50: Avaliados | D50: Não Conforme | E50: Conforme | F50: Não Conforme (%) | G50: Conforme (%)
B51: Água | C51: =D51+E51 -> 446 | D51: =COUNTIF(ÁGUA!AE:AE,"NC") -> 12 | E51: =COUNTIF(ÁGUA!AE:AE,"C") -> 434 | F51: =IFERROR(D51/C51,"-") -> 0.02690583 | G51: =IFERROR(E51/C51,"-") -> 0.97309417
...

Sheet GRÁFICOS - GOPOÚVA
A2: POLO GOPOÚVA
A4: ACOMPANHAMENTO EM CAMPO
A5: ='DADOS - GOPOÚVA'!B4 -> Período: 01/03/2026 à 31/03/2026
A7: ÍNDICE TECNOLÓGICO
B20: O Índice Tecnológico pode ser obtido através da fórmula:
B22: IT = {[97 + 3 (Kc/100)] x Ks/100}
B24: Onde:
B25: IT = Índice Tecnológico
B26: Kc = Fator do Canteiro
B27: Ks = Média de Notas das LVs
B29: Estando acima de 80% o IT é considerado satisfatório.
A31: Nota: O Índice Tecnológico não foi calculado, pois a avaliação de Canteiro ainda não foi realizada.
A34: ACOMPANHAMENTO DE LISTAS DE VERIFICAÇÃO - LVS
B36: Índice de Conformidade (%) | E36: Quantidade de LVs
B51: TIPO DE SERVIÇO | C51: QUANTIDADE DE LVS ACIMA DE 80%
B52: Água | C52: 0
B53: Esgoto | C53: 0
B54: Reposição | C54: 0
A57: CONFORMIDADE POR CRITÉRIO DE AVALIAÇÃO
A84: OLHAR DIGITAL
A85: ='DADOS - GOPOÚVA'!B4 -> Período: 01/03/2026 à 31/03/2026
B86: ÍNDICE DE QUALIDADE SABESP - IQS (%) - MARÇO
B101: ÍNDICE DE QUALIDADE SABESP - IQS (%)
B102: Tipo de Serviço | C102: Fotos Avaliadas | D102: Fotos NC | E102: Fotos Conforme | F102: Não Conforme (%) | G102: Conforme (%)
B103: Água | C103: =D103+E103 -> 446 | D103: =COUNTIF(ÁGUA!AF:AF,"Nc") -> 59 | E103: =COUNTIF(ÁGUA!AF:AF,"c") -> 387 | F103: =IFERROR(D103/C103,"-") -> 0.132287 | G103: =IFERROR(100%-F103,"-") -> 0.867713
B104: Esgoto | C104: =D104+E104 -> 23 | D104: =COUNTIF(ESGOTO!AF:AF,"NC") -> 6 | E104: =COUNTIF(ESGOTO!AF:AF,"C") -> 17 | F104: =IFERROR(D104/C104,"-") -> 0.26086957 | G104: =IFERROR(100%-F104,"-") -> 0.73913043
B105: Cavalete | C105: =D105+E105 -> 351 | D105: =COUNTIF(CAVALETE!Z:Z,"nc") -> 23 | E105: =COUNTIF(CAVALETE!Z:Z,"C") -> 328 | F105: =IFERROR(D105/C105,"-") -> 0.065527066 | G105: =IFERROR(100%-F105,"-") -> 0.93447293
B106: Reposição | C106: =D106+E106 -> 219 | D106: =COUNTIF(REPOSIÇÃO!AF:AF,"nC") -> 113 | E106: =COUNTIF(REPOSIÇÃO!AF:AF,"c") -> 106 | F106: =IFERROR(D106/C106,"-") -> 0.51598174 | G106: =IFERROR(100%-F106,"-") -> 0.48401826
F107: IQS (%): | G107: =IFERROR(AVERAGE(G103,G104,G105,G106), "-") -> 0.75633366

Sheet GRÁFICOS - ÁGUA
A1: AMOSTRA
B3: EXECUTADOS | D3: AVALIADOS
B4: =COUNTIF(ÁGUA!A:A,"ONMG - DIV MANUT SERV OPE GOPOÚVA") -> 1013 | D4: ='DADOS - GOPOÚVA'!C27 -> 446
B5: VERIFICADOS | C5: (%) | D5: SEM EVIDÊNCIAS | E5: (%)
B6: ='DADOS - GOPOÚVA'!C27+'GRÁFICOS - ÁGUA'!D8 -> 515 | C6: =IFERROR(B6/B4,"-") -> 0.50839092 | D6: =COUNTIFS(ÁGUA!O:O,"SF",ÁGUA!Q:Q,"SF",ÁGUA!S:S,"SF",ÁGUA!U:U,"SF",ÁGUA!W:W,"SF",ÁGUA!Y:Y,"SF",ÁGUA!AC:AC,"SF",ÁGUA!AA:AA,"SF") -> 10 | E6: =IFERROR(D6/B4,"-") -> 0.0098716683
B7: NÃO VERIFICADOS | C7: (%) | D7: NÃO SINCRONIZADOS | E7: (%)
B8: =B4-B6 -> 498 | C8: =IFERROR(B8/B4,"-") -> 0.49160908 | D8: =COUNTIFS(ÁGUA!O:O,"na",ÁGUA!Q:Q,"na",ÁGUA!S:S,"na",ÁGUA!U:U,"na",ÁGUA!W:W,"na",ÁGUA!Y:Y,"na",ÁGUA!AC:AC,"na",ÁGUA!AA:AA,"na") -> 69 | E8: =IFERROR(D8/B4,"-") -> 0.068114511
A11: RESULTADO
A40: AVALIAÇÃO DE MATERIAIS
A69: CONFORMIDADE POR ETAPAS DE SERVIÇO
A103: EQUIPES - CONFORMIDADES

Sheet ÁGUA
A1: Unidade Executante | B1: Número OS | C1: Descrição TSS | D1: Família | E1: Município | F1: Endereço | G1: Número | H1: Complemento | I1: Bairro | J1: Resultado | K1: Nota Execução/Não Execução | L1: Data Início Execução | M1: Data Fim Execução | N1: EQUIPE | O1: FACHADA | P1: Observação Fachada | Q1: SINALIZAÇÃO | R1: Observação Sinalização | S1: ENCERADO | T1: Observação encerado | U1: GEOMETRIA | V1: Observação Geometria | W1: BERÇO DE AREIA | X1: Observação Berço de Areia | Y1: ESTANQUEIDADE | Z1: Observaçao Estanqueidade | AA1: .COMPACTAÇÃO | AB1: Observação Compactação | AC1: FINALIZAÇÃO | AD1: Observação Finalização | AE1: Tempo de execução | AF1: Sequência de Fotos | AG1: Observações | AH1: Baixa de materias | AI1: POLO | AJ1: MUNICÍPIO | AK1: CARACTERÍSTICA DO SERVIÇO
A2: ONMG - DIV MANUT SERV OPE GOPOÚVA | B2: 2613586110 | C2: LIGAÇÃO DE ÁGUA S/V | D2: LIGAÇÃO DE ÁGUA | E2: GUARULHOS | F2: VIELA NUNES | G2: 30 | I2: RECREIO SAO JORGE | J2: LIGAÇÃO DE ÁGUA S/V | K2: FOTOS NA REDE TAMBEM, APENAS REPOSIÇÃO DE CONCRETO, 3X1 VALA RASA 0,60 | L2: 01/04/2026 | M2: 46026.61 | N2: CICERO XAVIER DA SILVA | O2: C | Q2: C | S2: C | U2: C | W2: C | Y2: C | AA2: C | AC2: C | AE2: C | AF2: =IF(AND(O2="",Q2="",S2="",U2="",W2="",Y2="",AA2="",AC2=""),"",IF(OR(AND(O2<>"NA",O2<>"C",O2<>"NC",O2<>"SF",O2<>""),AND(Q2<>"NA",Q2<>"C",Q2<>"NC",Q2<>"SF",Q2<>""),AND(S2<>"NA",S2<>"C",S2<>"NC",S2<>"SF",S2<>""),AND(U2<>"NA",U2<>"C",U2<>"NC",U2<>"SF",U2<>""),AND(W2<>"NA",W2<>"C",W2<>"NC",W2<>"SF",W2<>""),AND(Y2<>"NA",Y2<>"C",Y2<>"NC",Y2<>"SF",Y2<>""),AND(AA2<>"NA",AA2<>"C",AA2<>"NC",AA2<>"SF",AA2<>""),AND(AC2<>"NA",AC2<>"C",AC2<>"NC",AC2<>"SF",AC2<>"")),"FALSO",IF(AND(O2="NA",Q2="NA",S2="NA",U2="NA",W2="NA",Y2="NA",AA2="NA",AC2="NA"),"NA",IF(OR(O2="NC",Q2="NC",S2="NC",U2="NC",W2="NC",Y2="NC",AA2="NC",AC2="NC",O2="SF",Q2="SF",S2="SF",U2="SF",W2="SF",Y2="SF",AA2="SF",AC2="SF"),"NC",IF(OR(O2="C",Q2="C",S2="C",U2="C",W2="C",Y2="C",AA2="C",AC2="C"),"C",""))))) -> C | AG2: =IF(AND(AE2="C",AF2="C"),"UTILIZOU O PDA CORRETAMENTE",IF(AND(AE2="C",AF2="NC"),"UTILIZOU O PDA CORRETAMENTE. NÃO HÁ FOTOS DE TODAS AS ETAPAS",IF(AND(AE2="NC",AF2="NC"),"NÃO UTILIZOU O PDA",IF(AND(AE2="NA",AF2="NA"),"NÃO AVALIADO POR FALHA DE SINCRONISMO")))) -> UTILIZOU O PDA CORRETAMENTE | AH2: C | AI2: GOPOÚVA | AJ2: =E2 -> GUARULHOS | AK2: ÁGUA | AL2: -0.0002 | AM2: {=IF(OR(O2<>"", SUMPRODUCT(($AN$2:$AN$5000=AN2)*($AL$2:$AL$5000<=AL2)) <= (COUNTIF($AN$2:$AN$5000,AN2)*0.5)), "SORTEADO", "-")} -> SORTEADO | AN2: 01/04/2026
A3: ONMG - DIV MANUT SERV OPE GOPOÚVA | B3: 2613368415 | C3: TRANSFORMAÇÃO LIG EXIST SEM APROV RAMAL | D3: LIGAÇÃO DE ÁGUA | E3: GUARULHOS | F3: RUA IRUA | G3: 419 | H3: C/1 | I3: V BARROS | J3: TRANSFORMAÇÃO LIG EXIST SEM APROV RAMAL | K3: executado rua troca de ramal . Na frente da caixa uma nao tinha rede de agua , a rede parava antes da residencia . por isso foi executado a troca do ramal alinhando o ramal em direcao a caixa uma . | L3: 01/04/2026 | M3: 46026.681 | N3: RENATO RAMOS MANCCINI | O3: C | Q3: C | S3: C | U3: C | W3: C | Y3: C | AA3: C | AC3: C | AE3: C | AF3: =IF(AND(O3="",Q3="",S3="",U3="",W3="",Y3="",AA3="",AC3=""),"",IF(OR(AND(O3<>"NA",O3<>"C",O3<>"NC",O3<>"SF",O3<>""),AND(Q3<>"NA",Q3<>"C",Q3<>"NC",Q3<>"SF",Q3<>""),AND(S3<>"NA",S3<>"C",S3<>"NC",S3<>"SF",S3<>""),AND(U3<>"NA",U3<>"C",U3<>"NC",U3<>"SF",U3<>""),AND(W3<>"NA",W3<>"C",W3<>"NC",W3<>"SF",W3<>""),AND(Y3<>"NA",Y3<>"C",Y3<>"NC",Y3<>"SF",Y3<>""),AND(AA3<>"NA",AA3<>"C",AA3<>"NC",AA3<>"SF",AA3<>""),AND(AC3<>"NA",AC3<>"C",AC3<>"NC",AC3<>"SF",AC3<>"")),"FALSO",IF(AND(O3="NA",Q3="NA",S3="NA",U3="NA",W3="NA",Y3="NA",AA3="NA",AC3="NA"),"NA",IF(OR(O3="NC",Q3="NC",S3="NC",U3="NC",W3="NC",Y3="NC",AA3="NC",AC3="NC",O3="SF",Q3="SF",S3="SF",U3="SF",W3="SF",Y3="SF",AA3="SF",AC3="SF"),"NC",IF(OR(O3="C",Q3="C",S3="C",U3="C",W3="C",Y3="C",AA3="C",AC3="C"),"C",""))))) -> C | AG3: =IF(AND(AE3="C",AF3="C"),"UTILIZOU O PDA CORRETAMENTE",IF(AND(AE3="C",AF3="NC"),"UTILIZOU O PDA CORRETAMENTE. NÃO HÁ FOTOS DE TODAS AS ETAPAS",IF(AND(AE3="NC",AF3="NC"),"NÃO UTILIZOU O PDA",IF(AND(AE3="NA",AF3="NA"),"NÃO AVALIADO POR FALHA DE SINCRONISMO")))) -> UTILIZOU O PDA CORRETAMENTE | AH3: c | AI3: GOPOÚVA | AJ3: =E3 -> GUARULHOS | AK3: ÁGUA | AL3: -0.0004 | AM3: {=IF(OR(O3<>"", SUMPRODUCT(($AN$2:$AN$5000=AN3)*($AL$2:$AL$5000<=AL3)) <= (COUNTIF($AN$2:$AN$5000,AN3)*0.5)), "SORTEADO", "-")} -> SORTEADO | AN3: 01/04/2026
A4: ONMG - DIV MANUT SERV OPE GOPOÚVA | B4: 2613368455 | C4: TRANSFORMAÇÃO LIG NOVA SEM APROV RAMAL | D4: LIGAÇÃO DE ÁGUA | E4: GUARULHOS | F4: RUA IRUA | G4: 419 | H4: C/2 | I4: V BARROS | J4: TRANSFORMAÇÃO LIG NOVA SEM APROV RAMAL | K4: 2613368415 | L4: 01/04/2026 | M4: 46026.685 | N4: RENATO RAMOS MANCCINI | O4: C | Q4: C | S4: C | U4: C | W4: C | Y4: C | AA4: C | AC4: C | AE4: C | AF4: =IF(AND(O4="",Q4="",S4="",U4="",W4="",Y4="",AA4="",AC4=""),"",IF(OR(AND(O4<>"NA",O4<>"C",O4<>"NC",O4<>"SF",O4<>""),AND(Q4<>"NA",Q4<>"C",Q4<>"NC",Q4<>"SF",Q4<>""),AND(S4<>"NA",S4<>"C",S4<>"NC",S4<>"SF",S4<>""),AND(U4<>"NA",U4<>"C",U4<>"NC",U4<>"SF",U4<>""),AND(W4<>"NA",W4<>"C",W4<>"NC",W4<>"SF",W4<>""),AND(Y4<>"NA",Y4<>"C",Y4<>"NC",Y4<>"SF",Y4<>""),AND(AA4<>"NA",AA4<>"C",AA4<>"NC",AA4<>"SF",AA4<>""),AND(AC4<>"NA",AC4<>"C",AC4<>"NC",AC4<>"SF",AC4<>"")),"FALSO",IF(AND(O4="NA",Q4="NA",S4="NA",U4="NA",W4="NA",Y4="NA",AA4="NA",AC4="NA"),"NA",IF(OR(O4="NC",Q4="NC",S4="NC",U4="NC",W4="NC",Y4="NC",AA4="NC",AC4="NC",O4="SF",Q4="SF",S4="SF",U4="SF",W4="SF",Y4="SF",AA4="SF",AC4="SF"),"NC",IF(OR(O4="C",Q4="C",S4="C",U4="C",W4="C",Y4="C",AA4="C",AC4="C"),"C",""))))) -> C | AG4: =IF(AND(AE4="C",AF4="C"),"UTILIZOU O PDA CORRETAMENTE",IF(AND(AE4="C",AF4="NC"),"UTILIZOU O PDA CORRETAMENTE. NÃO HÁ FOTOS DE TODAS AS ETAPAS",IF(AND(AE4="NC",AF4="NC"),"NÃO UTILIZOU O PDA",IF(AND(AE4="NA",AF4="NA"),"NÃO AVALIADO POR FALHA DE SINCRONISMO")))) -> UTILIZOU O PDA CORRETAMENTE | AH4: C | AI4: GOPOÚVA | AJ4: =E4 -> GUARULHOS | AK4: ÁGUA | AL4: 0.188236 | AM4: {=IF(OR(O4<>"", SUMPRODUCT(($AN$2:$AN$5000=AN4)*($AL$2:$AL$5000<=AL4)) <= (COUNTIF($AN$2:$AN$5000,AN4)*0.5)), "SORTEADO", "-")} -> SORTEADO | AN4: 01/04/2026
A5: ONMG - DIV MANUT SERV OPE GOPOÚVA | B5: 2613597228 | C5: LIGAÇÃO DE ÁGUA S/V | D5: LIGAÇÃO DE ÁGUA | E5: GUARULHOS | F5: RUA SAO SEBASTIAO DA BOA VISTA | G5: 12 | I5: JD MARILENA | J5: LIGAÇÃO DE ÁGUA S/V | L5: 01/04/2026 | M5: 46026.544 | N5: SANDRO DE FREITAS GALINDO | O5: C | Q5: C | S5: C | U5: C | W5: C | Y5: C | AA5: C | AC5: C | AE5: C | AF5: =IF(AND(O5="",Q5="",S5="",U5="",W5="",Y5="",AA5="",AC5=""),"",IF(OR(AND(O5<>"NA",O5<>"C",O5<>"NC",O5<>"SF",O5<>""),AND(Q5<>"NA",Q5<>"C",Q5<>"NC",Q5<>"SF",Q5<>""),AND(S5<>"NA",S5<>"C",S5<>"NC",S5<>"SF",S5<>""),AND(U5<>"NA",U5<>"C",U5<>"NC",U5<>"SF",U5<>""),AND(W5<>"NA",W5<>"C",W5<>"NC",W5<>"SF",W5<>""),AND(Y5<>"NA",Y5<>"C",Y5<>"NC",Y5<>"SF",Y5<>""),AND(AA5<>"NA",AA5<>"C",AA5<>"NC",AA5<>"SF",AA5<>""),AND(AC5<>"NA",AC5<>"C",AC5<>"NC",AC5<>"SF",AC5<>"")),"FALSO",IF(AND(O5="NA",Q5="NA",S5="NA",U5="NA",W5="NA",Y5="NA",AA5="NA",AC5="NA"),"NA",IF(OR(O5="NC",Q5="NC",S5="NC",U5="NC",W5="NC",Y5="NC",AA5="NC",AC5="NC",O5="SF",Q5="SF",S5="SF",U5="SF",W5="SF",Y5="SF",AA5="SF",AC5="SF"),"NC",IF(OR(O5="C",Q5="C",S5="C",U5="C",W5="C",Y5="C",AA5="C",AC5="C"),"C",""))))) -> C | AG5: =IF(AND(AE5="C",AF5="C"),"UTILIZOU O PDA CORRETAMENTE",IF(AND(AE5="C",AF5="NC"),"UTILIZOU O PDA CORRETAMENTE. NÃO HÁ FOTOS DE TODAS AS ETAPAS",IF(AND(AE5="NC",AF5="NC"),"NÃO UTILIZOU O PDA",IF(AND(AE5="NA",AF5="NA"),"NÃO AVALIADO POR FALHA DE SINCRONISMO")))) -> UTILIZOU O PDA CORRETAMENTE | AH5: C | AI5: GOPOÚVA | AJ5: =E5 -> GUARULHOS | AK5: ÁGUA | AL5: -0.0008 | AM5: {=IF(OR(O5<>"", SUMPRODUCT(($AN$2:$AN$5000=AN5)*($AL$2:$AL$5000<=AL5)) <= (COUNTIF($AN$2:$AN$5000,AN5)*0.5)), "SORTEADO", "-")} -> SORTEADO | AN5: 01/04/2026
A6: ONMG - DIV MANUT SERV OPE GOPOÚVA | B6: 2613572128 | C6: INCLUIR LIG DE ÁGUA EM CAV MÚLTIPLO S/V | D6: LIGAÇÃO DE ÁGUA | E6: GUARULHOS | F6: RUA SANTO ANTONIO DA POSSE | G6: 147 | H6: C/3 | I6: JD BEIRUTE | J6: INCLUSÃO DE LIG DE AGUA EM CAV MULT S/V | K6: fotos na OS principal | L6: 01/04/2026 | M6: 46026.627 | N6: SANDRO DE FREITAS GALINDO | O6: C | Q6: C | S6: C | U6: C | W6: C | Y6: NA | AA6: C | AC6: C | AE6: C | AF6: =IF(AND(O6="",Q6="",S6="",U6="",W6="",Y6="",AA6="",AC6=""),"",IF(OR(AND(O6<>"NA",O6<>"C",O6<>"NC",O6<>"SF",O6<>""),AND(Q6<>"NA",Q6<>"C",Q6<>"NC",Q6<>"SF",Q6<>""),AND(S6<>"NA",S6<>"C",S6<>"NC",S6<>"SF",S6<>""),AND(U6<>"NA",U6<>"C",U6<>"NC",U6<>"SF",U6<>""),AND(W6<>"NA",W6<>"C",W6<>"NC",W6<>"SF",W6<>""),AND(Y6<>"NA",Y6<>"C",Y6<>"NC",Y6<>"SF",Y6<>""),AND(AA6<>"NA",AA6<>"C",AA6<>"NC",AA6<>"SF",AA6<>""),AND(AC6<>"NA",AC6<>"C",AC6<>"NC",AC6<>"SF",AC6<>"")),"FALSO",IF(AND(O6="NA",Q6="NA",S6="NA",U6="NA",W6="NA",Y6="NA",AA6="NA",AC6="NA"),"NA",IF(OR(O6="NC",Q6="NC",S6="NC",U6="NC",W6="NC",Y6="NC",AA6="NC",AC6="NC",O6="SF",Q6="SF",S6="SF",U6="SF",W6="SF",Y6="SF",AA6="SF",AC6="SF"),"NC",IF(OR(O6="C",Q6="C",S6="C",U6="C",W6="C",Y6="C",AA6="C",AC6="C"),"C",""))))) -> C | AG6: =IF(AND(AE6="C",AF6="C"),"UTILIZOU O PDA CORRETAMENTE",IF(AND(AE6="C",AF6="NC"),"UTILIZOU O PDA CORRETAMENTE. NÃO HÁ FOTOS DE TODAS AS ETAPAS",IF(AND(AE6="NC",AF6="NC"),"NÃO UTILIZOU O PDA",IF(AND(AE6="NA",AF6="NA"),"NÃO AVALIADO POR FALHA DE SINCRONISMO")))) -> UTILIZOU O PDA CORRETAMENTE | AH6: C | AI6: GOPOÚVA | AJ6: =E6 -> GUARULHOS | AK6: ÁGUA | AL6: -0.001 | AM6: {=IF(OR(O6<>"", SUMPRODUCT(($AN$2:$AN$5000=AN6)*($AL$2:$AL$5000<=AL6)) <= (COUNTIF($AN$2:$AN$5000,AN6)*0.5)), "SORTEADO", "-")} -> SORTEADO | AN6: 01/04/2026
A7: ONMG - DIV MANUT SERV OPE GOPOÚVA | B7: 2613596117 | C7: TRANSFORMAÇÃO LIG EXIST COM APROV RAMAL | D7: LIGAÇÃO DE ÁGUA | E7: GUARULHOS | F7: AVENIDA NOVA TABOAO | G7: 293 | H7: ANT200 C/1 | I7: JD NOVA TABOAO | J7: TRANSFORMAÇÃO LIG EXIST COM APROV RAMAL | L7: 01/04/2026 | M7: 46026.703 | N7: SANDRO DE FREITAS GALINDO | O7: C | Q7: C | S7: C | U7: C | W7: C | Y7: NA | AA7: C | AC7: C | AE7: C | AF7: =IF(AND(O7="",Q7="",S7="",U7="",W7="",Y7="",AA7="",AC7=""),"",IF(OR(AND(O7<>"NA",O7<>"C",O7<>"NC",O7<>"SF",O7<>""),AND(Q7<>"NA",Q7<>"C",Q7<>"NC",Q7<>"SF",Q7<>""),AND(S7<>"NA",S7<>"C",S7<>"NC",S7<>"SF",S7<>""),AND(U7<>"NA",U7<>"C",U7<>"NC",U7<>"SF",U7<>""),AND(W7<>"NA",W7<>"C",W7<>"NC",W7<>"SF",W7<>""),AND(Y7<>"NA",Y7<>"C",Y7<>"NC",Y7<>"SF",Y7<>""),AND(AA7<>"NA",AA7<>"C",AA7<>"NC",AA7<>"SF",AA7<>""),AND(AC7<>"NA",AC7<>"C",AC7<>"NC",AC7<>"SF",AC7<>"")),"FALSO",IF(AND(O7="NA",Q7="NA",S7="NA",U7="NA",W7="NA",Y7="NA",AA7="NA",AC7="NA"),"NA",IF(OR(O7="NC",Q7="NC",S7="NC",U7="NC",W7="NC",Y7="NC",AA7="NC",AC7="NC",O7="SF",Q7="SF",S7="SF",U7="SF",W7="SF",Y7="SF",AA7="SF",AC7="SF"),"NC",IF(OR(O7="C",Q7="C",S7="C",U7="C",W7="C",Y7="C",AA7="C",AC7="C"),"C",""))))) -> C | AG7: =IF(AND(AE7="C",AF7="C"),"UTILIZOU O PDA CORRETAMENTE",IF(AND(AE7="C",AF7="NC"),"UTILIZOU O PDA CORRETAMENTE. NÃO HÁ FOTOS DE TODAS AS ETAPAS",IF(AND(AE7="NC",AF7="NC"),"NÃO UTILIZOU O PDA",IF(AND(AE7="NA",AF7="NA"),"NÃO AVALIADO POR FALHA DE SINCRONISMO")))) -> UTILIZOU O PDA CORRETAMENTE | AH7: C | AI7: GOPOÚVA | AJ7: =E7 -> GUARULHOS | AK7: ÁGUA | AL7: -0.0012 | AM7: {=IF(OR(O7<>"", SUMPRODUCT(($AN$2:$AN$5000=AN7)*($AL$2:$AL$5000<=AL7)) <= (COUNTIF($AN$2:$AN$5000,AN7)*0.5)), "SORTEADO", "-")} -> SORTEADO | AN7: 01/04/2026
A8: ONMG - DIV MANUT SERV OPE GOPOÚVA | B8: 2613698364 | C8: VAZAMENTO DE ÁGUA NÃO VISÍVEL REDE | D8: VAZAMENTO DE ÁGUA | E8: GUARULHOS | F8: RUA DO ROSARIO | G8: 313 | I8: V CAMARGO | J8: REPARO DE REDE DE AGUA NÃO VISIVEL | K8: SEM FOTOS DEVIDO ERRO DE PLANEJAMENTO | L8: 01/04/2026 | M8: 46026.604 | N8: CLAUDIO JOSE SILVA SANTOS | AF8: =IF(AND(O8="",Q8="",S8="",U8="",W8="",Y8="",AA8="",AC8=""),"",IF(OR(AND(O8<>"NA",O8<>"C",O8<>"NC",O8<>"SF",O8<>""),AND(Q8<>"NA",Q8<>"C",Q8<>"NC",Q8<>"SF",Q8<>""),AND(S8<>"NA",S8<>"C",S8<>"NC",S8<>"SF",S8<>""),AND(U8<>"NA",U8<>"C",U8<>"NC",U8<>"SF",U8<>""),AND(W8<>"NA",W8<>"C",W8<>"NC",W8<>"SF",W8<>""),AND(Y8<>"NA",Y8<>"C",Y8<>"NC",Y8<>"SF",Y8<>""),AND(AA8<>"NA",AA8<>"C",AA8<>"NC",AA8<>"SF",AA8<>""),AND(AC8<>"NA",AC8<>"C",AC8<>"NC",AC8<>"SF",AC8<>"")),"FALSO",IF(AND(O8="NA",Q8="NA",S8="NA",U8="NA",W8="NA",Y8="NA",AA8="NA",AC8="NA"),"NA",IF(OR(O8="NC",Q8="NC",S8="NC",U8="NC",W8="NC",Y8="NC",AA8="NC",AC8="NC",O8="SF",Q8="SF",S8="SF",U8="SF",W8="SF",Y8="SF",AA8="SF",AC8="SF"),"NC",IF(OR(O8="C",Q8="C",S8="C",U8="C",W8="C",Y8="C",AA8="C",AC8="C"),"C",""))))) | AG8: =IF(AND(AE8="C",AF8="C"),"UTILIZOU O PDA CORRETAMENTE",IF(AND(AE8="C",AF8="NC"),"UTILIZOU O PDA CORRETAMENTE. NÃO HÁ FOTOS DE TODAS AS ETAPAS",IF(AND(AE8="NC",AF8="NC"),"NÃO UTILIZOU O PDA",IF(AND(AE8="NA",AF8="NA"),"NÃO AVALIADO POR FALHA DE SINCRONISMO")))) -> FALSE | AI8: GOPOÚVA | AJ8: =E8 -> GUARULHOS | AK8: ÁGUA | AL8: 0.71543241 | AM8: {=IF(OR(O8<>"", SUMPRODUCT(($AN$2:$AN$5000=AN8)*($AL$2:$AL$5000<=AL8)) <= (COUNTIF($AN$2:$AN$5000,AN8)*0.5)), "SORTEADO", "-")} -> - | AN8: 01/04/2026
A9: ONMG - DIV MANUT SERV OPE GOPOÚVA | B9: 2613700387 | C9: LIGAÇÃO DE ÁGUA EM CAVALETE MULTIPLO | D9: LIGAÇÃO DE ÁGUA | E9: GUARULHOS | F9: RUA SAO JOAO | G9: 11 | H9: C/2 | I9: JD IRENE | J9: LIGAÇÃO DE AGUA EM CAVALETE MÚLTIPLO | K9: 2613700313 | L9: 01/04/2026 | M9: 46026.706 | N9: RENATO RAMOS MANCCINI | O9: C | Q9: C | S9: C | U9: C | W9: C | Y9: C | AA9: C | AC9: C | AE9: C | AF9: =IF(AND(O9="",Q9="",S9="",U9="",W9="",Y9="",AA9="",AC9=""),"",IF(OR(AND(O9<>"NA",O9<>"C",O9<>"NC",O9<>"SF",O9<>""),AND(Q9<>"NA",Q9<>"C",Q9<>"NC",Q9<>"SF",Q9<>""),AND(S9<>"NA",S9<>"C",S9<>"NC",S9<>"SF",S9<>""),AND(U9<>"NA",U9<>"C",U9<>"NC",U9<>"SF",U9<>""),AND(W9<>"NA",W9<>"C",W9<>"NC",W9<>"SF",W9<>""),AND(Y9<>"NA",Y9<>"C",Y9<>"NC",Y9<>"SF",Y9<>""),AND(AA9<>"NA",AA9<>"C",AA9<>"NC",AA9<>"SF",AA9<>""),AND(AC9<>"NA",AC9<>"C",AC9<>"NC",AC9<>"SF",AC9<>"")),"FALSO",IF(AND(O9="NA",Q9="NA",S9="NA",U9="NA",W9="NA",Y9="NA",AA9="NA",AC9="NA"),"NA",IF(OR(O9="NC",Q9="NC",S9="NC",U9="NC",W9="NC",Y9="NC",AA9="NC",AC9="NC",O9="SF",Q9="SF",S9="SF",U9="SF",W9="SF",Y9="SF",AA9="SF",AC9="SF"),"NC",IF(OR(O9="C",Q9="C",S9="C",U9="C",W9="C",Y9="C",AA9="C",AC9="C"),"C",""))))) -> C | AG9: =IF(AND(AE9="C",AF9="C"),"UTILIZOU O PDA CORRETAMENTE",IF(AND(AE9="C",AF9="NC"),"UTILIZOU O PDA CORRETAMENTE. NÃO HÁ FOTOS DE TODAS AS ETAPAS",IF(AND(AE9="NC",AF9="NC"),"NÃO UTILIZOU O PDA",IF(AND(AE9="NA",AF9="NA"),"NÃO AVALIADO POR FALHA DE SINCRONISMO")))) -> UTILIZOU O PDA CORRETAMENTE | AH9: C | AI9: GOPOÚVA | AJ9: =E9 -> GUARULHOS | AK9: ÁGUA | AL9: -0.0016 | AM9: {=IF(OR(O9<>"", SUMPRODUCT(($AN$2:$AN$5000=AN9)*($AL$2:$AL$5000<=AL9)) <= (COUNTIF($AN$2:$AN$5000,AN9)*0.5)), "SORTEADO", "-")} -> SORTEADO | AN9: 01/04/2026
A10: ONMG - DIV MANUT SERV OPE GOPOÚVA | B10: 2613700313 | C10: LIGAÇÃO DE ÁGUA EM CAVALETE MULTIPLO | D10: LIGAÇÃO DE ÁGUA | E10: GUARULHOS | F10: RUA SAO JOAO | G10: 11 | H10: C/1 | I10: JD IRENE | J10: LIGAÇÃO DE AGUA EM CAVALETE MÚLTIPLO | K10: rua estreita | L10: 01/04/2026 | M10: 46026.706 | N10: RENATO RAMOS MANCCINI | O10: C | Q10: C | S10: C | U10: C | W10: C | Y10: C | AA10: C | AC10: C | AE10: C | AF10: =IF(AND(O10="",Q10="",S10="",U10="",W10="",Y10="",AA10="",AC10=""),"",IF(OR(AND(O10<>"NA",O10<>"C",O10<>"NC",O10<>"SF",O10<>""),AND(Q10<>"NA",Q10<>"C",Q10<>"NC",Q10<>"SF",Q10<>""),AND(S10<>"NA",S10<>"C",S10<>"NC",S10<>"SF",S10<>""),AND(U10<>"NA",U10<>"C",U10<>"NC",U10<>"SF",U10<>""),AND(W10<>"NA",W10<>"C",W10<>"NC",W10<>"SF",W10<>""),AND(Y10<>"NA",Y10<>"C",Y10<>"NC",Y10<>"SF",Y10<>""),AND(AA10<>"NA",AA10<>"C",AA10<>"NC",AA10<>"SF",AA10<>""),AND(AC10<>"NA",AC10<>"C",AC10<>"NC",AC10<>"SF",AC10<>"")),"FALSO",IF(AND(O10="NA",Q10="NA",S10="NA",U10="NA",W10="NA",Y10="NA",AA10="NA",AC10="NA"),"NA",IF(OR(O10="NC",Q10="NC",S10="NC",U10="NC",W10="NC",Y10="NC",AA10="NC",AC10="NC",O10="SF",Q10="SF",S10="SF",U10="SF",W10="SF",Y10="SF",AA10="SF",AC10="SF"),"NC",IF(OR(O10="C",Q10="C",S10="C",U10="C",W10="C",Y10="C",AA10="C",AC10="C"),"C",""))))) -> C | AG10: =IF(AND(AE10="C",AF10="C"),"UTILIZOU O PDA CORRETAMENTE",IF(AND(AE10="C",AF10="NC"),"UTILIZOU O PDA CORRETAMENTE. NÃO HÁ FOTOS DE TODAS AS ETAPAS",IF(AND(AE10="NC",AF10="NC"),"NÃO UTILIZOU O PDA",IF(AND(AE10="NA",AF10="NA"),"NÃO AVALIADO POR FALHA DE SINCRONISMO")))) -> UTILIZOU O PDA CORRETAMENTE | AH10: C | AI10: GOPOÚVA | AJ10: =E10 -> GUARULHOS | AK10: ÁGUA | AL10: -0.0018 | AM10: {=IF(OR(O10<>"", SUMPRODUCT(($AN$2:$AN$5000=AN10)*($AL$2:$AL$5000<=AL10)) <= (COUNTIF($AN$2:$AN$5000,AN10)*0.5)), "SORTEADO", "-")} -> SORTEADO | AN10: 01/04/2026
A11: ONMG - DIV MANUT SERV OPE GOPOÚVA | B11: 2613726127 | C11: VAZAMENTO DE ÁGUA NÃO VISÍVEL REDE | D11: VAZAMENTO DE ÁGUA | E11: GUARULHOS | F11: RUA GUARACY | G11: 417 | H11: CASA 02 | I11: JD PAULISTA | J11: REPARO DE REDE DE AGUA NÃO VISIVEL | L11: 01/04/2026 | M11: 46026.412 | N11: ADEMAR JOSE VIANA | AF11: =IF(AND(O11="",Q11="",S11="",U11="",W11="",Y11="",AA11="",AC11=""),"",IF(OR(AND(O11<>"NA",O11<>"C",O11<>"NC",O11<>"SF",O11<>""),AND(Q11<>"NA",Q11<>"C",Q11<>"NC",Q11<>"SF",Q11<>""),AND(S11<>"NA",S11<>"C",S11<>"NC",S11<>"SF",S11<>""),AND(U11<>"NA",U11<>"C",U11<>"NC",U11<>"SF",U11<>""),AND(W11<>"NA",W11<>"C",W11<>"NC",W11<>"SF",W11<>""),AND(Y11<>"NA",Y11<>"C",Y11<>"NC",Y11<>"SF",Y11<>""),AND(AA11<>"NA",AA11<>"C",AA11<>"NC",AA11<>"SF",AA11<>""),AND(AC11<>"NA",AC11<>"C",AC11<>"NC",AC11<>"SF",AC11<>"")),"FALSO",IF(AND(O11="NA",Q11="NA",S11="NA",U11="NA",W11="NA",Y11="NA",AA11="NA",AC11="NA"),"NA",IF(OR(O11="NC",Q11="NC",S11="NC",U11="NC",W11="NC",Y11="NC",AA11="NC",AC11="NC",O11="SF",Q11="SF",S11="SF",U11="SF",W11="SF",Y11="SF",AA11="SF",AC11="SF"),"NC",IF(OR(O11="C",Q11="C",S11="C",U11="C",W11="C",Y11="C",AA11="C",AC11="C"),"C",""))))) | AG11: =IF(AND(AE11="C",AF11="C"),"UTILIZOU O PDA CORRETAMENTE",IF(AND(AE11="C",AF11="NC"),"UTILIZOU O PDA CORRETAMENTE. NÃO HÁ FOTOS DE TODAS AS ETAPAS",IF(AND(AE11="NC",AF11="NC"),"NÃO UTILIZOU O PDA",IF(AND(AE11="NA",AF11="NA"),"NÃO AVALIADO POR FALHA DE SINCRONISMO")))) -> FALSE | AI11: GOPOÚVA | AJ11: =E11 -> GUARULHOS | AK11: ÁGUA | AL11: 0.96952517 | AM11: {=IF(OR(O11<>"", SUMPRODUCT(($AN$2:$AN$5000=AN11)*($AL$2:$AL$5000<=AL11)) <= (COUNTIF($AN$2:$AN$5000,AN11)*0.5)), "SORTEADO", "-")} -> - | AN11: 01/04/2026
A12: ONMG - DIV MANUT SERV OPE GOPOÚVA | B12: 2613740920 | C12: VAZAMENTO DE ÁGUA NÃO VISÍVEL REDE | D12: VAZAMENTO DE ÁGUA | E12: GUARULHOS | F12: AVENIDA EMILIO RIBAS | G12: 432 | H12: ANT. 420 | I12: V TIJUCO | J12: REPARO DE REDE DE AGUA NÃO VISIVEL | L12: 01/04/2026 | M12: 46026.668 | N12: JOSE LIMA SILVA | AF12: =IF(AND(O12="",Q12="",S12="",U12="",W12="",Y12="",AA12="",AC12=""),"",IF(OR(AND(O12<>"NA",O12<>"C",O12<>"NC",O12<>"SF",O12<>""),AND(Q12<>"NA",Q12<>"C",Q12<>"NC",Q12<>"SF",Q12<>""),AND(S12<>"NA",S12<>"C",S12<>"NC",S12<>"SF",S12<>""),AND(U12<>"NA",U12<>"C",U12<>"NC",U12<>"SF",U12<>""),AND(W12<>"NA",W12<>"C",W12<>"NC",W12<>"SF",W12<>""),AND(Y12<>"NA",Y12<>"C",Y12<>"NC",Y12<>"SF",Y12<>""),AND(AA12<>"NA",AA12<>"C",AA12<>"NC",AA12<>"SF",AA12<>""),AND(AC12<>"NA",AC12<>"C",AC12<>"NC",AC12<>"SF",AC12<>"")),"FALSO",IF(AND(O12="NA",Q12="NA",S12="NA",U12="NA",W12="NA",Y12="NA",AA12="NA",AC12="NA"),"NA",IF(OR(O12="NC",Q12="NC",S12="NC",U12="NC",W12="NC",Y12="NC",AA12="NC",AC12="NC",O12="SF",Q12="SF",S12="SF",U12="SF",W12="SF",Y12="SF",AA12="SF",AC12="SF"),"NC",IF(OR(O12="C",Q12="C",S12="C",U12="C",W12="C",Y12="C",AA12="C",AC12="C"),"C",""))))) | AG12: =IF(AND(AE12="C",AF12="C"),"UTILIZOU O PDA CORRETAMENTE",IF(AND(AE12="C",AF12="NC"),"UTILIZOU O PDA CORRETAMENTE. NÃO HÁ FOTOS DE TODAS AS ETAPAS",IF(AND(AE12="NC",AF12="NC"),"NÃO UTILIZOU O PDA",IF(AND(AE12="NA",AF12="NA"),"NÃO AVALIADO POR FALHA DE SINCRONISMO")))) -> FALSE | AI12: GOPOÚVA | AJ12: =E12 -> GUARULHOS | AK12: ÁGUA | AL12: 0.45180346 | AM12: {=IF(OR(O12<>"", SUMPRODUCT(($AN$2:$AN$5000=AN12)*($AL$2:$AL$5000<=AL12)) <= (COUNTIF($AN$2:$AN$5000,AN12)*0.5)), "SORTEADO", "-")} -> - | AN12: 01/04/2026
A13: ONMG - DIV MANUT SERV OPE GOPOÚVA | B13: 2613726216 | C13: VAZAMENTO DE ÁGUA NÃO VISÍVEL REDE | D13: VAZAMENTO DE ÁGUA | E13: GUARULHOS | F13: RUA TERRA BOA | G13: 158 | I13: CABUCU | J13: REPARO DE REDE DE AGUA NÃO VISIVEL | L13: 01/04/2026 | M13: 46026.596 | N13: ADIMILSON SOUZA OLIVEIRA | AF13: =IF(AND(O13="",Q13="",S13="",U13="",W13="",Y13="",AA13="",AC13=""),"",IF(OR(AND(O13<>"NA",O13<>"C",O13<>"NC",O13<>"SF",O13<>""),AND(Q13<>"NA",Q13<>"C",Q13<>"NC",Q13<>"SF",Q13<>""),AND(S13<>"NA",S13<>"C",S13<>"NC",S13<>"SF",S13<>""),AND(U13<>"NA",U13<>"C",U13<>"NC",U13<>"SF",U13<>""),AND(W13<>"NA",W13<>"C",W13<>"NC",W13<>"SF",W13<>""),AND(Y13<>"NA",Y13<>"C",Y13<>"NC",Y13<>"SF",Y13<>""),AND(AA13<>"NA",AA13<>"C",AA13<>"NC",AA13<>"SF",AA13<>""),AND(AC13<>"NA",AC13<>"C",AC13<>"NC",AC13<>"SF",AC13<>"")),"FALSO",IF(AND(O13="NA",Q13="NA",S13="NA",U13="NA",W13="NA",Y13="NA",AA13="NA",AC13="NA"),"NA",IF(OR(O13="NC",Q13="NC",S13="NC",U13="NC",W13="NC",Y13="NC",AA13="NC",AC13="NC",O13="SF",Q13="SF",S13="SF",U13="SF",W13="SF",Y13="SF",AA13="SF",AC13="SF"),"NC",IF(OR(O13="C",Q13="C",S13="C",U13="C",W13="C",Y13="C",AA13="C",AC13="C"),"C",""))))) | AG13: =IF(AND(AE13="C",AF13="C"),"UTILIZOU O PDA CORRETAMENTE",IF(AND(AE13="C",AF13="NC"),"UTILIZOU O PDA CORRETAMENTE. NÃO HÁ FOTOS DE TODAS AS ETAPAS",IF(AND(AE13="NC",AF13="NC"),"NÃO UTILIZOU O PDA",IF(AND(AE13="NA",AF13="NA"),"NÃO AVALIADO POR FALHA DE SINCRONISMO")))) -> FALSE | AI13: GOPOÚVA | AJ13: =E13 -> GUARULHOS | AK13: ÁGUA | AL13: 0.49334933 | AM13: {=IF(OR(O13<>"", SUMPRODUCT(($AN$2:$AN$5000=AN13)*($AL$2:$AL$5000<=AL13)) <= (COUNTIF($AN$2:$AN$5000,AN13)*0.5)), "SORTEADO", "-")} -> - | AN13: 01/04/2026
A14: ONMG - DIV MANUT SERV OPE GOPOÚVA | B14: 2613767287 | C14: TROCAR RAMAL DE ÁGUA PREVENTIVA | D14: RAMAL DE ÁGUA | E14: GUARULHOS | F14: RUA CORREGO DO BOM JESUS | G14: 223 | H14: CASA 1 | I14: TABOAO | J14: TROCA DE RAMAL DE AGUA PREVENTIVA | K14: nao foi possivel sequencia fotos correto devido estreitamento de pistar | L14: 01/04/2026 | M14: 46026.616 | N14: EDSON COUTINHO DOS SANTOS | AF14: =IF(AND(O14="",Q14="",S14="",U14="",W14="",Y14="",AA14="",AC14=""),"",IF(OR(AND(O14<>"NA",O14<>"C",O14<>"NC",O14<>"SF",O14<>""),AND(Q14<>"NA",Q14<>"C",Q14<>"NC",Q14<>"SF",Q14<>""),AND(S14<>"NA",S14<>"C",S14<>"NC",S14<>"SF",S14<>""),AND(U14<>"NA",U14<>"C",U14<>"NC",U14<>"SF",U14<>""),AND(W14<>"NA",W14<>"C",W14<>"NC",W14<>"SF",W14<>""),AND(Y14<>"NA",Y14<>"C",Y14<>"NC",Y14<>"SF",Y14<>""),AND(AA14<>"NA",AA14<>"C",AA14<>"NC",AA14<>"SF",AA14<>""),AND(AC14<>"NA",AC14<>"C",AC14<>"NC",AC14<>"SF",AC14<>"")),"FALSO",IF(AND(O14="NA",Q14="NA",S14="NA",U14="NA",W14="NA",Y14="NA",AA14="NA",AC14="NA"),"NA",IF(OR(O14="NC",Q14="NC",S14="NC",U14="NC",W14="NC",Y14="NC",AA14="NC",AC14="NC",O14="SF",Q14="SF",S14="SF",U14="SF",W14="SF",Y14="SF",AA14="SF",AC14="SF"),"NC",IF(OR(O14="C",Q14="C",S14="C",U14="C",W14="C",Y14="C",AA14="C",AC14="C"),"C",""))))) | AG14: =IF(AND(AE14="C",AF14="C"),"UTILIZOU O PDA CORRETAMENTE",IF(AND(AE14="C",AF14="NC"),"UTILIZOU O PDA CORRETAMENTE. NÃO HÁ FOTOS DE TODAS AS ETAPAS",IF(AND(AE14="NC",AF14="NC"),"NÃO UTILIZOU O PDA",IF(AND(AE14="NA",AF14="NA"),"NÃO AVALIADO POR FALHA DE SINCRONISMO")))) -> FALSE | AI14: GOPOÚVA | AJ14: =E14 -> GUARULHOS | AK14: ÁGUA | AL14: 0.56816256 | AM14: {=IF(OR(O14<>"", SUMPRODUCT(($AN$2:$AN$5000=AN14)*($AL$2:$AL$5000<=AL14)) <= (COUNTIF($AN$2:$AN$5000,AN14)*0.5)), "SORTEADO", "-")} -> - | AN14: 01/04/2026
A15: ONMG - DIV MANUT SERV OPE GOPOÚVA | B15: 2613767096 | C15: VAZAMENTO DE ÁGUA NÃO VISÍVEL REDE | D15: VAZAMENTO DE ÁGUA | E15: GUARULHOS | F15: RUA METEORITO | G15: 5 | H15: CASA 03 | I15: PQ PRIMAVERA | J15: SONDAGEM DE REDE DE AGUA NÃO VISIVEL | K15: nao foi possivel tira sequencia de fotos correto porem estreitamento de pistar | L15: 01/04/2026 | M15: 46026.674 | N15: EDSON COUTINHO DOS SANTOS | AF15: =IF(AND(O15="",Q15="",S15="",U15="",W15="",Y15="",AA15="",AC15=""),"",IF(OR(AND(O15<>"NA",O15<>"C",O15<>"NC",O15<>"SF",O15<>""),AND(Q15<>"NA",Q15<>"C",Q15<>"NC",Q15<>"SF",Q15<>""),AND(S15<>"NA",S15<>"C",S15<>"NC",S15<>"SF",S15<>""),AND(U15<>"NA",U15<>"C",U15<>"NC",U15<>"SF",U15<>""),AND(W15<>"NA",W15<>"C",W15<>"NC",W15<>"SF",W15<>""),AND(Y15<>"NA",Y15<>"C",Y15<>"NC",Y15<>"SF",Y15<>""),AND(AA15<>"NA",AA15<>"C",AA15<>"NC",AA15<>"SF",AA15<>""),AND(AC15<>"NA",AC15<>"C",AC15<>"NC",AC15<>"SF",AC15<>"")),"FALSO",IF(AND(O15="NA",Q15="NA",S15="NA",U15="NA",W15="NA",Y15="NA",AA15="NA",AC15="NA"),"NA",IF(OR(O15="NC",Q15="NC",S15="NC",U15="NC",W15="NC",Y15="NC",AA15="NC",AC15="NC",O15="SF",Q15="SF",S15="SF",U15="SF",W15="SF",Y15="SF",AA15="SF",AC15="SF"),"NC",IF(OR(O15="C",Q15="C",S15="C",U15="C",W15="C",Y15="C",AA15="C",AC15="C"),"C",""))))) | AG15: =IF(AND(AE15="C",AF15="C"),"UTILIZOU O PDA CORRETAMENTE",IF(AND(AE15="C",AF15="NC"),"UTILIZOU O PDA CORRETAMENTE. NÃO HÁ FOTOS DE TODAS AS ETAPAS",IF(AND(AE15="NC",AF15="NC"),"NÃO UTILIZOU O PDA",IF(AND(AE15="NA",AF15="NA"),"NÃO AVALIADO POR FALHA DE SINCRONISMO")))) -> FALSE | AI15: GOPOÚVA | AJ15: =E15 -> GUARULHOS | AK15: ÁGUA | AL15: 0.49981207 | AM15: {=IF(OR(O15<>"", SUMPRODUCT(($AN$2:$AN$5000=AN15)*($AL$2:$AL$5000<=AL15)) <= (COUNTIF($AN$2:$AN$5000,AN15)*0.5)), "SORTEADO", "-")} -> - | AN15: 01/04/2026
A16: ONMG - DIV MANUT SERV OPE GOPOÚVA | B16: 2613728020 | C16: VAZAMENTO DE ÁGUA NO PASSEIO | D16: VAZAMENTO DE ÁGUA | E16: GUARULHOS | F16: RUA ALEGRE | G16: 26 | H16: ANT. 35 | I16: V SAO RAFAEL | J16: SUPRIMIDO RAMAL DE AGUA ABANDONADO | L16: 01/04/2026 | M16: 46026.383 | N16: JOAO MANOEL PEREIRA DOS SANTOS | AF16: =IF(AND(O16="",Q16="",S16="",U16="",W16="",Y16="",AA16="",AC16=""),"",IF(OR(AND(O16<>"NA",O16<>"C",O16<>"NC",O16<>"SF",O16<>""),AND(Q16<>"NA",Q16<>"C",Q16<>"NC",Q16<>"SF",Q16<>""),AND(S16<>"NA",S16<>"C",S16<>"NC",S16<>"SF",S16<>""),AND(U16<>"NA",U16<>"C",U16<>"NC",U16<>"SF",U16<>""),AND(W16<>"NA",W16<>"C",W16<>"NC",W16<>"SF",W16<>""),AND(Y16<>"NA",Y16<>"C",Y16<>"NC",Y16<>"SF",Y16<>""),AND(AA16<>"NA",AA16<>"C",AA16<>"NC",AA16<>"SF",AA16<>""),AND(AC16<>"NA",AC16<>"C",AC16<>"NC",AC16<>"SF",AC16<>"")),"FALSO",IF(AND(O16="NA",Q16="NA",S16="NA",U16="NA",W16="NA",Y16="NA",AA16="NA",AC16="NA"),"NA",IF(OR(O16="NC",Q16="NC",S16="NC",U16="NC",W16="NC",Y16="NC",AA16="NC",AC16="NC",O16="SF",Q16="SF",S16="SF",U16="SF",W16="SF",Y16="SF",AA16="SF",AC16="SF"),"NC",IF(OR(O16="C",Q16="C",S16="C",U16="C",W16="C",Y16="C",AA16="C",AC16="C"),"C",""))))) | AG16: =IF(AND(AE16="C",AF16="C"),"UTILIZOU O PDA CORRETAMENTE",IF(AND(AE16="C",AF16="NC"),"UTILIZOU O PDA CORRETAMENTE. NÃO HÁ FOTOS DE TODAS AS ETAPAS",IF(AND(AE16="NC",AF16="NC"),"NÃO UTILIZOU O PDA",IF(AND(AE16="NA",AF16="NA"),"NÃO AVALIADO POR FALHA DE SINCRONISMO")))) -> FALSE | AI16: GOPOÚVA | AJ16: =E16 -> GUARULHOS | AK16: ÁGUA | AL16: 0.75813073 | AM16: {=IF(OR(O16<>"", SUMPRODUCT(($AN$2:$AN$5000=AN16)*($AL$2:$AL$5000<=AL16)) <= (COUNTIF($AN$2:$AN$5000,AN16)*0.5)), "SORTEADO", "-")} -> - | AN16: 01/04/2026
A17: ONMG - DIV MANUT SERV OPE GOPOÚVA | B17: 2613754890 | C17: TROCAR RAMAL DE ÁGUA PREVENTIVA | D17: RAMAL DE ÁGUA | E17: GUARULHOS | F17: RUA TAILANDIA | G17: 182 | I17: JD SANTA CECILIA | J17: TROCA DE RAMAL DE AGUA PREVENTIVA | L17: 01/04/2026 | M17: 46026.458 | N17: EDILSON BARRETO DA SILVA | O17: C | Q17: C | S17: C | U17: C | W17: C | Y17: C | AA17: C | AC17: NC | AD17: FALTA CARIMBO | AE17: C | AF17: =IF(AND(O17="",Q17="",S17="",U17="",W17="",Y17="",AA17="",AC17=""),"",IF(OR(AND(O17<>"NA",O17<>"C",O17<>"NC",O17<>"SF",O17<>""),AND(Q17<>"NA",Q17<>"C",Q17<>"NC",Q17<>"SF",Q17<>""),AND(S17<>"NA",S17<>"C",S17<>"NC",S17<>"SF",S17<>""),AND(U17<>"NA",U17<>"C",U17<>"NC",U17<>"SF",U17<>""),AND(W17<>"NA",W17<>"C",W17<>"NC",W17<>"SF",W17<>""),AND(Y17<>"NA",Y17<>"C",Y17<>"NC",Y17<>"SF",Y17<>""),AND(AA17<>"NA",AA17<>"C",AA17<>"NC",AA17<>"SF",AA17<>""),AND(AC17<>"NA",AC17<>"C",AC17<>"NC",AC17<>"SF",AC17<>"")),"FALSO",IF(AND(O17="NA",Q17="NA",S17="NA",U17="NA",W17="NA",Y17="NA",AA17="NA",AC17="NA"),"NA",IF(OR(O17="NC",Q17="NC",S17="NC",U17="NC",W17="NC",Y17="NC",AA17="NC",AC17="NC",O17="SF",Q17="SF",S17="SF",U17="SF",W17="SF",Y17="SF",AA17="SF",AC17="SF"),"NC",IF(OR(O17="C",Q17="C",S17="C",U17="C",W17="C",Y17="C",AA17="C",AC17="C"),"C",""))))) -> NC | AG17: =IF(AND(AE17="C",AF17="C"),"UTILIZOU O PDA CORRETAMENTE",IF(AND(AE17="C",AF17="NC"),"UTILIZOU O PDA CORRETAMENTE. NÃO HÁ FOTOS DE TODAS AS ETAPAS",IF(AND(AE17="NC",AF17="NC"),"NÃO UTILIZOU O PDA",IF(AND(AE17="NA",AF17="NA"),"NÃO AVALIADO POR FALHA DE SINCRONISMO")))) -> UTILIZOU O PDA CORRETAMENTE. NÃO HÁ FOTOS DE TODAS AS ETAPAS | AH17: C | AI17: GOPOÚVA | AJ17: =E17 -> GUARULHOS | AK17: ÁGUA | AL17: -0.0032 | AM17: {=IF(OR(O17<>"", SUMPRODUCT(($AN$2:$AN$5000=AN17)*($AL$2:$AL$5000<=AL17)) <= (COUNTIF($AN$2:$AN$5000,AN17)*0.5)), "SORTEADO", "-")} -> SORTEADO | AN17: 01/04/2026
A18: ONMG - DIV MANUT SERV OPE GOPOÚVA | B18: 2613754423 | C18: TROCAR RAMAL DE ÁGUA PREVENTIVA | D18: RAMAL DE ÁGUA | E18: GUARULHOS | F18: RUA TAILANDIA | G18: 186 | H18: ANT180,C/1 | I18: JD SANTA CECILIA | J18: TROCA DE RAMAL DE AGUA PREVENTIVA | K18: não consigo tira todas as fotos porque a rua esta fresado prá colocar asfalto novo .e esta interditado | L18: 01/04/2026 | M18: 46026.642 | N18: EDILSON BARRETO DA SILVA | O18: C | Q18: C | S18: C | U18: C | W18: C | Y18: C | AA18: C | AC18: NC | AD18: FALTA CARIMBO | AE18: C | AF18: =IF(AND(O18="",Q18="",S18="",U18="",W18="",Y18="",AA18="",AC18=""),"",IF(OR(AND(O18<>"NA",O18<>"C",O18<>"NC",O18<>"SF",O18<>""),AND(Q18<>"NA",Q18<>"C",Q18<>"NC",Q18<>"SF",Q18<>""),AND(S18<>"NA",S18<>"C",S18<>"NC",S18<>"SF",S18<>""),AND(U18<>"NA",U18<>"C",U18<>"NC",U18<>"SF",U18<>""),AND(W18<>"NA",W18<>"C",W18<>"NC",W18<>"SF",W18<>""),AND(Y18<>"NA",Y18<>"C",Y18<>"NC",Y18<>"SF",Y18<>""),AND(AA18<>"NA",AA18<>"C",AA18<>"NC",AA18<>"SF",AA18<>""),AND(AC18<>"NA",AC18<>"C",AC18<>"NC",AC18<>"SF",AC18<>"")),"FALSO",IF(AND(O18="NA",Q18="NA",S18="NA",U18="NA",W18="NA",Y18="NA",AA18="NA",AC18="NA"),"NA",IF(OR(O18="NC",Q18="NC",S18="NC",U18="NC",W18="NC",Y18="NC",AA18="NC",AC18="NC",O18="SF",Q18="SF",S18="SF",U18="SF",W18="SF",Y18="SF",AA18="SF",AC18="SF"),"NC",IF(OR(O18="C",Q18="C",S18="C",U18="C",W18="C",Y18="C",AA18="C",AC18="C"),"C",""))))) -> NC | AG18: =IF(AND(AE18="C",AF18="C"),"UTILIZOU O PDA CORRETAMENTE",IF(AND(AE18="C",AF18="NC"),"UTILIZOU O PDA CORRETAMENTE. NÃO HÁ FOTOS DE TODAS AS ETAPAS",IF(AND(AE18="NC",AF18="NC"),"NÃO UTILIZOU O PDA",IF(AND(AE18="NA",AF18="NA"),"NÃO AVALIADO POR FALHA DE SINCRONISMO")))) -> UTILIZOU O PDA CORRETAMENTE. NÃO HÁ FOTOS DE TODAS AS ETAPAS | AH18: C | AI18: GOPOÚVA | AJ18: =E18 -> GUARULHOS | AK18: ÁGUA | AL18: -0.0034 | AM18: {=IF(OR(O18<>"", SUMPRODUCT(($AN$2:$AN$5000=AN18)*($AL$2:$AL$5000<=AL18)) <= (COUNTIF($AN$2:$AN$5000,AN18)*0.5)), "SORTEADO", "-")} -> SORTEADO | AN18: 01/04/2026
A19: ONMG - DIV MANUT SERV OPE GOPOÚVA | B19: 2689310773 | C19: VAZAMENTO DE ÁGUA NO PASSEIO | D19: VAZAMENTO DE ÁGUA | E19: GUARULHOS | F19: RUA VIVENCIA ESPIRITO SANTO | G19: 210 | H19: APTO 3 | I19: JD PALMIRA | J19: REPARO DE REDE DE AGUA | L19: 01/04/2026 | M19: 46026.415 | N19: HENRIQUE ANDRADE PEREIRA | O19: C | Q19: C | S19: C | U19: C | W19: C | Y19: NA | AA19: C | AC19: C | AE19: C | AF19: =IF(AND(O19="",Q19="",S19="",U19="",W19="",Y19="",AA19="",AC19=""),"",IF(OR(AND(O19<>"NA",O19<>"C",O19<>"NC",O19<>"SF",O19<>""),AND(Q19<>"NA",Q19<>"C",Q19<>"NC",Q19<>"SF",Q19<>""),AND(S19<>"NA",S19<>"C",S19<>"NC",S19<>"SF",S19<>""),AND(U19<>"NA",U19<>"C",U19<>"NC",U19<>"SF",U19<>""),AND(W19<>"NA",W19<>"C",W19<>"NC",W19<>"SF",W19<>""),AND(Y19<>"NA",Y19<>"C",Y19<>"NC",Y19<>"SF",Y19<>""),AND(AA19<>"NA",AA19<>"C",AA19<>"NC",AA19<>"SF",AA19<>""),AND(AC19<>"NA",AC19<>"C",AC19<>"NC",AC19<>"SF",AC19<>"")),"FALSO",IF(AND(O19="NA",Q19="NA",S19="NA",U19="NA",W19="NA",Y19="NA",AA19="NA",AC19="NA"),"NA",IF(OR(O19="NC",Q19="NC",S19="NC",U19="NC",W19="NC",Y19="NC",AA19="NC",AC19="NC",O19="SF",Q19="SF",S19="SF",U19="SF",W19="SF",Y19="SF",AA19="SF",AC19="SF"),"NC",IF(OR(O19="C",Q19="C",S19="C",U19="C",W19="C",Y19="C",AA19="C",AC19="C"),"C",""))))) -> C | AG19: =IF(AND(AE19="C",AF19="C"),"UTILIZOU O PDA CORRETAMENTE",IF(AND(AE19="C",AF19="NC"),"UTILIZOU O PDA CORRETAMENTE. NÃO HÁ FOTOS DE TODAS AS ETAPAS",IF(AND(AE19="NC",AF19="NC"),"NÃO UTILIZOU O PDA",IF(AND(AE19="NA",AF19="NA"),"NÃO AVALIADO POR FALHA DE SINCRONISMO")))) -> UTILIZOU O PDA CORRETAMENTE | AH19: C | AI19: GOPOÚVA | AJ19: =E19 -> GUARULHOS | AK19: ÁGUA | AL19: 0.15534462 | AM19: {=IF(OR(O19<>"", SUMPRODUCT(($AN$2:$AN$5000=AN19)*($AL$2:$AL$5000<=AL19)) <= (COUNTIF($AN$2:$AN$5000,AN19)*0.5)), "SORTEADO", "-")} -> SORTEADO | AN19: 01/04/2026
A20: ONMG - DIV MANUT SERV OPE GOPOÚVA | B20: 2689382014 | C20: VAZAMENTO DE ÁGUA NO PASSEIO | D20: VAZAMENTO DE ÁGUA | E20: GUARULHOS | F20: RUA VIVENCIA ESPIRITO SANTO | G20: 210 | H20: APTO 1 | I20: JD PALMIRA | J20: SUPRIMIDO RAMAL DE AGUA ABANDONADO | K20: as fotos e reposicao estao na os 2689310773 | L20: 01/04/2026 | M20: 46026.495 | N20: HENRIQUE ANDRADE PEREIRA | AF20: =IF(AND(O20="",Q20="",S20="",U20="",W20="",Y20="",AA20="",AC20=""),"",IF(OR(AND(O20<>"NA",O20<>"C",O20<>"NC",O20<>"SF",O20<>""),AND(Q20<>"NA",Q20<>"C",Q20<>"NC",Q20<>"SF",Q20<>""),AND(S20<>"NA",S20<>"C",S20<>"NC",S20<>"SF",S20<>""),AND(U20<>"NA",U20<>"C",U20<>"NC",U20<>"SF",U20<>""),AND(W20<>"NA",W20<>"C",W20<>"NC",W20<>"SF",W20<>""),AND(Y20<>"NA",Y20<>"C",Y20<>"NC",Y20<>"SF",Y20<>""),AND(AA20<>"NA",AA20<>"C",AA20<>"NC",AA20<>"SF",AA20<>""),AND(AC20<>"NA",AC20<>"C",AC20<>"NC",AC20<>"SF",AC20<>"")),"FALSO",IF(AND(O20="NA",Q20="NA",S20="NA",U20="NA",W20="NA",Y20="NA",AA20="NA",AC20="NA"),"NA",IF(OR(O20="NC",Q20="NC",S20="NC",U20="NC",W20="NC",Y20="NC",AA20="NC",AC20="NC",O20="SF",Q20="SF",S20="SF",U20="SF",W20="SF",Y20="SF",AA20="SF",AC20="SF"),"NC",IF(OR(O20="C",Q20="C",S20="C",U20="C",W20="C",Y20="C",AA20="C",AC20="C"),"C",""))))) | AG20: =IF(AND(AE20="C",AF20="C"),"UTILIZOU O PDA CORRETAMENTE",IF(AND(AE20="C",AF20="NC"),"UTILIZOU O PDA CORRETAMENTE. NÃO HÁ FOTOS DE TODAS AS ETAPAS",IF(AND(AE20="NC",AF20="NC"),"NÃO UTILIZOU O PDA",IF(AND(AE20="NA",AF20="NA"),"NÃO AVALIADO POR FALHA DE SINCRONISMO")))) -> FALSE | AI20: GOPOÚVA | AJ20: =E20 -> GUARULHOS | AK20: ÁGUA | AL20: 0.92273796 | AM20: {=IF(OR(O20<>"", SUMPRODUCT(($AN$2:$AN$5000=AN20)*($AL$2:$AL$5000<=AL20)) <= (COUNTIF($AN$2:$AN$5000,AN20)*0.5)), "SORTEADO", "-")} -> - | AN20: 01/04/2026
A21: ONMG - DIV MANUT SERV OPE GOPOÚVA | B21: 2613840742 | C21: VAZAMENTO DE ÁGUA NÃO VISÍVEL REDE | D21: VAZAMENTO DE ÁGUA | E21: GUARULHOS | F21: RUA GUARACY | G21: 405 | I21: JD PAULISTA | J21: REPARO DE REDE DE AGUA NÃO VISIVEL | K21: sem foto porque o servico foi aberto depois do executado | L21: 01/04/2026 | M21: 46026.447 | N21: ADEMAR JOSE VIANA | O21: C | Q21: C | S21: C | U21: C | W21: C | Y21: NA | AA21: C | AC21: C | AE21: C | AF21: =IF(AND(O21="",Q21="",S21="",U21="",W21="",Y21="",AA21="",AC21=""),"",IF(OR(AND(O21<>"NA",O21<>"C",O21<>"NC",O21<>"SF",O21<>""),AND(Q21<>"NA",Q21<>"C",Q21<>"NC",Q21<>"SF",Q21<>""),AND(S21<>"NA",S21<>"C",S21<>"NC",S21<>"SF",S21<>""),AND(U21<>"NA",U21<>"C",U21<>"NC",U21<>"SF",U21<>""),AND(W21<>"NA",W21<>"C",W21<>"NC",W21<>"SF",W21<>""),AND(Y21<>"NA",Y21<>"C",Y21<>"NC",Y21<>"SF",Y21<>""),AND(AA21<>"NA",AA21<>"C",AA21<>"NC",AA21<>"SF",AA21<>""),AND(AC21<>"NA",AC21<>"C",AC21<>"NC",AC21<>"SF",AC21<>"")),"FALSO",IF(AND(O21="NA",Q21="NA",S21="NA",U21="NA",W21="NA",Y21="NA",AA21="NA",AC21="NA"),"NA",IF(OR(O21="NC",Q21="NC",S21="NC",U21="NC",W21="NC",Y21="NC",AA21="NC",AC21="NC",O21="SF",Q21="SF",S21="SF",U21="SF",W21="SF",Y21="SF",AA21="SF",AC21="SF"),"NC",IF(OR(O21="C",Q21="C",S21="C",U21="C",W21="C",Y21="C",AA21="C",AC21="C"),"C",""))))) -> C | AG21: =IF(AND(AE21="C",AF21="C"),"UTILIZOU O PDA CORRETAMENTE",IF(AND(AE21="C",AF21="NC"),"UTILIZOU O PDA CORRETAMENTE. NÃO HÁ FOTOS DE TODAS AS ETAPAS",IF(AND(AE21="NC",AF21="NC"),"NÃO UTILIZOU O PDA",IF(AND(AE21="NA",AF21="NA"),"NÃO AVALIADO POR FALHA DE SINCRONISMO")))) -> UTILIZOU O PDA CORRETAMENTE | AH21: C | AI21: GOPOÚVA | AJ21: =E21 -> GUARULHOS | AK21: ÁGUA | AL21: 0.25695336 | AM21: {=IF(OR(O21<>"", SUMPRODUCT(($AN$2:$AN$5000=AN21)*($AL$2:$AL$5000<=AL21)) <= (COUNTIF($AN$2:$AN$5000,AN21)*0.5)), "SORTEADO", "-")} -> SORTEADO | AN21: 01/04/2026
A22: ONMG - DIV MANUT SERV OPE GOPOÚVA | B22: 2613859002 | C22: VAZAMENTO DE ÁGUA NÃO VISÍVEL REDE | D22: VAZAMENTO DE ÁGUA | E22: GUARULHOS | F22: RUA CURIO | G22: 221 | H22: CASA 01 | I22: JD VALERIA | J22: SUPRIMIDO RAMAL AGUA ABAND NÃO VISIVEL | L22: 01/04/2026 | M22: 46026.653 | N22: ADEMAR JOSE VIANA | AF22: =IF(AND(O22="",Q22="",S22="",U22="",W22="",Y22="",AA22="",AC22=""),"",IF(OR(AND(O22<>"NA",O22<>"C",O22<>"NC",O22<>"SF",O22<>""),AND(Q22<>"NA",Q22<>"C",Q22<>"NC",Q22<>"SF",Q22<>""),AND(S22<>"NA",S22<>"C",S22<>"NC",S22<>"SF",S22<>""),AND(U22<>"NA",U22<>"C",U22<>"NC",U22<>"SF",U22<>""),AND(W22<>"NA",W22<>"C",W22<>"NC",W22<>"SF",W22<>""),AND(Y22<>"NA",Y22<>"C",Y22<>"NC",Y22<>"SF",Y22<>""),AND(AA22<>"NA",AA22<>"C",AA22<>"NC",AA22<>"SF",AA22<>""),AND(AC22<>"NA",AC22<>"C",AC22<>"NC",AC22<>"SF",AC22<>"")),"FALSO",IF(AND(O22="NA",Q22="NA",S22="NA",U22="NA",W22="NA",Y22="NA",AA22="NA",AC22="NA"),"NA",IF(OR(O22="NC",Q22="NC",S22="NC",U22="NC",W22="NC",Y22="NC",AA22="NC",AC22="NC",O22="SF",Q22="SF",S22="SF",U22="SF",W22="SF",Y22="SF",AA22="SF",AC22="SF"),"NC",IF(OR(O22="C",Q22="C",S22="C",U22="C",W22="C",Y22="C",AA22="C",AC22="C"),"C",""))))) | AG22: =IF(AND(AE22="C",AF22="C"),"UTILIZOU O PDA CORRETAMENTE",IF(AND(AE22="C",AF22="NC"),"UTILIZOU O PDA CORRETAMENTE. NÃO HÁ FOTOS DE TODAS AS ETAPAS",IF(AND(AE22="NC",AF22="NC"),"NÃO UTILIZOU O PDA",IF(AND(AE22="NA",AF22="NA"),"NÃO AVALIADO POR FALHA DE SINCRONISMO")))) -> FALSE | AI22: GOPOÚVA | AJ22: =E22 -> GUARULHOS | AK22: ÁGUA | AL22: 0.60916212 | AM22: {=IF(OR(O22<>"", SUMPRODUCT(($AN$2:$AN$5000=AN22)*($AL$2:$AL$5000<=AL22)) <= (COUNTIF($AN$2:$AN$5000,AN22)*0.5)), "SORTEADO", "-")} -> - | AN22: 01/04/2026
A23: ONMG - DIV MANUT SERV OPE GOPOÚVA | B23: 2613863178 | C23: VAZAMENTO DE ÁGUA LEITO TERRA | D23: VAZAMENTO DE ÁGUA | E23: GUARULHOS | F23: RUA PADRE CELESTINO | G23: 579 | H23: ANTIGO 585 | I23: CENTRO | J23: REPARO DE REDE DE AGUA | K23: não tem reposição obra no local material utilizado 1 m de tubo de PVC de 75 | L23: 01/04/2026 | M23: 46026.646 | N23: JOAO MANOEL PEREIRA DOS SANTOS | AF23: =IF(AND(O23="",Q23="",S23="",U23="",W23="",Y23="",AA23="",AC23=""),"",IF(OR(AND(O23<>"NA",O23<>"C",O23<>"NC",O23<>"SF",O23<>""),AND(Q23<>"NA",Q23<>"C",Q23<>"NC",Q23<>"SF",Q23<>""),AND(S23<>"NA",S23<>"C",S23<>"NC",S23<>"SF",S23<>""),AND(U23<>"NA",U23<>"C",U23<>"NC",U23<>"SF",U23<>""),AND(W23<>"NA",W23<>"C",W23<>"NC",W23<>"SF",W23<>""),AND(Y23<>"NA",Y23<>"C",Y23<>"NC",Y23<>"SF",Y23<>""),AND(AA23<>"NA",AA23<>"C",AA23<>"NC",AA23<>"SF",AA23<>""),AND(AC23<>"NA",AC23<>"C",AC23<>"NC",AC23<>"SF",AC23<>"")),"FALSO",IF(AND(O23="NA",Q23="NA",S23="NA",U23="NA",W23="NA",Y23="NA",AA23="NA",AC23="NA"),"NA",IF(OR(O23="NC",Q23="NC",S23="NC",U23="NC",W23="NC",Y23="NC",AA23="NC",AC23="NC",O23="SF",Q23="SF",S23="SF",U23="SF",W23="SF",Y23="SF",AA23="SF",AC23="SF"),"NC",IF(OR(O23="C",Q23="C",S23="C",U23="C",W23="C",Y23="C",AA23="C",AC23="C"),"C",""))))) | AG23: =IF(AND(AE23="C",AF23="C"),"UTILIZOU O PDA CORRETAMENTE",IF(AND(AE23="C",AF23="NC"),"UTILIZOU O PDA CORRETAMENTE. NÃO HÁ FOTOS DE TODAS AS ETAPAS",IF(AND(AE23="NC",AF23="NC"),"NÃO UTILIZOU O PDA",IF(AND(AE23="NA",AF23="NA"),"NÃO AVALIADO POR FALHA DE SINCRONISMO")))) -> FALSE | AI23: GOPOÚVA | AJ23: =E23 -> GUARULHOS | AK23: ÁGUA | AL23: 0.87909279 | AM23: {=IF(OR(O23<>"", SUMPRODUCT(($AN$2:$AN$5000=AN23)*($AL$2:$AL$5000<=AL23)) <= (COUNTIF($AN$2:$AN$5000,AN23)*0.5)), "SORTEADO", "-")} -> - | AN23: 01/04/2026
A24: ONMG - DIV MANUT SERV OPE GOPOÚVA | B24: 2613866326 | C24: TROCAR RAMAL DE ÁGUA PREVENTIVA | D24: RAMAL DE ÁGUA | E24: GUARULHOS | F24: RUA MONTE CARLO | G24: 34 | H24: ANT 51D | I24: BELA VISTA | J24: TROCA DE RAMAL DE AGUA PREVENTIVA | K24: Serviço executado sem fotos devido os aberta após execução do serviço e dentro da vala do INTEGRA TIETÊ com o acompanhamento do fiscal Elvis | L24: 01/04/2026 | M24: 46026.542 | N24: JOSE PETRUCIO SANTOS FILHO | AF24: =IF(AND(O24="",Q24="",S24="",U24="",W24="",Y24="",AA24="",AC24=""),"",IF(OR(AND(O24<>"NA",O24<>"C",O24<>"NC",O24<>"SF",O24<>""),AND(Q24<>"NA",Q24<>"C",Q24<>"NC",Q24<>"SF",Q24<>""),AND(S24<>"NA",S24<>"C",S24<>"NC",S24<>"SF",S24<>""),AND(U24<>"NA",U24<>"C",U24<>"NC",U24<>"SF",U24<>""),AND(W24<>"NA",W24<>"C",W24<>"NC",W24<>"SF",W24<>""),AND(Y24<>"NA",Y24<>"C",Y24<>"NC",Y24<>"SF",Y24<>""),AND(AA24<>"NA",AA24<>"C",AA24<>"NC",AA24<>"SF",AA24<>""),AND(AC24<>"NA",AC24<>"C",AC24<>"NC",AC24<>"SF",AC24<>"")),"FALSO",IF(AND(O24="NA",Q24="NA",S24="NA",U24="NA",W24="NA",Y24="NA",AA24="NA",AC24="NA"),"NA",IF(OR(O24="NC",Q24="NC",S24="NC",U24="NC",W24="NC",Y24="NC",AA24="NC",AC24="NC",O24="SF",Q24="SF",S24="SF",U24="SF",W24="SF",Y24="SF",AA24="SF",AC24="SF"),"NC",IF(OR(O24="C",Q24="C",S24="C",U24="C",W24="C",Y24="C",AA24="C",AC24="C"),"C",""))))) | AG24: =IF(AND(AE24="C",AF24="C"),"UTILIZOU O PDA CORRETAMENTE",IF(AND(AE24="C",AF24="NC"),"UTILIZOU O PDA CORRETAMENTE. NÃO HÁ FOTOS DE TODAS AS ETAPAS",IF(AND(AE24="NC",AF24="NC"),"NÃO UTILIZOU O PDA",IF(AND(AE24="NA",AF24="NA"),"NÃO AVALIADO POR FALHA DE SINCRONISMO")))) -> FALSE | AI24: GOPOÚVA | AJ24: =E24 -> GUARULHOS | AK24: ÁGUA | AL24: 0.45038989 | AM24: {=IF(OR(O24<>"", SUMPRODUCT(($AN$2:$AN$5000=AN24)*($AL$2:$AL$5000<=AL24)) <= (COUNTIF($AN$2:$AN$5000,AN24)*0.5)), "SORTEADO", "-")} -> - | AN24: 01/04/2026
A25: ONMG - DIV MANUT SERV OPE GOPOÚVA | B25: 2613866966 | C25: TROCAR RAMAL DE ÁGUA PREVENTIVA | D25: RAMAL DE ÁGUA | E25: GUARULHOS | F25: RUA MONTE CARLO | G25: 42 | H25: ANT. 52 | I25: BELA VISTA | J25: TROCA DE RAMAL DE AGUA PREVENTIVA | K25: Serviço executado sem fotos devido os aberta após execução do serviço e dentro da vala do INTEGRA TIETÊ com o acompanhamento do fiscal Elvi | L25: 01/04/2026 | M25: 46026.54 | N25: JOSE PETRUCIO SANTOS FILHO | O25: NA | Q25: NA | S25: NA | U25: NA | W25: NA | Y25: NA | AA25: NA | AC25: NA | AE25: NA | AF25: =IF(AND(O25="",Q25="",S25="",U25="",W25="",Y25="",AA25="",AC25=""),"",IF(OR(AND(O25<>"NA",O25<>"C",O25<>"NC",O25<>"SF",O25<>""),AND(Q25<>"NA",Q25<>"C",Q25<>"NC",Q25<>"SF",Q25<>""),AND(S25<>"NA",S25<>"C",S25<>"NC",S25<>"SF",S25<>""),AND(U25<>"NA",U25<>"C",U25<>"NC",U25<>"SF",U25<>""),AND(W25<>"NA",W25<>"C",W25<>"NC",W25<>"SF",W25<>""),AND(Y25<>"NA",Y25<>"C",Y25<>"NC",Y25<>"SF",Y25<>""),AND(AA25<>"NA",AA25<>"C",AA25<>"NC",AA25<>"SF",AA25<>""),AND(AC25<>"NA",AC25<>"C",AC25<>"NC",AC25<>"SF",AC25<>"")),"FALSO",IF(AND(O25="NA",Q25="NA",S25="NA",U25="NA",W25="NA",Y25="NA",AA25="NA",AC25="NA"),"NA",IF(OR(O25="NC",Q25="NC",S25="NC",U25="NC",W25="NC",Y25="NC",AA25="NC",AC25="NC",O25="SF",Q25="SF",S25="SF",U25="SF",W25="SF",Y25="SF",AA25="SF",AC25="SF"),"NC",IF(OR(O25="C",Q25="C",S25="C",U25="C",W25="C",Y25="C",AA25="C",AC25="C"),"C",""))))) -> NA | AG25: =IF(AND(AE25="C",AF25="C"),"UTILIZOU O PDA CORRETAMENTE",IF(AND(AE25="C",AF25="NC"),"UTILIZOU O PDA CORRETAMENTE. NÃO HÁ FOTOS DE TODAS AS ETAPAS",IF(AND(AE25="NC",AF25="NC"),"NÃO UTILIZOU O PDA",IF(AND(AE25="NA",AF25="NA"),"NÃO AVALIADO POR FALHA DE SINCRONISMO")))) -> NÃO AVALIADO POR FALHA DE SINCRONISMO | AH25: C | AI25: GOPOÚVA | AJ25: =E25 -> GUARULHOS | AK25: ÁGUA | AL25: 0.12234832 | AM25: {=IF(OR(O25<>"", SUMPRODUCT(($AN$2:$AN$5000=AN25)*($AL$2:$AL$5000<=AL25)) <= (COUNTIF($AN$2:$AN$5000,AN25)*0.5)), "SORTEADO", "-")} -> SORTEADO | AN25: 01/04/2026
A26: ONMG - DIV MANUT SERV OPE GOPOÚVA | B26: 2613870340 | C26: SUBSTITUIR TAMPA DE CAIXA UMA | D26: OUTROS SERVIÇOS DE ÁGUA | E26: GUARULHOS | F26: RUA EUSONIA | G26: 402 | I26: JD EUSONIA | J26: SUBSTITUIDA TAMPA DE CAIXA UMA | K26: fotos encaminhadas no WhatsApp | L26: 01/04/2026 | M26: 46026.527 | N26: MURILO ALVES ROCHA | AF26: =IF(AND(O26="",Q26="",S26="",U26="",W26="",Y26="",AA26="",AC26=""),"",IF(OR(AND(O26<>"NA",O26<>"C",O26<>"NC",O26<>"SF",O26<>""),AND(Q26<>"NA",Q26<>"C",Q26<>"NC",Q26<>"SF",Q26<>""),AND(S26<>"NA",S26<>"C",S26<>"NC",S26<>"SF",S26<>""),AND(U26<>"NA",U26<>"C",U26<>"NC",U26<>"SF",U26<>""),AND(W26<>"NA",W26<>"C",W26<>"NC",W26<>"SF",W26<>""),AND(Y26<>"NA",Y26<>"C",Y26<>"NC",Y26<>"SF",Y26<>""),AND(AA26<>"NA",AA26<>"C",AA26<>"NC",AA26<>"SF",AA26<>""),AND(AC26<>"NA",AC26<>"C",AC26<>"NC",AC26<>"SF",AC26<>"")),"FALSO",IF(AND(O26="NA",Q26="NA",S26="NA",U26="NA",W26="NA",Y26="NA",AA26="NA",AC26="NA"),"NA",IF(OR(O26="NC",Q26="NC",S26="NC",U26="NC",W26="NC",Y26="NC",AA26="NC",AC26="NC",O26="SF",Q26="SF",S26="SF",U26="SF",W26="SF",Y26="SF",AA26="SF",AC26="SF"),"NC",IF(OR(O26="C",Q26="C",S26="C",U26="C",W26="C",Y26="C",AA26="C",AC26="C"),"C",""))))) | AG26: =IF(AND(AE26="C",AF26="C"),"UTILIZOU O PDA CORRETAMENTE",IF(AND(AE26="C",AF26="NC"),"UTILIZOU O PDA CORRETAMENTE. NÃO HÁ FOTOS DE TODAS AS ETAPAS",IF(AND(AE26="NC",AF26="NC"),"NÃO UTILIZOU O PDA",IF(AND(AE26="NA",AF26="NA"),"NÃO AVALIADO POR FALHA DE SINCRONISMO")))) -> FALSE | AI26: GOPOÚVA | AJ26: =E26 -> GUARULHOS | AK26: ÁGUA | AL26: 0.62306272 | AM26: {=IF(OR(O26<>"", SUMPRODUCT(($AN$2:$AN$5000=AN26)*($AL$2:$AL$5000<=AL26)) <= (COUNTIF($AN$2:$AN$5000,AN26)*0.5)), "SORTEADO", "-")} -> - | AN26: 01/04/2026
A27: ONMG - DIV MANUT SERV OPE GOPOÚVA | B27: 2689271856 | C27: TROCAR RAMAL DE ÁGUA | D27: VAZAMENTO DE ÁGUA | E27: GUARULHOS | F27: RUA SOLDADO ARLINDO SARDANHA | G27: 28 | H27: ANT. 18 | I27: CENTRO | J27: TROCA DE RAMAL DE AGUA | K27: nao foi possivel sequencia de fotos correta devido local estreito e nao foi possível fotos de estanquiedade devido pé de cavalete ser de uma polegada | L27: 01/04/2026 | M27: 46026.512 | N27: JOSE LIMA SILVA | AF27: =IF(AND(O27="",Q27="",S27="",U27="",W27="",Y27="",AA27="",AC27=""),"",IF(OR(AND(O27<>"NA",O27<>"C",O27<>"NC",O27<>"SF",O27<>""),AND(Q27<>"NA",Q27<>"C",Q27<>"NC",Q27<>"SF",Q27<>""),AND(S27<>"NA",S27<>"C",S27<>"NC",S27<>"SF",S27<>""),AND(U27<>"NA",U27<>"C",U27<>"NC",U27<>"SF",U27<>""),AND(W27<>"NA",W27<>"C",W27<>"NC",W27<>"SF",W27<>""),AND(Y27<>"NA",Y27<>"C",Y27<>"NC",Y27<>"SF",Y27<>""),AND(AA27<>"NA",AA27<>"C",AA27<>"NC",AA27<>"SF",AA27<>""),AND(AC27<>"NA",AC27<>"C",AC27<>"NC",AC27<>"SF",AC27<>"")),"FALSO",IF(AND(O27="NA",Q27="NA",S27="NA",U27="NA",W27="NA",Y27="NA",AA27="NA",AC27="NA"),"NA",IF(OR(O27="NC",Q27="NC",S27="NC",U27="NC",W27="NC",Y27="NC",AA27="NC",AC27="NC",O27="SF",Q27="SF",S27="SF",U27="SF",W27="SF",Y27="SF",AA27="SF",AC27="SF"),"NC",IF(OR(O27="C",Q27="C",S27="C",U27="C",W27="C",Y27="C",AA27="C",AC27="C"),"C",""))))) | AG27: =IF(AND(AE27="C",AF27="C"),"UTILIZOU O PDA CORRETAMENTE",IF(AND(AE27="C",AF27="NC"),"UTILIZOU O PDA CORRETAMENTE. NÃO HÁ FOTOS DE TODAS AS ETAPAS",IF(AND(AE27="NC",AF27="NC"),"NÃO UTILIZOU O PDA",IF(AND(AE27="NA",AF27="NA"),"NÃO AVALIADO POR FALHA DE SINCRONISMO")))) -> FALSE | AI27: GOPOÚVA | AJ27: =E27 -> GUARULHOS | AK27: ÁGUA | AL27: 0.70743787 | AM27: {=IF(OR(O27<>"", SUMPRODUCT(($AN$2:$AN$5000=AN27)*($AL$2:$AL$5000<=AL27)) <= (COUNTIF($AN$2:$AN$5000,AN27)*0.5)), "SORTEADO", "-")} -> - | AN27: 01/04/2026
A28: ONMG - DIV MANUT SERV OPE GOPOÚVA | B28: 2613872040 | C28: VAZAMENTO DE ÁGUA NÃO VISÍVEL REDE | D28: VAZAMENTO DE ÁGUA | E28: GUARULHOS | F28: RUA CONEGO VALADAO | G28: 125 | H28: ANT. 1834 | I28: GOPOUVA | J28: REPARO DE REDE DE AGUA NÃO VISIVEL | K28: todas as fotos estao na os 2613872040 | L28: 01/04/2026 | M28: 46026.676 | N28: EDILSON DA SILVA DE ALMEIDA | AF28: =IF(AND(O28="",Q28="",S28="",U28="",W28="",Y28="",AA28="",AC28=""),"",IF(OR(AND(O28<>"NA",O28<>"C",O28<>"NC",O28<>"SF",O28<>""),AND(Q28<>"NA",Q28<>"C",Q28<>"NC",Q28<>"SF",Q28<>""),AND(S28<>"NA",S28<>"C",S28<>"NC",S28<>"SF",S28<>""),AND(U28<>"NA",U28<>"C",U28<>"NC",U28<>"SF",U28<>""),AND(W28<>"NA",W28<>"C",W28<>"NC",W28<>"SF",W28<>""),AND(Y28<>"NA",Y28<>"C",Y28<>"NC",Y28<>"SF",Y28<>""),AND(AA28<>"NA",AA28<>"C",AA28<>"NC",AA28<>"SF",AA28<>""),AND(AC28<>"NA",AC28<>"C",AC28<>"NC",AC28<>"SF",AC28<>"")),"FALSO",IF(AND(O28="NA",Q28="NA",S28="NA",U28="NA",W28="NA",Y28="NA",AA28="NA",AC28="NA"),"NA",IF(OR(O28="NC",Q28="NC",S28="NC",U28="NC",W28="NC",Y28="NC",AA28="NC",AC28="NC",O28="SF",Q28="SF",S28="SF",U28="SF",W28="SF",Y28="SF",AA28="SF",AC28="SF"),"NC",IF(OR(O28="C",Q28="C",S28="C",U28="C",W28="C",Y28="C",AA28="C",AC28="C"),"C",""))))) | AG28: =IF(AND(AE28="C",AF28="C"),"UTILIZOU O PDA CORRETAMENTE",IF(AND(AE28="C",AF28="NC"),"UTILIZOU O PDA CORRETAMENTE. NÃO HÁ FOTOS DE TODAS AS ETAPAS",IF(AND(AE28="NC",AF28="NC"),"NÃO UTILIZOU O PDA",IF(AND(AE28="NA",AF28="NA"),"NÃO AVALIADO POR FALHA DE SINCRONISMO")))) -> FALSE | AI28: GOPOÚVA | AJ28: =E28 -> GUARULHOS | AK28: ÁGUA | AL28: 0.49141178 | AM28: {=IF(OR(O28<>"", SUMPRODUCT(($AN$2:$AN$5000=AN28)*($AL$2:$AL$5000<=AL28)) <= (COUNTIF($AN$2:$AN$5000,AN28)*0.5)), "SORTEADO", "-")} -> - | AN28: 01/04/2026
A29: ONMG - DIV MANUT SERV OPE GOPOÚVA | B29: 2613872051 | C29: TROCAR RAMAL DE ÁGUA - VAZ NÃO VISIVEL | D29: VAZAMENTO DE ÁGUA | E29: GUARULHOS | F29: RUA TAILANDIA | G29: 174 | H29: ANT. 5 C/1 | I29: JD SANTA CECILIA | J29: TROCA DE RAMAL DE AGUA NÃO VISIVEL | K29: serviço executado sem abertura do os tirar as fotos no particular | L29: 01/04/2026 | M29: 46026.674 | N29: EDILSON BARRETO DA SILVA | O29: NA | Q29: NA | S29: NA | U29: NA | W29: NA | Y29: NA | AA29: NA | AC29: NA | AE29: NA | AF29: =IF(AND(O29="",Q29="",S29="",U29="",W29="",Y29="",AA29="",AC29=""),"",IF(OR(AND(O29<>"NA",O29<>"C",O29<>"NC",O29<>"SF",O29<>""),AND(Q29<>"NA",Q29<>"C",Q29<>"NC",Q29<>"SF",Q29<>""),AND(S29<>"NA",S29<>"C",S29<>"NC",S29<>"SF",S29<>""),AND(U29<>"NA",U29<>"C",U29<>"NC",U29<>"SF",U29<>""),AND(W29<>"NA",W29<>"C",W29<>"NC",W29<>"SF",W29<>""),AND(Y29<>"NA",Y29<>"C",Y29<>"NC",Y29<>"SF",Y29<>""),AND(AA29<>"NA",AA29<>"C",AA29<>"NC",AA29<>"SF",AA29<>""),AND(AC29<>"NA",AC29<>"C",AC29<>"NC",AC29<>"SF",AC29<>"")),"FALSO",IF(AND(O29="NA",Q29="NA",S29="NA",U29="NA",W29="NA",Y29="NA",AA29="NA",AC29="NA"),"NA",IF(OR(O29="NC",Q29="NC",S29="NC",U29="NC",W29="NC",Y29="NC",AA29="NC",AC29="NC",O29="SF",Q29="SF",S29="SF",U29="SF",W29="SF",Y29="SF",AA29="SF",AC29="SF"),"NC",IF(OR(O29="C",Q29="C",S29="C",U29="C",W29="C",Y29="C",AA29="C",AC29="C"),"C",""))))) -> NA | AG29: OS ABERTA POSTERIROMENTE A EXECUÇÃO DO SERVIÇO | AH29: C | AI29: GOPOÚVA | AJ29: =E29 -> GUARULHOS | AK29: ÁGUA | AL29: -0.0056 | AM29: {=IF(OR(O29<>"", SUMPRODUCT(($AN$2:$AN$5000=AN29)*($AL$2:$AL$5000<=AL29)) <= (COUNTIF($AN$2:$AN$5000,AN29)*0.5)), "SORTEADO", "-")} -> SORTEADO | AN29: 01/04/2026
A30: ONMG - DIV MANUT SERV OPE GOPOÚVA | B30: 2613878731 | C30: VAZAMENTO DE ÁGUA NÃO VISÍVEL REDE | D30: VAZAMENTO DE ÁGUA | E30: GUARULHOS | F30: RUA HUGO ZILLER | G30: 426 | H30: ANT. 3 | I30: JD SANTA CECILIA | J30: REPARO DE REDE DE AGUA NÃO VISIVEL | K30: nao foi possivel fotos devido OS ser aberta posteriormente, prioridade da sabesp, sem pavimento obras de esgoto no local | L30: 01/04/2026 | M30: 46026.605 | N30: JOSE LIMA SILVA | O30: NA | Q30: NA | S30: NA | U30: NA | W30: NA | Y30: NA | AA30: NA | AC30: NA | AE30: NA | AF30: =IF(AND(O30="",Q30="",S30="",U30="",W30="",Y30="",AA30="",AC30=""),"",IF(OR(AND(O30<>"NA",O30<>"C",O30<>"NC",O30<>"SF",O30<>""),AND(Q30<>"NA",Q30<>"C",Q30<>"NC",Q30<>"SF",Q30<>""),AND(S30<>"NA",S30<>"C",S30<>"NC",S30<>"SF",S30<>""),AND(U30<>"NA",U30<>"C",U30<>"NC",U30<>"SF",U30<>""),AND(W30<>"NA",W30<>"C",W30<>"NC",W30<>"SF",W30<>""),AND(Y30<>"NA",Y30<>"C",Y30<>"NC",Y30<>"SF",Y30<>""),AND(AA30<>"NA",AA30<>"C",AA30<>"NC",AA30<>"SF",AA30<>""),AND(AC30<>"NA",AC30<>"C",AC30<>"NC",AC30<>"SF",AC30<>"")),"FALSO",IF(AND(O30="NA",Q30="NA",S30="NA",U30="NA",W30="NA",Y30="NA",AA30="NA",AC30="NA"),"NA",IF(OR(O30="NC",Q30="NC",S30="NC",U30="NC",W30="NC",Y30="NC",AA30="NC",AC30="NC",O30="SF",Q30="SF",S30="SF",U30="SF",W30="SF",Y30="SF",AA30="SF",AC30="SF"),"NC",IF(OR(O30="C",Q30="C",S30="C",U30="C",W30="C",Y30="C",AA30="C",AC30="C"),"C",""))))) -> NA | AG30: OS ABERTA POSTERIORMENTE A EXECUÇÃO DO SERVIÇO | AH30: C | AI30: GOPOÚVA | AJ30: =E30 -> GUARULHOS | AK30: ÁGUA | AL30: -0.0058 | AM30: {=IF(OR(O30<>"", SUMPRODUCT(($AN$2:$AN$5000=AN30)*($AL$2:$AL$5000<=AL30)) <= (COUNTIF($AN$2:$AN$5000,AN30)*0.5)), "SORTEADO", "-")} -> SORTEADO | AN30: 01/04/2026
